Workbook

Sheet Casa Sonhar
B2: JULHO | H2: AGOSTO | N2: SETEMBRO | T2: OUTUBRO | Z2: NOVEMBRO | AF2: DEZEMBRO
A3: INDICADOR | B3: SEMANA 1 | C3: SEMANA 2 | D3: SEMANA 3 | E3: SEMANA 4 | F3: SEMANA 5 | G3: TOTAL | H3: SEMANA 1 | I3: SEMANA 2 | J3: SEMANA 3 | K3: SEMANA 4 | L3: SEMANA 5 | M3: TOTAL | N3: SEMANA 1 | O3: SEMANA 2 | P3: SEMANA 3 | Q3: SEMANA 4 | R3: SEMANA 5 | S3: TOTAL | T3: SEMANA 1 | U3: SEMANA 2 | V3: SEMANA 3 | W3: SEMANA 4 | X3: SEMANA 5 | Y3: TOTAL | Z3: SEMANA 1 | AA3: SEMANA 2 | AB3: SEMANA 3 | AC3: SEMANA 4 | AD3: SEMANA 5 | AE3: TOTAL | AF3: SEMANA 1 | AG3: SEMANA 2 | AH3: SEMANA 3 | AI3: SEMANA 4 | AJ3: SEMANA 5 | AK3: TOTAL
B4: PREENCHER | H4: PREENCHER | N4: PREENCHER | T4: PREENCHER | Z4: PREENCHER | AF4: PREENCHER
A5: Polo Contagem - Gloria | B5: FREQUENCIA | H5: FREQUENCIA | N5: FREQUENCIA | T5: FREQUENCIA | Z5: FREQUENCIA | AF5: FREQUENCIA
A6: DANÇA SONHAR - MANHÃ | G6: =AVERAGE(B6:F6) -> #DIV/0! | M6: =AVERAGE(H6:L6) -> #DIV/0! | O6: 90 | P6: 100 | Q6: 100 | R6: 98 | S6: =AVERAGE(N6:R6) -> 97 | T6: 90 | U6: 90 | V6: 98 | W6: 95 | X6: 100 | Y6: =AVERAGE(T6:X6) -> 94.6 | AA6: 88 | AB6: 90 | AC6: 95 | AD6: 100 | AE6: =AVERAGE(Z6:AD6) -> 93.25 | AG6: 85 | AK6: =AVERAGE(AF6:AJ6) -> 85
A7: DANÇA SONHAR - TARDE | G7: =AVERAGE(B7:F7) -> #DIV/0! | M7: =AVERAGE(H7:L7) -> #DIV/0! | O7: 75 | P7: 80 | Q7: 75 | R7: 90 | S7: =AVERAGE(N7:R7) -> 80 | T7: 100 | U7: 100 | V7: 100 | W7: 100 | X7: 94 | Y7: =AVERAGE(T7:X7) -> 98.8 | Z7: 88 | AA7: 88 | AB7: 88 | AE7: =AVERAGE(Z7:AD7) -> 88 | AG7: 86 | AK7: =AVERAGE(AF7:AJ7) -> 86
A8: CONTRATURNO MANHÃ | G8: =AVERAGE(B8:F8) -> #DIV/0! | M8: =AVERAGE(H8:L8) -> #DIV/0! | N8: 100 | O8: 92 | P8: 100 | Q8: 100 | R8: 100 | S8: =AVERAGE(N8:R8) -> 98.4 | T8: 92 | U8: 81 | V8: 92 | W8: 81 | X8: 86 | Y8: =AVERAGE(T8:X8) -> 86.4 | Z8: 89 | AA8: 91 | AB8: 88 | AC8: 81 | AD8: 83 | AE8: =AVERAGE(Z8:AD8) -> 86.4
A9: CONTRATURNO TARDE | G9: =AVERAGE(B9:F9) -> #DIV/0! | M9: =AVERAGE(H9:L9) -> #DIV/0! | O9: 74 | P9: 80 | Q9: 97 | R9: 100 | S9: =AVERAGE(N9:R9) -> 87.75 | T9: 100 | U9: 79 | V9: 96 | W9: 95 | X9: 92 | Y9: =AVERAGE(T9:X9) -> 92.4 | Z9: 95 | AA9: 93 | AB9: 78 | AC9: 91 | AD9: 98 | AE9: =AVERAGE(Z9:AD9) -> 91
A10: LABORATORIO PERCUSSIVO SONHAR | G10: =AVERAGE(B10:F10) -> #DIV/0! | M10: =AVERAGE(H10:L10) -> #DIV/0! | O10: 100 | P10: 100 | Q10: 100 | R10: 100 | S10: =AVERAGE(N10:R10) -> 100 | T10: 85 | U10: _ | V10: 90 | W10: 100 | X10: _ | Y10: =AVERAGE(T10:X10) -> 91.666667 | Z10: 100 | AA10: 100 | AC10: 89 | AD10: 89 | AE10: =AVERAGE(Z10:AD10) -> 94.5
A11: CAPOEIRA CASA SONHAR TARDE | O11: 93 | P11: 87 | Q11: 97 | R11: 87 | S11: =AVERAGE(N11:R11) -> 91 | T11: 87 | U11: 80 | V11: 87 | W11: 100 | X11: _ | Y11: =AVERAGE(T11:X11) -> 88.5 | AA11: 100 | AB11: 93 | AC11: 100 | AE11: =AVERAGE(Z11:AD11) -> 97.666667
A12: SOCIO EMOCIONAL SONHAR | G12: =AVERAGE(B12:F12) -> #DIV/0! | P12: 100 | S12: =AVERAGE(N12:R12) -> 100 | T12: _ | U12: _ | V12: _ | W12: _ | X12: _ | Z12: _
A13: LABORATORIO PERCUSIVO MANHÃ | T13: 85 | U13: _ | V13: 90 | W13: _ | X13: _ | Y13: =AVERAGE(T13:X13) -> 87.5 | Z13: 90 | AA13: 85 | AC13: 90 | AD13: 95 | AE13: =AVERAGE(Z13:AD13) -> 90
A14: RECREAÇÃO
A15: ARTES | AB15: 100 | AC15: 80 | AE15: =AVERAGE(Z15:AD15) -> 90
A16: TOTAL | B16: =AVERAGE(B6:B10) -> #DIV/0! | C16: =AVERAGE(C6:C10) -> #DIV/0! | D16: =AVERAGE(D6:D10) -> #DIV/0! | E16: =AVERAGE(E6:E10) -> #DIV/0! | F16: =AVERAGE(F6:F10) -> #DIV/0! | G16: =AVERAGE(G6:G12) -> #DIV/0! | H16: =AVERAGE(H6:H10) -> #DIV/0! | I16: =AVERAGE(I6:I10) -> #DIV/0! | J16: =AVERAGE(J6:J10) -> #DIV/0! | K16: =AVERAGE(K6:K10) -> #DIV/0! | L16: =AVERAGE(L6:L10) -> #DIV/0! | M16: =AVERAGE(M6:M10) -> #DIV/0! | N16: =AVERAGE(N6:N10) -> 100 | O16: =AVERAGE(O6:O11) -> 87.333333 | P16: =AVERAGE(P6:P11) -> 91.166667 | Q16: =AVERAGE(Q6:Q10) -> 94.4 | R16: =AVERAGE(R6:R10) -> 97.6 | S16: =AVERAGE(S6:S12) -> 93.45 | T16: =AVERAGE(T6:T10) -> 93.4 | U16: =AVERAGE(U6:U10) -> 87.5 | V16: =AVERAGE(V6:V10) -> 95.2 | W16: =AVERAGE(W6:W10) -> 94.2 | X16: =AVERAGE(X6:X10) -> 93 | Y16: =AVERAGE(Y6:Y13) -> 91.409524 | Z16: =AVERAGE(Z6:Z10) -> 93 | AA16: =AVERAGE(AA6:AA10) -> 92 | AB16: =AVERAGE(AB6:AB10) -> 86 | AC16: =AVERAGE(AC6:AC10) -> 89 | AD16: =AVERAGE(AD6:AD10) -> 92.5 | AE16: =AVERAGE(AE6:AE13) -> 91.545238 | AF16: =AVERAGE(AF6:AF10) -> #DIV/0! | AG16: =AVERAGE(AG6:AG10) -> 85.5 | AH16: =AVERAGE(AH6:AH10) -> #DIV/0! | AI16: =AVERAGE(AI6:AI10) -> #DIV/0! | AJ16: =AVERAGE(AJ6:AJ10) -> #DIV/0! | AK16: =AVERAGE(AK6:AK10) -> 85.5
A17: OFICCINA/CURSO | B17: EVASÃO | H17: EVASÃO | N17: EVASÃO | T17: EVASÃO | Z17: EVASÃO | AF17: EVASÃO
A18: DANÇA SONHAR - MANHÃ | G18: =SUM(B18:F18) -> 0 | M18: =SUM(H18:L18) -> 0 | S18: =SUM(N18:R18) -> 0 | Y18: =SUM(T18:X18) -> 0 | AE18: =SUM(Z18:AD18) -> 0 | AK18: =SUM(AF18:AJ18) -> 0
A19: DANÇA SONHAR - TARDE | G19: =SUM(B19:F19) -> 0 | M19: =SUM(H19:L19) -> 0 | S19: =SUM(N19:R19) -> 0 | Y19: =SUM(T19:X19) -> 0 | AE19: =SUM(Z19:AD19) -> 0 | AK19: =SUM(AF19:AJ19) -> 0
A20: CONTRATURNO MANHÃ | G20: =SUM(B20:F20) -> 0 | M20: =SUM(H20:L20) -> 0 | S20: =SUM(N20:R20) -> 0 | Y20: =SUM(T20:X20) -> 0 | AE20: =SUM(Z20:AD20) -> 0 | AJ20: 1 | AK20: =SUM(AF20:AJ20) -> 1
A21: CONTRATURNO TARDE
A22: CAPOEIRA CASA SONHAR TARDE
A23: LABORATORIO PERCUSSIVO SONHAR
A24: RECREAÇÃO
A25: ARTES
A26: TOTAL | B26: =AVERAGE(B18:B23) -> #DIV/0! | C26: =AVERAGE(C18:C23) -> #DIV/0! | D26: =AVERAGE(D18:D23) -> #DIV/0! | E26: =AVERAGE(E18:E23) -> #DIV/0! | F26: =AVERAGE(F18:F23) -> #DIV/0! | G26: =SUM(G18:G23) -> 0 | H26: =AVERAGE(H18:H23) -> #DIV/0! | I26: =AVERAGE(I18:I23) -> #DIV/0! | J26: =AVERAGE(J18:J23) -> #DIV/0! | K26: =AVERAGE(K18:K23) -> #DIV/0! | L26: =AVERAGE(L18:L23) -> #DIV/0! | M26: =SUM(M18:M23) -> 0 | N26: =AVERAGE(N18:N23) -> #DIV/0! | O26: =AVERAGE(O18:O23) -> #DIV/0! | P26: =AVERAGE(P18:P23) -> #DIV/0! | Q26: =AVERAGE(Q18:Q23) -> #DIV/0! | R26: =AVERAGE(R18:R23) -> #DIV/0! | S26: =SUM(S18:S23) -> 0 | T26: =AVERAGE(T18:T23) -> #DIV/0! | U26: =AVERAGE(U18:U23) -> #DIV/0! | V26: =AVERAGE(V18:V23) -> #DIV/0! | W26: =AVERAGE(W18:W23) -> #DIV/0! | X26: =AVERAGE(X18:X23) -> #DIV/0! | Y26: =SUM(Y18:Y23) -> 0 | Z26: =AVERAGE(Z18:Z23) -> #DIV/0! | AA26: =AVERAGE(AA18:AA23) -> #DIV/0! | AB26: =AVERAGE(AB18:AB23) -> #DIV/0! | AC26: =AVERAGE(AC18:AC23) -> #DIV/0! | AD26: =AVERAGE(AD18:AD23) -> #DIV/0! | AF26: =AVERAGE(AF18:AF23) -> #DIV/0! | AG26: =AVERAGE(AG18:AG23) -> #DIV/0! | AH26: =AVERAGE(AH18:AH23) -> #DIV/0! | AI26: =AVERAGE(AI18:AI23) -> #DIV/0! | AJ26: =AVERAGE(AJ18:AJ23) -> 1 | AK26: =SUM(AK18:AK23) -> 1
A28: OFICINA/CURSO | B28: QUANTIDADE DE ALUNOS | H28: QUANTIDADE DE ALUNOS | N28: QUANTIDADE DE ALUNOS | T28: QUANTIDADE DE ALUNOS | Z28: QUANTIDADE DE ALUNOS | AF28: QUANTIDADE DE ALUNOS
A29: DANÇA SONHAR - MANHÃ | F29: 22 | G29: =F29 -> 22 | H29: 22 | L29: 22 | M29: =SUM(L29) -> 22 | R29: 22 | S29: =SUM(N29:R29) -> 22 | X29: 22 | Y29: =SUM(T29:X29) -> 22 | AD29: 22 | AE29: =SUM(Z29:AD29) -> 22 | AJ29: 22 | AK29: =AJ29 -> 22
A30: DANÇA SONHAR - TARDE | F30: 20 | G30: =F30 -> 20 | H30: 20 | L30: 20 | M30: 20 | R30: 20 | S30: =SUM(N30:R30) -> 20 | X30: 20 | Y30: =SUM(T30:X30) -> 20 | AD30: 20 | AE30: =SUM(Z30:AD30) -> 20 | AJ30: 20 | AK30: =AJ30 -> 20
A31: CONTRATURNO MANHÃ | F31: 17 | G31: =F31 -> 17 | H31: 17 | L31: 17 | M31: =SUM(L31) -> 17 | R31: 19 | S31: =SUM(N31:R31) -> 19 | X31: 19 | Y31: =SUM(T31:X31) -> 19 | AD31: 19 | AE31: =SUM(Z31:AD31) -> 19 | AJ31: 19 | AK31: =AJ31 -> 19
A32: CONTRATURNO TARDE | F32: 11 | G32: =F32 -> 11 | H32: 14 | L32: 12 | M32: 12 | R32: 21 | S32: =SUM(N32:R32) -> 21 | X32: 21 | Y32: =SUM(T32:X32) -> 21 | AD32: 21 | AE32: =SUM(Z32:AD32) -> 21 | AJ32: 21 | AK32: =AJ32 -> 21
A33: CAPOEIRA CASA SONHAR TARDE | R33: 17 | S33: =SUM(N33:R33) -> 17 | X33: 17 | Y33: =SUM(T33:X33) -> 17 | AD33: 17 | AE33: =SUM(Z33:AD33) -> 17 | AJ33: 17 | AK33: =AJ33 -> 17
A34: LABORATORIO PERCUSSIVO SONHAR | F34: 10 | G34: =F34 -> 10 | H34: 9 | L34: 10 | M34: =SUM(L34) -> 10 | R34: 10 | S34: =SUM(N34:R34) -> 10 | X34: 10 | Y34: =SUM(T34:X34) -> 10 | AD34: 10 | AE34: =SUM(Z34:AD34) -> 10 | AJ34: 10 | AK34: =AJ34 -> 10
A35: LABORATORIO PERCUSSIVO MANHA | X35: 21 | Y35: =SUM(T35:X35) -> 21 | AD35: 21 | AE35: =SUM(Z35:AD35) -> 21 | AJ35: 21 | AK35: =AJ35 -> 21
A36: RECREAÇÃO | AE36: 15 | AJ36: 15 | AK36: =AJ36 -> 15
A37: ARTES | AD37: 18 | AE37: =SUM(Z37:AD37) -> 18 | AJ37: 18 | AK37: =AJ37 -> 18
A38: TOTAL | B38: =AVERAGE(B29:B34) -> #DIV/0! | C38: =AVERAGE(C29:C34) -> #DIV/0! | D38: =AVERAGE(D29:D34) -> #DIV/0! | E38: =AVERAGE(E29:E34) -> #DIV/0! | F38: =SUM(F29:F34) -> 80 | G38: =SUM(G29:G34) -> 80 | H38: =SUM(H29:H34) -> 82 | I38: =SUM(I29:I34) -> 0 | J38: =SUM(J29:J34) -> 0 | K38: =SUM(K29:K34) -> 0 | L38: =SUM(L29:L34) -> 81 | M38: =SUM(M29:M34) -> 81 | N38: =AVERAGE(N29:N34) -> #DIV/0! | O38: =AVERAGE(O29:O34) -> #DIV/0! | P38: =AVERAGE(P29:P34) -> #DIV/0! | Q38: =AVERAGE(Q29:Q34) -> #DIV/0! | S38: =SUM(S29:S34) -> 109 | T38: =AVERAGE(T29:T34) -> #DIV/0! | U38: =AVERAGE(U29:U34) -> #DIV/0! | V38: =AVERAGE(V29:V34) -> #DIV/0! | W38: =AVERAGE(W29:W34) -> #DIV/0! | X38: =SUM(X29:X35) -> 130 | Y38: =SUM(Y29:Y35) -> 130 | Z38: =AVERAGE(Z29:Z34) -> #DIV/0! | AA38: =AVERAGE(AA29:AA34) -> #DIV/0! | AB38: =AVERAGE(AB29:AB34) -> #DIV/0! | AC38: =AVERAGE(AC29:AC34) -> #DIV/0! | AD38: =AVERAGE(AD29:AD35) -> 18.571429 | AE38: =SUM(AE29:AE37) -> 163 | AF38: =AVERAGE(AF29:AF34) -> #DIV/0! | AG38: =AVERAGE(AG29:AG34) -> #DIV/0! | AH38: =AVERAGE(AH29:AH34) -> #DIV/0! | AI38: =AVERAGE(AI29:AI34) -> #DIV/0! | AJ38: =AVERAGE(AJ29:AJ34) -> 18.166667 | AK38: =SUM(AK29:AK37) -> 163
A39: CRITÉRIO DE SUCESSO | G39: =SUM(B39:F39) -> 0 | M39: =SUM(H39:L39) -> 0 | S39: =SUM(N39:R39) -> 0 | Y39: =SUM(T39:X39) -> 0 | AE39: =SUM(Z39:AD39) -> 0 | AK39: =SUM(AF39:AJ39) -> 0
A40: NPS | M40: =L40 -> 0 | S40: =SUM(N40:R40) -> 0 | Y40: =SUM(T40:X40) -> 0 | AE40: =SUM(Z40:AD40) -> 0 | AK40: =SUM(AF40:AJ40) -> 0

Sheet Gloria Marques
B2: FEVEREIRO | H2: MARÇO | N2: ABRIL | T2: MAIO | Z2: JUNHO | AF2: JULHO | AL2: AGOSTO | AR2: SETEMBRO | AX2: OUTUBRO | BD2: NOVEMBRO | BJ2: DEZEMBRO
A3: INDICADOR | B3: SEMANA 1 | C3: SEMANA 2 | D3: SEMANA 3 | E3: SEMANA 4 | F3: SEMANA 5 | G3: TOTAL | H3: SEMANA 1 | I3: SEMANA 2 | J3: SEMANA 3 | K3: SEMANA 4 | L3: SEMANA 5 | M3: TOTAL | N3: SEMANA 1 | O3: SEMANA 2 | P3: SEMANA 3 | Q3: SEMANA 4 | R3: SEMANA 5 | S3: TOTAL | T3: SEMANA 1 | U3: SEMANA 2 | V3: SEMANA 3 | W3: SEMANA 4 | X3: SEMANA 5 | Y3: TOTAL | Z3: SEMANA 1 | AA3: SEMANA 2 | AB3: SEMANA 3 | AC3: SEMANA 4 | AD3: SEMANA 5 | AE3: TOTAL | AF3: SEMANA 1 | AG3: SEMANA 2 | AH3: SEMANA 3 | AI3: SEMANA 4 | AJ3: SEMANA 5 | AK3: TOTAL | AL3: SEMANA 1 | AM3: SEMANA 2 | AN3: SEMANA 3 | AO3: SEMANA 4 | AP3: SEMANA 5 | AQ3: TOTAL | AR3: SEMANA 1 | AS3: SEMANA 2 | AT3: SEMANA 3 | AU3: SEMANA 4 | AV3: SEMANA 5 | AW3: TOTAL | AX3: SEMANA 1 | AY3: SEMANA 2 | AZ3: SEMANA 3 | BA3: SEMANA 4 | BB3: SEMANA 5 | BC3: TOTAL | BD3: SEMANA 1 | BE3: SEMANA 2 | BF3: SEMANA 3 | BG3: SEMANA 4 | BH3: SEMANA 5 | BI3: TOTAL | BJ3: SEMANA 1 | BK3: SEMANA 2 | BL3: SEMANA 3 | BM3: SEMANA 4 | BN3: SEMANA 5 | BO3: TOTAL
B4: PREENCHER | H4: PREENCHER | N4: PREENCHER | T4: PREENCHER | Z4: PREENCHER | AF4: PREENCHER | AL4: PREENCHER | AR4: PREENCHER | AX4: PREENCHER | BD4: PREENCHER | BJ4: PREENCHER
A5: Polo Contagem - Gloria | B5: FREQUENCIA | H5: FREQUENCIA | N5: FREQUENCIA | T5: FREQUENCIA | Z5: FREQUENCIA | AF5: FREQUENCIA | AL5: FREQUENCIA | AR5: FREQUENCIA | AX5: FREQUENCIA | BD5: FREQUENCIA | BJ5: FREQUENCIA
A6: CAPOEIRA 01 | B6: 95 | C6: 79 | E6: 84.2 | G6: =AVERAGE(B6:F6) -> 86.066667 | H6: 84.2 | I6: 94.7 | J6: 100 | K6: 100 | M6: =AVERAGE(H6:L6) -> 94.725 | N6: 89.5 | Q6: 78.9 | R6: 84.2 | S6: =AVERAGE(N6:R6) -> 84.2 | T6: 89.5 | U6: 78.9 | V6: 74 | W6: 73.7 | Y6: =AVERAGE(T6:X6) -> 79.025 | Z6: 87 | AA6: 100 | AB6: _ | AC6: 93 | AE6: =AVERAGE(Z6:AD6) -> 93.333333 | AF6: _ | AG6: 85 | AH6: _ | AI6: _ | AK6: =AVERAGE(AF6:AJ6) -> 85 | AL6: 100 | AM6: 80 | AN6: 75 | AO6: _ | AQ6: =AVERAGE(AL6:AP6) -> 85 | AR6: 90 | AS6: _ | AT6: _ | AU6: _ | AV6: 80 | AW6: =AVERAGE(AR6:AV6) -> 85 | AX6: 85 | AY6: _ | AZ6: 90 | BA6: _ | BB6: _ | BC6: =AVERAGE(AX6:BB6) -> 87.5 | BE6: 65 | BF6: 80 | BG6: 95 | BI6: =AVERAGE(BD6:BH6) -> 80
A7: CAPOEIRA 02 | B7: 47.4 | C7: 31.6 | E7: 36.8 | G7: =AVERAGE(B7:F7) -> 38.6 | H7: 47.4 | I7: 63.2 | J7: 73.7 | K7: 78.9 | M7: =AVERAGE(H7:L7) -> 65.8 | N7: 73.7 | Q7: 63.2 | R7: 63.2 | S7: =AVERAGE(N7:R7) -> 66.7 | T7: 78.9 | U7: 78.9 | V7: 68 | W7: 78.9 | Y7: =AVERAGE(T7:X7) -> 76.175 | Z7: _ | AA7: 75 | AB7: _ | AC7: 93.8 | AE7: =AVERAGE(Z7:AD7) -> 84.4 | AF7: _ | AG7: 81.3 | AH7: 81 | AI7: _ | AK7: =AVERAGE(AF7:AJ7) -> 81.15 | AL7: 92 | AM7: _ | AN7: 83 | AO7: 75 | AQ7: =AVERAGE(AL7:AP7) -> 83.333333 | AR7: 100 | AS7: _ | AT7: _ | AU7: _ | AV7: _ | AW7: =AVERAGE(AR7:AV7) -> 100 | AX7: _ | AY7: _ | AZ7: _ | BA7: _ | BB7: _
A8: FUTEBOL 01 | B8: 100 | C8: 81.1 | E8: 75.7 | G8: =AVERAGE(B8:F8) -> 85.6 | H8: 89.2 | I8: 73 | J8: 83.8 | K8: 81.1 | M8: =AVERAGE(H8:L8) -> 82 | N8: 100 | Q8: 83.8 | R8: 86.5 | S8: =AVERAGE(N8:R8) -> 90.1 | T8: 75.7 | U8: 76 | V8: 73 | W8: 86.5 | Y8: =AVERAGE(T8:X8) -> 77.8 | Z8: 79 | AA8: 87 | AB8: _ | AC8: 82 | AE8: =AVERAGE(Z8:AD8) -> 82.666667 | AF8: _ | AG8: _ | AH8: _ | AI8: _ | AJ8: _ | AL8: 97 | AM8: _ | AN8: _ | AO8: 100 | AQ8: =AVERAGE(AL8:AP8) -> 98.5 | AR8: 76 | AS8: 73 | AT8: _ | AU8: _ | AV8: _ | AW8: =AVERAGE(AR8:AV8) -> 74.5 | AX8: 81 | AY8: _ | AZ8: 81 | BA8: _ | BB8: _ | BC8: =AVERAGE(AX8:BB8) -> 81 | BD8: 67 | BE8: _ | BF8: 83 | BI8: =AVERAGE(BD8:BH8) -> 75
A9: FUTEBOL 02 | B9: 100 | C9: 78.8 | E9: 87.9 | G9: =AVERAGE(B9:F9) -> 88.9 | H9: 81.8 | I9: 97 | J9: 87.9 | K9: 87.9 | M9: =AVERAGE(H9:L9) -> 89.4 | N9: 81.8 | Q9: 75.8 | R9: 84.8 | S9: =AVERAGE(N9:R9) -> 80.8 | T9: 75.8 | V9: 64 | W9: 81.8 | Y9: =AVERAGE(T9:X9) -> 73.866667 | Z9: 84 | AA9: 91 | AB9: _ | AC9: _ | AE9: =AVERAGE(Z9:AD9) -> 87.5 | AF9: _ | AG9: 94 | AH9: _ | AK9: =AVERAGE(AF9:AJ9) -> 94 | AL9: 100 | AM9: 94 | AN9: 85 | AO9: 88 | AQ9: =AVERAGE(AL9:AP9) -> 91.75 | AR9: 94 | AS9: 100 | AT9: _ | AU9: 97 | AV9: _ | AW9: =AVERAGE(AR9:AV9) -> 97 | AX9: 84 | AY9: _ | AZ9: 100 | BA9: 79 | BB9: _ | BC9: =AVERAGE(AX9:BB9) -> 87.666667 | BE9: 82 | BF9: 82 | BI9: =AVERAGE(BD9:BH9) -> 82 | BJ9: 87 | BO9: =AVERAGE(BJ9:BN9) -> 87
A10: JIU JITSU 01 | B10: 100 | C10: 100 | E10: 100 | G10: =AVERAGE(B10:F10) -> 100 | H10: 100 | I10: 100 | J10: 93.3 | K10: 100 | M10: =AVERAGE(H10:L10) -> 98.325 | R10: 80 | T10: 86.7 | U10: 80 | V10: 80 | W10: 73.3 | Y10: =AVERAGE(T10:X10) -> 80 | Z10: _ | AA10: 94 | AB10: _ | AC10: 75 | AE10: =AVERAGE(Z10:AD10) -> 84.5 | AF10: _ | AG10: _ | AH10: _ | AI10: _ | AJ10: _ | AL10: 80 | AM10: _ | AN10: _ | AO10: _ | AQ10: =AVERAGE(AL10:AP10) -> 80 | AR10: _ | AS10: _ | AT10: _ | AU10: 92 | AV10: 85 | AW10: =AVERAGE(AR10:AV10) -> 88.5 | AX10: 100 | AY10: _ | AZ10: _ | BA10: 100 | BB10: _ | BC10: =AVERAGE(AX10:BB10) -> 100 | BD10: 100 | BE10: 100 | BF10: 83 | BI10: =AVERAGE(BD10:BH10) -> 94.333333
A11: JIU JITSU 02 | B11: 87 | C11: 60 | E11: 100 | G11: =AVERAGE(B11:F11) -> 82.333333 | H11: 100 | I11: 100 | J11: 100 | K11: 86.7 | M11: =AVERAGE(H11:L11) -> 100 | N11: 80 | Q11: 80 | R11: 93.3 | S11: =AVERAGE(N11:R11) -> 84.433333 | T11: 93.3 | U11: 93.3 | V11: 87 | W11: 93.3 | Y11: =AVERAGE(T11:X11) -> 91.725 | Z11: 65 | AA11: z | AB11: _ | AC11: 76 | AE11: =AVERAGE(Z11:AD11) -> 70.5 | AF11: _ | AG11: 88 | AH11: _ | AI11: _ | AJ11: _ | AK11: =AVERAGE(AF11:AJ11) -> 88 | AL11: 93 | AM11: _ | AN11: _ | AO11: _ | AQ11: =AVERAGE(AL11:AP11) -> 93 | AR11: _ | AS11: _ | AT11: _ | AU11: 93 | AV11: 79 | AW11: =AVERAGE(AR11:AV11) -> 86 | AX11: 100 | AY11: _ | AZ11: 100 | BB11: _ | BC11: =AVERAGE(AX11:BB11) -> 100 | BE11: 100 | BF11: 91 | BI11: =AVERAGE(BD11:BH11) -> 95.5
A12: SKATE 01 | I12: 80 | J12: 70 | K12: 80 | M12: =AVERAGE(H12:L12) -> 76.666667 | N12: 94.4 | Q12: 90 | R12: 60 | S12: =AVERAGE(N12:R12) -> 81.466667 | T12: 70 | U12: 90 | V12: 90 | W12: 80 | Y12: =AVERAGE(T12:X12) -> 82.5 | Z12: 80 | AA12: 100 | AB12: _ | AC12: 100 | AE12: =AVERAGE(Z12:AD12) -> 93.333333 | AF12: _ | AG12: 90 | AH12: 100 | AI12: _ | AJ12: _ | AK12: =AVERAGE(AF12:AJ12) -> 95 | AL12: 92 | AM12: 92 | AN12: _ | AO12: 100 | AQ12: =AVERAGE(AL12:AP12) -> 94.666667 | AR12: 100 | AS12: 75 | AT12: 92 | AU12: _ | AV12: _ | AW12: =AVERAGE(AR12:AV12) -> 89 | AX12: _ | AY12: _ | AZ12: _ | BB12: _ | BD12: 100 | BE12: 92 | BF12: 92 | BG12: 100 | BI12: =AVERAGE(BD12:BH12) -> 96
A13: SKATE 02 | B13: 100 | C13: 67 | E13: 94.4 | G13: =AVERAGE(B13:F13) -> 87.133333 | H13: 94.4 | I13: 100 | J13: 93 | K13: 100 | M13: =AVERAGE(H13:L13) -> 96.85 | N13: 100 | Q13: 94.4 | R13: 83.3 | S13: =AVERAGE(N13:R13) -> 92.566667 | T13: 94.4 | U13: 78 | V13: 88.9 | W13: 94.4 | Y13: =AVERAGE(T13:X13) -> 88.925 | Z13: 84 | AA13: 84 | AB13: _ | AC13: 79 | AE13: =AVERAGE(Z13:AD13) -> 82.333333 | AF13: _ | AG13: _ | AH13: 89 | AI13: _ | AJ13: _ | AK13: =AVERAGE(AF13:AJ13) -> 89 | AL13: 100 | AM13: 90 | AN13: 86 | AO13: _ | AQ13: =AVERAGE(AL13:AP13) -> 92 | AR13: 86 | AS13: _ | AT13: _ | AU13: 93 | AV13: _ | AX13: 93 | AY13: _ | AZ13: 79 | BB13: _ | BC13: =AVERAGE(AX13:BB13) -> 86 | BD13: 86 | BF13: 86 | BI13: =AVERAGE(BD13:BH13) -> 86
A14: DANÇA 01 | B14: 82 | C14: 66 | E14: 57.9 | G14: =AVERAGE(B14:F14) -> 68.633333 | H14: 60.5 | I14: 57.9 | J14: 57.9 | K14: 68.4 | M14: =AVERAGE(H14:L14) -> 61.175 | N14: 65.8 | Q14: 71.1 | R14: 60.5 | S14: =AVERAGE(N14:R14) -> 65.8 | T14: 86.8 | U14: 68.4 | V14: 71.1 | W14: 73.7 | Y14: =AVERAGE(T14:X14) -> 75 | Z14: 92 | AA14: 96 | AB14: _ | AC14: _ | AE14: =AVERAGE(Z14:AD14) -> 94 | AF14: _ | AG14: _ | AH14: _ | AI14: _ | AJ14: _ | AL14: 100 | AM14: _ | AN14: 92 | AO14: 100 | AQ14: =AVERAGE(AL14:AP14) -> 97.333333 | AR14: 81 | AS14: 85 | AT14: _ | AU14: _ | AV14: 88 | AW14: =AVERAGE(AR14:AV14) -> 84.666667 | AX14: 85 | AY14: _ | AZ14: 85 | BA14: 88 | BB14: _ | BC14: =AVERAGE(AX14:BB14) -> 86 | BD14: 88 | BE14: 88 | BF14: 88 | BI14: =AVERAGE(BD14:BH14) -> 88
A15: DANÇA 02 | B15: 100 | C15: 100 | E15: 85 | G15: =AVERAGE(B15:F15) -> 95 | H15: 90 | I15: 100 | J15: 95 | K15: 75 | M15: =AVERAGE(H15:L15) -> 90 | N15: 90 | Q15: 70 | R15: 95 | S15: =AVERAGE(N15:R15) -> 85 | T15: 90 | U15: 80 | V15: 65 | W15: 90 | Y15: =AVERAGE(T15:X15) -> 81.25 | Z15: _ | AB15: _ | AC15: _ | AF15: _ | AG15: _ | AH15: _ | AI15: _ | AJ15: _ | AL15: _ | AM15: _ | AN15: _ | AO15: _ | AR15: _ | AS15: _ | AT15: _ | AU15: _ | AV15: _ | AX15: _ | AY15: _ | AZ15: _ | BA15: _ | BB15: _ | BD15: _ | BE15: _
A16: TEATRO 01 | B16: 100 | C16: 100 | E16: 86.7 | G16: =AVERAGE(B16:F16) -> 95.566667 | H16: 100 | I16: 100 | J16: 100 | K16: 93.3 | M16: =AVERAGE(H16:L16) -> 98.325 | N16: 93.3 | Q16: 66.7 | R16: 100 | S16: =AVERAGE(N16:R16) -> 86.666667 | T16: 66.7 | U16: 80 | V16: 86.7 | W16: 93.3 | Y16: =AVERAGE(T16:X16) -> 81.675 | Z16: 89 | AA16: 78 | AB16: _ | AC16: 88.9 | AE16: =AVERAGE(Z16:AD16) -> 85.3 | AF16: _ | AG16: _ | AH16: 95 | AI16: _ | AJ16: _ | AK16: =AVERAGE(AF16:AJ16) -> 95 | AL16: 95 | AM16: 85 | AN16: 65 | AO16: 70 | AQ16: =AVERAGE(AL16:AP16) -> 78.75 | AR16: 100 | AS16: _ | AT16: 94 | AU16: 100 | AV16: 94 | AW16: =AVERAGE(AR16:AV16) -> 97 | AX16: _ | AY16: _ | AZ16: 94 | BA16: 78 | BB16: _ | BC16: =AVERAGE(AX16:BB16) -> 86 | BD16: 72 | BE16: 94 | BF16: 89 | BI16: =AVERAGE(BD16:BH16) -> 85
A17: TEATRO 02 | B17: 80 | C17: 50 | E17: 100 | G17: =AVERAGE(B17:F17) -> 76.666667 | H17: 100 | I17: 100 | J17: 100 | K17: 100 | M17: =AVERAGE(H17:L17) -> 100 | N17: 100 | Q17: 100 | R17: 100 | S17: =AVERAGE(N17:R17) -> 100 | T17: 93.3 | U17: 100 | V17: 100 | W17: 93.3 | Y17: =AVERAGE(T17:X17) -> 96.65 | Z17: 72 | AA17: 89 | AB17: _ | AC17: 72 | AE17: =AVERAGE(Z17:AD17) -> 77.666667 | AF17: `_ | AG17: 91 | AH17: 91 | AI17: _ | AJ17: _ | AK17: =AVERAGE(AF17:AJ17) -> 91 | AL17: 100 | AM17: 100 | AN17: 82 | AO17: 91 | AQ17: =AVERAGE(AL17:AP17) -> 93.25 | AR17: 91 | AS17: 91 | AT17: _ | AU17: 100 | AV17: _ | AW17: =AVERAGE(AR17:AV17) -> 94 | AX17: _ | AY17: _ | AZ17: 100 | BA17: 68 | BB17: _ | BC17: =AVERAGE(AX17:BB17) -> 84 | BD17: 72 | BE17: 92 | BF17: 80 | BI17: =AVERAGE(BD17:BH17) -> 81.333333
A18: PERCUSSÃO 01 | B18: 100 | C18: 84.2 | E18: 100 | G18: =AVERAGE(B18:F18) -> 94.733333 | H18: 100 | I18: 100 | J18: 100 | K18: 94.7 | M18: =AVERAGE(H18:L18) -> 98.675 | N18: 100 | P18: 100 | Q18: 57.9 | R18: 100 | S18: =AVERAGE(N18:R18) -> 89.475 | T18: 100 | U18: 94.7 | V18: 84.2 | W18: 78.9 | Y18: =AVERAGE(T18:X18) -> 89.45 | Z18: 84.2 | AA18: 89 | AB18: _ | AC18: _ | AE18: =AVERAGE(Z18:AD18) -> 86.6 | AF18: _ | AG18: _ | AH18: _ | AI18: _ | AJ18: _ | AO18: _ | AR18: 90 | AS18: 95 | AT18: _ | AU18: 100 | AV18: _ | AW18: =AVERAGE(AR18:AV18) -> 95 | AX18: 100 | AY18: _ | AZ18: 100 | BA18: 100 | BB18: _ | BC18: =AVERAGE(AX18:BB18) -> 100 | BE18: _
A19: PERCUSSÃO 02 | AA19: 85 | AB19: 95 | AC19: 100 | AD19: 100 | AE19: =AVERAGE(Z19:AD19) -> 95 | AF19: _ | AG19: 90 | AH19: 90 | AI19: _ | AJ19: _ | AK19: =AVERAGE(AF19:AJ19) -> 90 | AL19: 80 | AM19: 90 | AN19: 95 | AO19: 80 | AQ19: =AVERAGE(AL19:AP19) -> 86.25 | AT19: _ | AX19: _ | AY19: _ | AZ19: _ | BA19: _ | BB19: _ | BD19: 95 | BE19: 100 | BF19: 89 | BI19: =AVERAGE(BD19:BH19) -> 94.666667
A20: SERENATA | AA20: 80 | AB20: 100 | AC20: 100 | AD20: 100 | AE20: =AVERAGE(Z20:AD20) -> 95 | AF20: _ | AG20: 92 | AH20: 100 | AI20: 90 | AJ20: _ | AK20: =AVERAGE(AF20:AJ20) -> 94 | AL20: 84 | AM20: 90 | AN20: 90 | AO20: 92 | AQ20: =AVERAGE(AL20:AP20) -> 89 | AR20: 96 | AS20: _ | AT20: _ | AU20: 78 | AV20: 86 | AW20: =AVERAGE(AR20:AV20) -> 86.666667 | AX20: 84 | AY20: 82 | AZ20: 78 | BA20: _ | BB20: _ | BC20: =AVERAGE(AX20:BB20) -> 81.333333 | BD20: 82 | BE20: 73 | BF20: 76 | BG20: 73 | BI20: =AVERAGE(BD20:BH20) -> 76 | BJ20: 80 | BO20: =AVERAGE(BJ20:BN20) -> 80
A21: Dança Conteporânea Avançada | AX21: 100 | AY21: 100 | AZ21: 100 | BA21: 100 | BB21: _ | BC21: =AVERAGE(AX21:BB21) -> 100 | BD21: 100 | BE21: 100 | BF21: 93 | BG21: 100 | BH21: 100 | BI21: =AVERAGE(BD21:BH21) -> 98.6 | BK21: 100 | BO21: =AVERAGE(BJ21:BN21) -> 100
A22: DANÇA SONHAR - MANHÃ | AL22: Não se aplica | AR22: Não se aplica | AX22: Não se aplica | BD22: Não se aplica | BJ22: Não se aplica
A23: DANÇA SONHAR - TARDE | AL23: Não se aplica | AR23: Não se aplica | AX23: Não se aplica | BD23: Não se aplica | BJ23: Não se aplica
A24: CONTRATURNO MANHÃ | AL24: Não se aplica | AR24: Não se aplica | AX24: Não se aplica | BD24: Não se aplica | BJ24: Não se aplica
A25: CONTRATURNO TARDE | AL25: Não se aplica | AR25: Não se aplica | AX25: Não se aplica | BD25: Não se aplica | BJ25: Não se aplica
A26: LABORATORIO PERCUSSIVO SONHAR | D26: 87.5 | E26: 85 | G26: =AVERAGE(B26:F26) -> 86.25 | H26: 85 | I26: 80 | J26: 90 | K26: 85 | M26: =AVERAGE(H26:K26) -> 85 | N26: 77.5 | O26: 87.5 | P26: 82.5 | Q26: 65 | R26: 72.5 | S26: =AVERAGE(N26:R26) -> 77 | V26: 72.5 | W26: 100 | Y26: =AVERAGE(T26:X26) -> 86.25 | Z26: 89.2 | AA26: 89.2 | AB26: 97.3 | AC26: 100 | AD26: 89 | AE26: =AVERAGE(Z26:AD26) -> 92.94 | AL26: Não se aplica | AR26: Não se aplica | AX26: Não se aplica | BD26: Não se aplica | BJ26: Não se aplica
A27: SOCIO EMOCIONAL PEC | AG27: 100 | AK27: =AG27 -> 100 | AN27: 100 | AQ27: =AVERAGE(AL27:AP27) -> 100
A28: TOTAL | B28: =AVERAGE(B6:B26) -> 90.95 | C28: =AVERAGE(C6:C26) -> 74.808333 | D28: =AVERAGE(D6:D26) -> 87.5 | E28: =AVERAGE(E6:E26) -> 84.123077 | F28: =AVERAGE(F6:F26) -> #DIV/0! | G28: =AVERAGE(G6:G26) -> 83.498718 | H28: =AVERAGE(H6:H26) -> 87.115385 | I28: =AVERAGE(I6:I26) -> 88.985714 | ... AF28: =AVERAGE(AF6:AF26) -> #DIV/0! | AG28: =AVERAGE(AG6:AG27) -> 90.144444 | AH28: =AVERAGE(AH6:AH26) -> 92.285714 | AI28: =AVERAGE(AI6:AI26) -> 90 | AJ28: =AVERAGE(AJ6:AJ26) -> #DIV/0! | AK28: =AVERAGE(AK6:AK27) -> 91.104545 | AL28: =AVERAGE(AL6:AL26) -> 93.307692 | AM28: =AVERAGE(AM6:AM26) -> 90.125 | AN28: =AVERAGE(AN6:AN26) -> 83.666667 | AO28: =AVERAGE(AO6:AO26) -> 88.444444 | AP28: =AVERAGE(AP6:AP26) -> #DIV/0! | AQ28: =AVERAGE(AQ6:AQ27) -> 90.202381 | AR28: =AVERAGE(AR6:AR26) -> 91.272727 | AS28: =AVERAGE(AS6:AS26) -> 86.5 | AT28: =AVERAGE(AT6:AT26) -> 93 | AU28: =AVERAGE(AU6:AU26) -> 94.125 | AV28: =AVERAGE(AV6:AV26) -> 85.333333 | AW28: =AVERAGE(AW6:AW26) -> 89.777778 | AX28: =AVERAGE(AX6:AX26) -> 91.2 | AY28: =AVERAGE(AY6:AY26) -> 91 | ... BO28: =AVERAGE(BO6:BO26) -> 89
A29: OFICCINA/CURSO | B29: EVASÃO | H29: EVASÃO | N29: EVASÃO | T29: EVASÃO | Z29: EVASÃO | AF29: EVASÃO | AL29: EVASÃO | AR29: EVASÃO | AX29: EVASÃO | BD29: EVASÃO | BJ29: EVASÃO
A30: CAPOEIRA 01 | G30: =SUM(B30:F30) -> 0 | M30: =SUM(H30:L30) -> 0 | R30: 1 | S30: =SUM(N30:R30) -> 1 | X30: 7 | Y30: =SUM(T30:X30) -> 7 | AE30: =SUM(Z30:AD30) -> 0 | AJ30: 9 | AK30: =SUM(AF30:AJ30) -> 9 | AQ30: =SUM(AL30:AP30) -> 0 | AW30: =SUM(AR30:AV30) -> 0 | BC30: =SUM(AX30:BB30) -> 0 | BI30: =SUM(BD30:BH30) -> 0 | BN30: 0 | BO30: =SUM(BJ30:BN30) -> 0
A31: CAPOEIRA 02 | G31: =SUM(B31:F31) -> 0 | M31: =SUM(H31:L31) -> 0 | S31: =SUM(N31:R31) -> 0 | Y31: =SUM(T31:X31) -> 0 | AE31: =SUM(Z31:AD31) -> 0 | AJ31: 1 | AK31: =SUM(AF31:AJ31) -> 1 | AQ31: =SUM(AL31:AP31) -> 0 | AW31: =SUM(AR31:AV31) -> 0 | BC31: =SUM(AX31:BB31) -> 0 | BI31: =SUM(BD31:BH31) -> 0 | BN31: 0 | BO31: =SUM(BJ31:BN31) -> 0
A32: FUTEBOL 01 | G32: =SUM(B32:F32) -> 0 | M32: =SUM(H32:L32) -> 0 | S32: =SUM(N32:R32) -> 0 | Y32: =SUM(T32:X32) -> 0 | AE32: =SUM(Z32:AD32) -> 0 | AJ32: 4 | AK32: =SUM(AF32:AJ32) -> 4 | AQ32: =SUM(AL32:AP32) -> 0 | AW32: =SUM(AR32:AV32) -> 0 | BC32: =SUM(AX32:BB32) -> 0 | BI32: =SUM(BD32:BH32) -> 0 | BN32: 0 | BO32: =SUM(BJ32:BN32) -> 0
A33: FUTEBOL 02 | S33: =SUM(N33:R33) -> 0 | AJ33: 0 | BN33: 1
A34: JIU JITSU 01 | S34: =SUM(N34:R34) -> 0 | AJ34: 0 | BN34: 1
A35: JIU JITSU 02 | S35: =SUM(N35:R35) -> 0 | AJ35: 1 | BN35: 0
A36: SKATE 01 | S36: =SUM(N36:R36) -> 0 | AJ36: 0 | BN36: 0
A37: SKATE 02 | S37: =SUM(N37:R37) -> 0 | AJ37: 1 | BN37: 8
A38: DANÇA 01 | O38: 2 | S38: =SUM(N38:R38) -> 2 | U38: 2 | AJ38: 2 | BN38: 1
A39: DANÇA 02 | S39: =SUM(N39:R39) -> 0 | AJ39: 0 | BN39: 0
A40: TEATRO 01 | G40: =SUM(B40:F40) -> 0 | M40: =SUM(H40:L40) -> 0 | S40: =SUM(N40:R40) -> 0 | Y40: =SUM(T40:X40) -> 0 | AE40: =SUM(Z40:AD40) -> 0 | AJ40: 1 | AK40: =SUM(AF40:AJ40) -> 1 | AQ40: =SUM(AL40:AP40) -> 0 | AW40: =SUM(AR40:AV40) -> 0 | BC40: =SUM(AX40:BB40) -> 0 | BI40: =SUM(BD40:BH40) -> 0 | BN40: 0 | BO40: =SUM(BJ40:BN40) -> 0
A41: TEATRO 02 | G41: =SUM(B41:F41) -> 0 | M41: =SUM(H41:L41) -> 0 | S41: =SUM(N41:R41) -> 0 | Y41: =SUM(T41:X41) -> 0 | AE41: =SUM(Z41:AD41) -> 0 | AJ41: 1 | AK41: =SUM(AF41:AJ41) -> 1 | AQ41: =SUM(AL41:AP41) -> 0 | AW41: =SUM(AR41:AV41) -> 0 | BC41: =SUM(AX41:BB41) -> 0 | BI41: =SUM(BD41:BH41) -> 0 | BN41: 0 | BO41: =SUM(BJ41:BN41) -> 0
...

Sheet PSICO.MARKETING
A1: INDICADORES INSTITUTO O GRITO
C2: Fevereiro | I2: Março | O2: Abril | U2: Maio | AA2: Junho | AG2: Julho | AM2: Agosto | AS2: SETEMBRO | AY2: OUTUBRO | BE2: NOVEMBRO | BK2: DEZEMBRO
A3: SETOR | B3: INDICADOR | C3: SEMANA 1 | D3: SEMANA 2 | E3: SEMANA 3 | F3: SEMANA 4 | G3: SEMANA 5 | H3: TOTAL | I3: SEMANA 1 | J3: SEMANA 2 | K3: SEMANA 3 | L3: SEMANA 4 | M3: SEMANA 5 | N3: TOTAL | O3: SEMANA 1 | P3: SEMANA 2 | Q3: SEMANA 3 | R3: SEMANA 4 | S3: SEMANA 5 | T3: TOTAL | U3: SEMANA 1 | V3: SEMANA 2 | W3: SEMANA 3 | X3: SEMANA 4 | Y3: SEMANA 5 | Z3: TOTAL | AA3: SEMANA 1 | AB3: SEMANA 2 | AC3: SEMANA 3 | AD3: SEMANA 4 | AE3: SEMANA 5 | AF3: TOTAL | AG3: SEMANA 1 | AH3: SEMANA 2 | AI3: SEMANA 3 | AJ3: SEMANA 4 | AK3: SEMANA 5 | AL3: TOTAL | AM3: SEMANA 1 | AN3: SEMANA 2 | AO3: SEMANA 3 | AP3: SEMANA 4 | AQ3: SEMANA 5 | AR3: TOTAL | AS3: SEMANA 1 | AT3: SEMANA 2 | AU3: SEMANA 3 | AV3: SEMANA 4 | AW3: SEMANA 5 | AX3: TOTAL | AY3: SEMANA 1 | AZ3: SEMANA 2 | BA3: SEMANA 3 | BB3: SEMANA 4 | BC3: SEMANA 5 | BD3: TOTAL | BE3: SEMANA 1 | BF3: SEMANA 2 | BG3: SEMANA 3 | BH3: SEMANA 4 | BI3: SEMANA 5 | BJ3: TOTAL | BK3: SEMANA 1 | BL3: SEMANA 2 | BM3: SEMANA 3 | BN3: SEMANA 4 | BO3: SEMANA 5 | BP3: TOTAL
C4: PREENCHER | I4: PREENCHER | O4: PREENCHER | U4: PREENCHER | AA4: PREENCHER | AG4: PREENCHER | AM4: PREENCHER | AS4: PREENCHER | AY4: PREENCHER | BE4: PREENCHER | BK4: PREENCHER
A5: PSICO | B5: Atenção Social | C5: 0 | D5: 1 | E5: 10 | F5: 4 | G5: 0 | H5: =SUM(C5:G5) -> 15 | I5: 7 | J5: 12 | K5: 8 | L5: 9 | M5: 5 | N5: =SUM(I5:M5) -> 41 | O5: 5 | P5: 4 | Q5: 10 | R5: 23 | S5: 0 | T5: =SUM(O5:S5) -> 42 | U5: 3 | V5: 5 | W5: 30 | X5: 40 | Y5: 0 | Z5: =SUM(U5:Y5) -> 78 | AA5: 8 | AB5: 15 | AC5: 5 | AD5: 12 | AE5: 6 | AF5: =SUM(AA5:AE5) -> 46 | AG5: 8 | AH5: 11 | AI5: 13 | AJ5: 9 | AK5: 2 | AL5: =SUM(AG5:AK5) -> 43 | AM5: 4 | AN5: 7 | AO5: 7 | AP5: 19 | AQ5: 6 | AR5: =SUM(AM5:AQ5) -> 43 | AS5: 0 | AT5: 6 | AU5: 12 | AV5: 10 | AW5: 12 | AX5: =SUM(AS5:AW5) -> 40 | AY5: 8 | AZ5: 9 | BA5: 7 | BB5: 16 | BC5: 0 | BD5: =SUM(AY5:BC5) -> 40 | BE5: 5 | BF5: 11 | BG5: 2 | BH5: 7 | BI5: 18 | BJ5: =SUM(BE5:BI5) -> 43 | BK5: 2 | BL5: 4 | BM5: 7 | BN5: 7 | BP5: =SUM(BK5:BO5) -> 20
B6: Socio Emocional | C6: 0 | D6: 0 | E6: 0 | F6: 20 | G6: 0 | H6: =SUM(C6:G6) -> 20 | I6: 0 | J6: 0 | K6: 0 | L6: 18 | M6: 72 | N6: =SUM(I6:M6) -> 90 | O6: 0 | P6: 0 | Q6: 0 | R6: 124 | S6: 0 | T6: =SUM(O6:S6) -> 124 | U6: 29 | V6: 0 | W6: 0 | X6: 146 | Y6: 0 | Z6: =SUM(U6:Y6) -> 175 | AA6: 0 | AB6: 0 | AC6: 0 | AD6: 26 | AE6: 59 | AF6: =SUM(AA6:AE6) -> 85 | AG6: 47 | AH6: 32 | AI6: 9 | AJ6: 0 | AK6: 0 | AL6: =SUM(AG6:AK6) -> 88 | AM6: 0 | AN6: 0 | AO6: 80 | AP6: 16 | AQ6: 0 | AR6: =SUM(AM6:AQ6) -> 96 | AS6: 19 | AT6: 0 | AU6: 0 | AV6: 51 | AW6: 18 | AX6: =SUM(AS6:AW6) -> 88 | AY6: 0 | AZ6: 0 | BA6: 78 | BB6: 10 | BC6: 0 | BD6: =SUM(AY6:BC6) -> 88 | BE6: 39 | BF6: 0 | BG6: 41 | BH6: 0 | BI6: 0 | BJ6: =SUM(BE6:BI6) -> 80 | BK6: 46 | BL6: 0 | BM6: 49 | BN6: 0 | BP6: =SUM(BK6:BO6) -> 95
B7: Espaço O Grito | C7: 0 | D7: 0 | E7: 0 | F7: 1 | G7: 0 | H7: =SUM(C7:G7) -> 1 | I7: 0 | J7: 0 | K7: 0 | L7: 1 | M7: 0 | N7: =SUM(I7:M7) -> 1 | O7: 0 | P7: 1 | Q7: 0 | R7: 0 | S7: 0 | T7: =SUM(O7:S7) -> 1 | U7: 0 | V7: 0 | W7: 0 | X7: 0 | Y7: 0 | Z7: =SUM(U7:Y7) -> 0 | AA7: 0 | AB7: 0 | AC7: 0 | AD7: 0 | AE7: 1 | AF7: =SUM(AA7:AE7) -> 1 | AG7: 1 | AH7: 0 | AI7: 0 | AJ7: 0 | AK7: 0 | AL7: =SUM(AG7:AK7) -> 1 | AM7: 0 | AN7: 0 | AO7: 0 | AP7: 1 | AQ7: 0 | AR7: =SUM(AM7:AQ7) -> 1 | AS7: 0 | AT7: 0 | AU7: 2 | AV7: 0 | AW7: 0 | AX7: =SUM(AS7:AW7) -> 2 | AY7: 0 | AZ7: 0 | BA7: 0 | BB7: 1 | BC7: 0 | BD7: =SUM(AY7:BC7) -> 1 | BE7: 0 | BF7: 0 | BG7: 0 | BH7: 1 | BI7: 0 | BJ7: =SUM(BE7:BI7) -> 1 | BK7: 0 | BL7: 0 | BM7: 1 | BN7: 0 | BP7: =SUM(BK7:BO7) -> 1
B8: Rede O Grito | C8: 0 | D8: 0 | E8: 0 | F8: 0 | G8: 0 | H8: =SUM(C8:G8) -> 0 | I8: 0 | J8: 0 | K8: 0 | L8: 1 | M8: 0 | N8: =SUM(I8:M8) -> 1 | O8: 0 | P8: 0 | Q8: 0 | R8: 0 | S8: 0 | T8: 0 | U8: 0 | V8: 0 | W8: 0 | X8: 1 | Y8: 0 | Z8: =SUM(U8:Y8) -> 1 | AA8: 0 | AB8: 0 | AC8: 0 | AD8: 1 | AE8: 0 | AF8: =SUM(AA8:AE8) -> 1 | AG8: 0 | AH8: 0 | AI8: 0 | AJ8: 0 | AK8: 1 | AL8: =SUM(AG8:AK8) -> 1 | AM8: 0 | AN8: 0 | AO8: 1 | AP8: 0 | AQ8: 1 | AR8: =SUM(AM8:AQ8) -> 2 | AS8: 0 | AT8: 0 | AU8: 0 | AV8: 0 | AW8: 1 | AX8: =SUM(AS8:AW8) -> 1 | AY8: 0 | AZ8: 0 | BA8: 0 | BB8: 1 | BC8: 0 | BD8: =SUM(AY8:BC8) -> 1 | BE8: 0 | BF8: 0 | BG8: 0 | BH8: 0 | BI8: 1 | BJ8: =SUM(BE8:BI8) -> 1 | BK8: 1 | BL8: 0 | BM8: 0 | BN8: 0 | BP8: =SUM(BK8:BO8) -> 1
A9: MKT | B9: SEGUIDORES | C9: 31 | D9: 30 | E9: 31 | F9: 8 | H9: =SUM(C9:G9) -> 100 | I9: 21 | J9: 36 | K9: 73 | L9: 23 | N9: =SUM(I9:M9) -> 153 | O9: 22 | P9: 48 | Q9: 7 | R9: 11 | T9: =SUM(O9:S9) -> 88 | U9: 34 | V9: 14 | W9: 32 | X9: 18 | Y9: 0 | Z9: 98 | AA9: 20 | AB9: 20 | AC9: 16 | AD9: 14 | AF9: =SUM(AA9:AE9) -> 70 | AG9: 14 | AH9: 20 | AI9: 50 | AJ9: 9 | AL9: =SUM(AG9:AK9) -> 93 | AM9: 21 | AN9: 19 | AO9: 28 | AP9: 96 | AR9: =SUM(AM9:AQ9) -> 164 | AS9: 27 | AT9: 17 | AU9: 37 | AV9: 34 | AX9: =SUM(AS9:AW9) -> 115 | AY9: 21 | AZ9: 21 | BA9: 31 | BB9: 12 | BD9: =SUM(AY9:BC9) -> 85 | BE9: 16 | BF9: 22 | BG9: 28 | BJ9: =SUM(BE9:BI9) -> 66 | BP9: =SUM(BK9:BO9) -> 0
B10: DOADOR RECOR. | H10: 0 | N10: =SUM(I10:M10) -> 0 | T10: =SUM(O10:S10) -> 0 | U10: 0 | V10: 0 | W10: 0 | X10: 0 | Z10: =SUM(U10:Y10) -> 0 | AA10: 0 | AF10: =SUM(AA10:AE10) -> 0 | AL10: =SUM(AG10:AK10) -> 0 | AR10: =SUM(AM10:AQ10) -> 0 | AX10: =SUM(AS10:AW10) -> 0 | BD10: =SUM(AY10:BC10) -> 0 | BJ10: =SUM(BE10:BI10) -> 0 | BP10: =SUM(BK10:BO10) -> 0
O12: Meta boa é Meta batida!

Sheet QP
B2: FEVEREIRO | I2: MARÇO | P2: ABRIL | W2: MAIO | AD2: JUNHO | AK2: JULHO | AR2: AGOSTO | AY2: SETEMBRO | BF2: OUTUBRO | BM2: NOVEMBRO | BT2: DEZEMBRO
A3: INDICADOR | B3: SEMANA 1 | C3: SEMANA 2 | D3: SEMANA 3 | E3: SEMANA 4 | F3: SEMANA 5 | G3: TOTAL | H3: INDICADOR | I3: SEMANA 1 | J3: SEMANA 2 | K3: SEMANA 3 | L3: SEMANA 4 | M3: SEMANA 5 | N3: TOTAL | P3: SEMANA 1 | Q3: SEMANA 2 | R3: SEMANA 3 | S3: SEMANA 4 | T3: SEMANA 5 | U3: TOTAL | W3: SEMANA 1 | X3: SEMANA 2 | Y3: SEMANA 3 | Z3: SEMANA 4 | AA3: SEMANA 5 | AB3: TOTAL | AD3: SEMANA 1 | AE3: SEMANA 2 | AF3: SEMANA 3 | AG3: SEMANA 4 | AH3: SEMANA 5 | AI3: TOTAL | AJ3: Cursos | AK3: SEMANA 1 | AL3: SEMANA 2 | AM3: SEMANA 3 | AN3: SEMANA 4 | AO3: SEMANA 5 | AP3: TOTAL | AQ3: Cursos | AR3: SEMANA 1 | AS3: SEMANA 2 | AT3: SEMANA 3 | AU3: SEMANA 4 | AV3: SEMANA 5 | AW3: TOTAL | AX3: Cursos | AY3: SEMANA 1 | AZ3: SEMANA 2 | BA3: SEMANA 3 | BB3: SEMANA 4 | BC3: SEMANA 5 | BD3: TOTAL | BE3: Cursos | BF3: SEMANA 1 | BG3: SEMANA 2 | BH3: SEMANA 3 | BI3: SEMANA 4 | BJ3: SEMANA 5 | BK3: TOTAL | BL3: Cursos | BM3: SEMANA 1 | BN3: SEMANA 2 | BO3: SEMANA 3 | BP3: SEMANA 4 | BQ3: SEMANA 5 | BR3: TOTAL | BS3: Cursos | BT3: SEMANA 1 | BU3: SEMANA 2 | BV3: SEMANA 3 | BW3: SEMANA 4 | BX3: SEMANA 5 | BY3: TOTAL
B4: PREENCHER | I4: PREENCHER | P4: PREENCHER | W4: PREENCHER | AD4: PREENCHER | AK4: PREENCHER | AR4: PREENCHER | AY4: PREENCHER | BF4: PREENCHER | BM4: PREENCHER | BT4: PREENCHER
A5: OFICINA/CURSO | B5: FREQUENCIA | H5: OFICINA/CURSO | I5: FREQUENCIA | P5: FREQUENCIA | W5: FREQUENCIA | AD5: FREQUENCIA | AK5: FREQUENCIA | AR5: FREQUENCIA | AY5: FREQUENCIA | BF5: FREQUENCIA | BM5: FREQUENCIA | BT5: FREQUENCIA
A6: Empreendedorismo EAD | B6: 100 | C6: 100 | D6: 100 | E6: 94 | F6: 97 | G6: =AVERAGE(B6:F6) -> 98.2 | H6: Marketing Digital | I6: 100 | J6: 100 | K6: 81 | L6: 85 | M6: 96 | N6: =AVERAGE(I6:M6) -> 92.4 | O6: 1- Manicure e Pedicure | P6: 100 | Q6: 96.88 | R6: 87.5 | S6: 81.25 | U6: =AVERAGE(P6:T6) -> 91.4075 | V6: Assistente Jurirido | W6: 100 | X6: 99 | Y6: 91 | Z6: 81 | AA6: 79 | AB6: =AVERAGE(W6:AA6) -> 90 | AC6: 1-Canva | AD6: 100 | AE6: 100 | AF6: 89 | AG6: 93 | AH6: 84 | AI6: =AVERAGE(AD6:AH6) -> 93.2 | AJ6: 1- Departamento Pessoal EAD | AK6: 100 | AL6: 91 | AM6: 86 | AN6: 85 | AP6: =AVERAGE(AK6:AO6) -> 90.5 | AQ6: 1- Preparo de Massas Senac | AR6: 100 | AW6: =AVERAGE(AR6:AV6) -> 100 | AX6: 1- Fashion Marketing Digital | AY6: 100 | AZ6: 100 | BD6: =AVERAGE(AY6:BC6) -> 100 | BE6: 1- Farmacia e Drogaria | BF6: 80 | BG6: 75 | BH6: 69 | BI6: 100 | BK6: =AVERAGE(BF6:BJ6) -> 81 | BL6: 1 - Formação Jovem | BN6: 73 | BO6: 48 | BP6: 48 | BQ6: 100 | BR6: =AVERAGE(BM6:BQ6) -> 67.25 | BS6: Artesanato Natalino 01 - Programa 40+ | BU6: 96 | BY6: =AVERAGE(BT6:BX6) -> 96
A7: Logistica EAD | B7: 100 | C7: 100 | D7: 74 | E7: 93 | F7: 89 | G7: =AVERAGE(B7:F7) -> 91.2 | H7: Decoração de festa com Balões | J7: 94.12 | K7: 88 | L7: 95 | N7: =AVERAGE(I7:M7) -> 92.373333 | O7: 2 - Excel | P7: 100 | Q7: 100 | R7: 88.89 | S7: 87 | U7: =AVERAGE(P7:T7) -> 93.9725 | V7: Atendente de Farmacia | W7: 87.5 | X7: 80 | Y7: 77 | Z7: 71.67 | AA7: 75 | AB7: =AVERAGE(W7:AA7) -> 78.234 | AC7: 2-Gestão de Projetos | AD7: 100 | AE7: 100 | AF7: 89 | AG7: 100 | AH7: 94 | AI7: =AVERAGE(AD7:AH7) -> 96.6 | AJ7: 2- Edição de Video | AL7: 100 | AM7: 76 | AN7: 79 | AP7: =AVERAGE(AK7:AO7) -> 85 | AQ7: 2- Contabilidade EAD | AR7: 100 | AS7: 100 | AT7: 82.14 | AU7: 88.1 | AV7: 74 | AW7: =AVERAGE(AR7:AV7) -> 88.848 | AX7: 2- Formação Jovem | AY7: 93 | AZ7: 92 | BA7: 80 | BB7: 80 | BC7: 47 | BD7: =AVERAGE(AY7:BC7) -> 78.4 | BE7: 2- Preparo de Pães, Roscas e Biscoitos Tradicionais | BF7: 100 | BK7: =AVERAGE(BF7:BJ7) -> 100 | BL7: 2 - Atendente de Telemarketing | BO7: 100 | BP7: 100 | BQ7: 100 | BR7: =AVERAGE(BM7:BQ7) -> 100 | BS7: Atividade Física e Nutricional - Programa 40+ | BT7: 96 | BY7: =AVERAGE(BT7:BX7) -> 96
A8: Recursos Humanos | B8: 100 | C8: 100 | D8: 79 | E8: 97 | F8: 95 | G8: =AVERAGE(B8:F8) -> 94.2 | H8: Trancista Profissional | J8: 88 | K8: 85 | L8: 87 | M8: 83 | N8: =AVERAGE(I8:M8) -> 85.75 | O8: 3- Administração EAD | P8: 89.47 | Q8: 92.11 | R8: 87.5 | S8: 91.27 | U8: =AVERAGE(P8:T8) -> 90.0875 | V8: Design de Sobrancelha | X8: 98 | Y8: 88 | Z8: 73 | AA8: 100 | AB8: =AVERAGE(W8:AA8) -> 89.75 | AC8: 3- Jovem Falcão | AE8: 85 | AF8: 85 | AI8: =AVERAGE(AD8:AH8) -> 85 | AJ8: 3-Auto maquiagem | AL8: 83 | AM8: 87 | AN8: 79 | AP8: =AVERAGE(AK8:AO8) -> 83 | AQ8: 3- Capacitação e Assistência Basica ao Idoso EAD | AR8: 100 | AS8: 100 | AT8: 92.86 | AU8: 92.86 | AV8: 92 | AW8: =AVERAGE(AR8:AV8) -> 95.544 | AX8: 3- Design de Sobrancelha e Epilação Egípcia | AY8: 86 | AZ8: 87 | BD8: =AVERAGE(AY8:BC8) -> 86.5 | BE8: 3- Tecnicas de Depilação | BF8: 100 | BK8: =AVERAGE(BF8:BJ8) -> 100 | BL8: 3 - Design de Sobranacelhas | BO8: 100 | BP8: 100 | BR8: =AVERAGE(BM8:BQ8) -> 100 | BS8: Artesanato Natalino 02 - Programa 40+ | BV8: 87 | BY8: =AVERAGE(BT8:BX8) -> 87
G9: =AVERAGE(B9:F9) -> #DIV/0! | H9: Informatica | K9: 92 | L9: 95 | M9: 95 | N9: =AVERAGE(I9:M9) -> 94 | O9: 4- Jovem Falcão | Q9: 90 | R9: 90 | S9: 90 | T9: 85 | U9: =AVERAGE(P9:T9) -> 88.75 | V9: 4- Jovem Falcão | W9: 100 | Y9: 80 | Z9: 75 | AB9: =AVERAGE(W9:AA9) -> 85 | AC9: 4- Design De Sobrancelha A Ponte | AE9: 95 | AF9: 97 | AG9: 95 | AH9: 100 | AI9: =AVERAGE(AD9:AH9) -> 96.75 | AJ9: 4- Informatica | AM9: 97 | AN9: 96 | AO9: 100 | AP9: =AVERAGE(AK9:AO9) -> 97.666667 | AQ9: 4- Preparo de Pães,Roscas e Biscoitos Tradicionais Senac | AS9: 89.93 | AT9: 76.79 | AW9: 90 | AX9: 4- Preparo de Bolos e Tortas | BA9: 97 | BD9: 90 | BE9: 4- Preparo de Salgado | BF9: 96 | BK9: =AVERAGE(BF9:BJ9) -> 96 | BL9: 4 - Quitandas tradicionais Mineiras | BO9: 100 | BP9: 100 | BR9: =AVERAGE(BM9:BQ9) -> 100
G10: =AVERAGE(B10:F10) -> #DIV/0! | N10: =AVERAGE(I10:M10) -> #DIV/0! | AC10: 5- Oficina Introdutoria | AD10: 100 | AE10: 100 | AI10: =AVERAGE(AD10:AH10) -> 100 | AQ10: 5- Montagem de Computadores Senac | AS10: 100 | AT10: 88 | AU10: 90 | AV10: 83 | AW10: 100 | AX10: 5- Preparo de Salgados | BB10: 96 | BD10: 100 | BE10: 5- Preparo de Pizza | BF10: 98 | BK10: =AVERAGE(BF10:BJ10) -> 98 | BL10: 5 - Preparo de Bolos e Tortas | BO10: 100 | BP10: 100 | BR10: =AVERAGE(BM10:BQ10) -> 100
G11: =AVERAGE(B11:F11) -> #DIV/0! | N11: =AVERAGE(I11:M11) -> #DIV/0! | AC11: 6- Costura | AG11: 100 | AH11: 100 | AI11: =AVERAGE(AD11:AH11) -> 100 | AQ11: 6- Design de Sobrancelha e Epilação Egipicia | AT11: 94 | AU11: 92.86 | AV11: 85 | AX11: 6- Preparo de Molhos Quentes e Frios | BC11: 98 | BE11: 6- Formação Jovem | BF11: 73 | BG11: 60 | BH11: 66 | BK11: =AVERAGE(BF11:BJ11) -> 66.333333 | BL11: 6- Porteiro | BM11: 100 | BN11: 100 | BR11: =AVERAGE(BM11:BQ11) -> 100
G12: =AVERAGE(B12:F12) -> #DIV/0! | N12: =AVERAGE(I12:M12) -> #DIV/0! | AQ12: 7- Preparo de Bolos e Tortas | AU12: 96.82 | AX12: 7- Preparo de Pães, Roscas e Biscoitos Tradicionais | BC12: 100 | BE12: 7- Hardware: Montagem de Computador | BF12: 100 | BG12: 100 | BH12: 100 | BI12: 100 | BJ12: 100 | BK12: =AVERAGE(BF12:BJ12) -> 100 | BL12: 7- Atividade fisica e nutricional | BN12: 62 | BO12: 100 | BP12: 100 | BQ12: 73 | BR12: =AVERAGE(BM12:BQ12) -> 83.75
G13: =AVERAGE(B13:F13) -> #DIV/0! | N13: =AVERAGE(I13:M13) -> #DIV/0! | AQ13: 8- Preparo de Pizza | BE13: 8- Tecnicas Basicas para Porteiro | BF13: 100 | BG13: 100 | BH13: 100 | BI13: 100 | BJ13: 100 | BK13: =AVERAGE(BF13:BJ13) -> 100
G14: =AVERAGE(B14:F14) -> #DIV/0! | N14: =AVERAGE(I14:M14) -> #DIV/0! | U14: =AVERAGE(P14:T14) -> #DIV/0! | BE14: 9- Tecnicas Basicas de Depilação | BH14: 97 | BI14: 98 | BK14: =AVERAGE(BF14:BJ14) -> 97.5
BE15: 10- Tecnicas Basicas Para Pizza | BH15: 100 | BK15: =AVERAGE(BF15:BJ15) -> 100
BE16: 11- Qualidade no Atendimento | BI16: 100 | BJ16: 100 | BK16: =AVERAGE(BF16:BJ16) -> 100
BE17: 12- Preparo de Massa
BE18: 13- Design de Sobrancelha Senac | BH18: 100 | BK18: =AVERAGE(BF18:BJ18) -> 100
BE19: 14 - Técnicas basicas de salgados | BH19: 100 | BK19: =AVERAGE(BF19:BJ19) -> 100
A21: TOTAL | B21: =AVERAGE(B6:B14) -> 100 | C21: =AVERAGE(C6:C14) -> 100 | D21: =AVERAGE(D6:D14) -> 84.333333 | E21: =AVERAGE(E6:E14) -> 94.666667 | F21: =AVERAGE(F6:F14) -> 93.666667 | G21: =AVERAGE(G6:G8) -> 94.533333 | H21: TOTAL | I21: =AVERAGE(I6:I14) -> 100 | J21: =AVERAGE(J6:J14) -> 94.04 | K21: =AVERAGE(K6:K14) -> 86.5 | L21: =AVERAGE(L6:L14) -> 90.5 | M21: =AVERAGE(M6:M14) -> 91.333333 | N21: =AVERAGE(N6:N9) -> 91.130833 | P21: =AVERAGE(P6:P14) -> 96.49 | Q21: =AVERAGE(Q6:Q14) -> 94.7475 | R21: =AVERAGE(R6:R14) -> 88.4725 | S21: =AVERAGE(S6:S14) -> 87.38 | T21: =AVERAGE(T6:T14) -> 85 | U21: =AVERAGE(U6:U9) -> 91.054375 | W21: =AVERAGE(W6:W14) -> 95.833333 | X21: =AVERAGE(X6:X14) -> 92.333333 | Y21: =AVERAGE(Y6:Y14) -> 84 | Z21: =AVERAGE(Z6:Z14) -> 75.1675 | AA21: =AVERAGE(AA6:AA14) -> 84.666667 | AB21: =AVERAGE(AB6:AB13) -> 85.746 | AD21: =AVERAGE(AD6:AD14) -> 100 | AE21: =AVERAGE(AE6:AE14) -> 96 | AF21: =AVERAGE(AF6:AF14) -> 90 | AG21: =AVERAGE(AG6:AG14) -> 97 | AH21: =AVERAGE(AH6:AH14) -> 94.5 | AI21: =AVERAGE(AI6:AI14) -> 95.258333 | AK21: =AVERAGE(AK6:AK14) -> 100 | AL21: =AVERAGE(AL6:AL14) -> 91.333333 | AM21: =AVERAGE(AM6:AM14) -> 86.5 | AN21: =AVERAGE(AN6:AN14) -> 84.75 | AO21: =AVERAGE(AO6:AO14) -> 100 | AP21: =AVERAGE(AP6:AP14) -> 89.041667 | AR21: =AVERAGE(AR6:AR14) -> 100 | AS21: =AVERAGE(AS6:AS14) -> 97.4825 | AT21: =AVERAGE(AT6:AT14) -> 86.758 | AU21: =AVERAGE(AU6:AU14) -> 92.128 | AV21: =AVERAGE(AV6:AV14) -> 83.5 | AW21: =AVERAGE(AW6:AW14) -> 94.8784 | AY21: =AVERAGE(AY6:AY14) -> 93 | AZ21: =AVERAGE(AZ6:AZ14) -> 93 | BA21: =AVERAGE(BA6:BA14) -> 88.5 | BB21: =AVERAGE(BB6:BB14) -> 88 | BC21: =AVERAGE(BC6:BC14) -> 81.666667 | BD21: =AVERAGE(BD6:BD14) -> 90.98 | BF21: =AVERAGE(BF6:BF14) -> 93.375 | BG21: =AVERAGE(BG6:BG14) -> 83.75 | BH21: =AVERAGE(BH6:BH14) -> 86.4 | BI21: =AVERAGE(BI6:BI14) -> 99.5 | BJ21: =AVERAGE(BJ6:BJ14) -> 100 | BK21: =AVERAGE(BK6:BK20) -> 95.294872 | BM21: =AVERAGE(BM6:BM14) -> 100 | BN21: =AVERAGE(BN6:BN14) -> 78.333333 | BO21: =AVERAGE(BO6:BO14) -> 91.333333 | BP21: =AVERAGE(BP6:BP14) -> 91.333333 | BQ21: =AVERAGE(BQ6:BQ14) -> 91 | BR21: =AVERAGE(BR6:BR20) -> 93 | BT21: =AVERAGE(BT6:BT14) -> 96 | BU21: =AVERAGE(BU6:BU14) -> 96 | BV21: =AVERAGE(BV6:BV14) -> 87 | BW21: =AVERAGE(BW6:BW14) -> #DIV/0! | BX21: =AVERAGE(BX6:BX14) -> #DIV/0! | BY21: =AVERAGE(BY6:BY20) -> 93
A22: OFICCINA/CURSO | B22: EVASÃO | H22: OFICCINA/CURSO | I22: EVASÃO | P22: EVASÃO | W22: EVASÃO | AD22: EVASÃO | AK22: EVASÃO | AR22: EVASÃO | AY22: EVASÃO | BF22: EVASÃO | BM22: EVASÃO | BT22: EVASÃO
A23: Empreendedorismo EAD | G23: =SUM(B23:F23) -> 0 | H23: Marketing Digital | N23: =SUM(I23:M23) -> 0 | O23: 1- Manicure e Pedicure | U23: =SUM(P23:T23) -> 0 | V23: Assistente Jurirido | W23: 2 | AB23: =SUM(W23:AA23) -> 2 | AC23: Canva | AI23: =SUM(AD23:AH23) -> 0 | AJ23: 1- Departamento Pessoal EAD | AP23: =SUM(AK23:AO23) -> 0 | AQ23: 1- Preparo de Massas Senac | AW23: =SUM(AR23:AV23) -> 0 | AX23: 1- Fashion Marketing Digital | BD23: =SUM(AY23:BC23) -> 0 | BE23: 1- Farmacia e Drogaria | BK23: =SUM(BF23:BJ23) -> 0 | BL23: 1 - Formação Jovem | BR23: =SUM(BM23:BQ23) -> 0 | BS23: Artesanato Natalino 01 - Programa 40+ | BY23: =SUM(BT23:BX23) -> 0
A24: Logistica EAD | G24: =SUM(B24:F24) -> 0 | H24: Decoração de festa com Balões | I24: 4 | N24: =SUM(I24:M24) -> 4 | O24: 2 - Excel | U24: =SUM(P24:T24) -> 0 | V24: Atendente de Farmacia | W24: 1 | AB24: =SUM(W24:AA24) -> 1 | AC24: Gestão de Projetos | AI24: =SUM(AD24:AH24) -> 0 | AJ24: 2- Edição de Video | AP24: =SUM(AK24:AO24) -> 0 | AQ24: 2- Contabilidade EAD | AW24: =SUM(AR24:AV24) -> 0 | AX24: 2- Formação Jovem | BD24: =SUM(AY24:BC24) -> 0 | BE24: 2- Preparo de Pães, Roscas e Biscoitos Tradicionais | BK24: =SUM(BF24:BJ24) -> 0 | BL24: 2 - Atendente de Telemarketing | BO24: 2 | BR24: =SUM(BM24:BQ24) -> 2 | BS24: Atividade Física e Nutricional - Programa 40+ | BY24: =SUM(BT24:BX24) -> 0
A25: Recursos Humanos | F25: 1 | G25: =SUM(B25:F25) -> 1 | H25: Trancista Profissional | N25: =SUM(I25:M25) -> 0 | O25: 3- Administração EAD | P25: 1 | U25: =SUM(P25:T25) -> 1 | V25: Design de Sobrancelha | AB25: =SUM(W25:AA25) -> 0 | AC25: Formação Jovem | AD25: 2 | AI25: =SUM(AD25:AH25) -> 2 | AJ25: 3-Auto maquiagem | AP25: =SUM(AK25:AO25) -> 0 | AQ25: 3- Capacitação e Assistência Basica ao Idoso EAD | AW25: =SUM(AR25:AV25) -> 0 | AX25: 3- Design de Sobrancelha e Epilação Egipicia | BD25: =SUM(AY25:BC25) -> 0 | BE25: 3- Tecnicas de Depilação | BK25: =SUM(BF25:BJ25) -> 0 | BL25: 3 - Design de Sobranacelhas | BR25: =SUM(BM25:BQ25) -> 0 | BS25: Artesanato Natalino 02 - Programa 40+ | BY25: =SUM(BT25:BX25) -> 0
G26: =SUM(B26:F26) -> 0 | H26: Informatica | I26: 1 | N26: =SUM(I26:M26) -> 1 | U26: =SUM(P26:T26) -> 0 | AB26: =SUM(W26:AA26) -> 0 | AC26: Oficina Introdutoria | AI26: =SUM(AD26:AH26) -> 0 | AJ26: 4- Informatica | AP26: =SUM(AK26:AO26) -> 0 | AQ26: 4- Preparo de Pães,Roscas e Biscoitos Tradicionais Senac | AR26: 1 | AW26: =SUM(AR26:AV26) -> 1 | AX26: 4- Preparo de Bolos e Tortas | BD26: =SUM(AY26:BC26) -> 0 | BE26: 4- Preparo de Salgado | BK26: =SUM(BF26:BJ26) -> 0 | BL26: 4 - Quitandas Mineiras | BR26: =SUM(BM26:BQ26) -> 0 | BY26: =SUM(BT26:BX26) -> 0
G27: =SUM(B27:F27) -> 0 | N27: =SUM(I27:M27) -> 0 | U27: =SUM(P27:T27) -> 0 | AB27: =SUM(W27:AA27) -> 0 | AC27: Costura | AI27: =SUM(AD27:AH27) -> 0 | AP27: =SUM(AK27:AO27) -> 0 | AQ27: 5- Montagem de Computadores Senac | AW27: =SUM(AR27:AV27) -> 0 | AX27: 6- Preparo de Molhos Quentes e Frios | BD27: =SUM(AY27:BC27) -> 0 | BE27: 5- Preparo de Pizza | BF27: 1 | BK27: =SUM(BF27:BJ27) -> 1 | BL27: 5 - Preparo de Bolos e Tortas | BR27: =SUM(BM27:BQ27) -> 0 | BY27: =SUM(BT27:BX27) -> 0
G28: =SUM(B28:F28) -> 0 | U28: 0 | AB28: =SUM(W28:AA28) -> 0 | AQ28: 6- Design de Sobrancelha e Epilação Egipicia | BE28: 7- Hardware: Montagem de Computador | BL28: 6- Porteiro
G29: =SUM(B29:F29) -> 0 | U29: 0 | AB29: =SUM(W29:AA29) -> 0 | AQ29: 7- Preparo de Bolos e Tortas | BE29: 8- Tecnicas Basicas para Porteiro | BL29: 7- Atividade fisica e nutricional
G30: =SUM(B30:F30) -> 0 | N30: =SUM(I30:M30) -> 0 | U30: =SUM(P30:T30) -> 0 | AB30: =SUM(W30:AA30) -> 0 | AI30: =SUM(AD30:AH30) -> 0 | AP30: =SUM(AK30:AO30) -> 0 | AQ30: 8- Preparo de Pizza | AW30: =SUM(AR30:AV30) -> 0 | BD30: =SUM(AY30:BC30) -> 0 | BE30: 9- Tecnicas Basicas de Depilação | BK30: =SUM(BF30:BJ30) -> 0 | BR30: =SUM(BM30:BQ30) -> 0 | BY30: =SUM(BT30:BX30) -> 0
G31: =SUM(B31:F31) -> 0 | N31: =SUM(I31:M31) -> 0 | U31: =SUM(P31:T31) -> 0 | AI31: =SUM(AD31:AH31) -> 0 | AP31: =SUM(AK31:AO31) -> 0 | AW31: =SUM(AR31:AV31) -> 0 | BD31: =SUM(AY31:BC31) -> 0 | BE31: 10- Tecnicas Basicas Para Pizza | BK31: =SUM(BF31:BJ31) -> 0 | BR31: =SUM(BM31:BQ31) -> 0 | BY31: =SUM(BT31:BX31) -> 0
BE32: 11- Qualidade no Atendimento
BE33: 12- Preparo de Massa | BF33: 1
BE34: 13- Design de Sobrancelha Senac
BE35: 14 - Técnicas basicas de salgados
A36: TOTAL | B36: =AVERAGE(B23:B31) -> #DIV/0! | C36: =AVERAGE(C23:C31) -> #DIV/0! | D36: =AVERAGE(D23:D31) -> #DIV/0! | E36: =AVERAGE(E23:E31) -> #DIV/0! | F36: =AVERAGE(F23:F31) -> 1 | G36: =SUM(G23:G31) -> 1 | H36: TOTAL | I36: =AVERAGE(I23:I31) -> 2.5 | J36: =AVERAGE(J23:J31) -> #DIV/0! | K36: =AVERAGE(K23:K31) -> #DIV/0! | L36: =AVERAGE(L23:L31) -> #DIV/0! | M36: =AVERAGE(M23:M31) -> #DIV/0! | N36: =SUM(N23:N31) -> 5 | P36: =AVERAGE(P23:P31) -> 1 | Q36: =AVERAGE(Q23:Q31) -> #DIV/0! | R36: =AVERAGE(R23:R31) -> #DIV/0! | S36: =AVERAGE(S23:S31) -> #DIV/0! | T36: =AVERAGE(T23:T31) -> #DIV/0! | U36: =SUM(U23:U31) -> 1 | W36: =AVERAGE(W23:W31) -> 1.5 | X36: =AVERAGE(X23:X31) -> #DIV/0! | Y36: =AVERAGE(Y23:Y31) -> #DIV/0! | Z36: =AVERAGE(Z23:Z31) -> #DIV/0! | AA36: =AVERAGE(AA23:AA31) -> #DIV/0! | AB36: =(AB37*100)/'INDICADORES GERAL'!$D$22 -> 5 | AD36: =AVERAGE(AD23:AD31) -> 2 | AE36: =AVERAGE(AE23:AE31) -> #DIV/0! | AF36: =SUM(AF23:AF31) -> 0 | AG36: =AVERAGE(AG23:AG31) -> #DIV/0! | AH36: =AVERAGE(AH23:AH31) -> #DIV/0! | AI36: =(AI37*100)/'INDICADORES GERAL'!$D$22 -> 3.3333333 | AK36: =AVERAGE(AK23:AK31) -> #DIV/0! | AL36: =AVERAGE(AL23:AL31) -> #DIV/0! | AM36: =AVERAGE(AM23:AM31) -> #DIV/0! | AN36: =AVERAGE(AN23:AN31) -> #DIV/0! | AO36: =AVERAGE(AO23:AO31) -> #DIV/0! | AP36: =AP37/'INDICADORES GERAL'!$D$22 -> 0 | AR36: =AVERAGE(AR23:AR31) -> 1 | AS36: =AVERAGE(AS23:AS31) -> #DIV/0! | AT36: =AVERAGE(AT23:AT31) -> #DIV/0! | AU36: =AVERAGE(AU23:AU31) -> #DIV/0! | AV36: =AVERAGE(AV23:AV31) -> #DIV/0! | AW36: =AW37/'INDICADORES GERAL'!$D$22 -> 0.016666667 | AY36: =AVERAGE(AY23:AY31) -> #DIV/0! | AZ36: =AVERAGE(AZ23:AZ31) -> #DIV/0! | BA36: =AVERAGE(BA23:BA31) -> #DIV/0! | BB36: =AVERAGE(BB23:BB31) -> #DIV/0! | BC36: =AVERAGE(BC23:BC31) -> #DIV/0! | BD36: =BD37/'INDICADORES GERAL'!$D$22 -> 0 | BF36: =AVERAGE(BF23:BF31) -> 1 | BG36: =AVERAGE(BG23:BG31) -> #DIV/0! | BH36: =AVERAGE(BH23:BH31) -> #DIV/0! | BI36: =AVERAGE(BI23:BI31) -> #DIV/0! | BJ36: =AVERAGE(BJ23:BJ31) -> #DIV/0! | BK36: =BK37/'INDICADORES GERAL'!$D$22 -> 0.016666667 | BM36: =AVERAGE(BM23:BM31) -> #DIV/0! | BN36: =AVERAGE(BN23:BN31) -> #DIV/0! | BO36: =AVERAGE(BO23:BO31) -> 2 | BP36: =AVERAGE(BP23:BP31) -> #DIV/0! | BQ36: =AVERAGE(BQ23:BQ31) -> #DIV/0! | BR36: =BR37/'INDICADORES GERAL'!$D$22 -> 0.033333333 | BT36: =AVERAGE(BT23:BT31) -> #DIV/0! | BU36: =AVERAGE(BU23:BU31) -> #DIV/0! | BV36: =AVERAGE(BV23:BV31) -> #DIV/0! | BW36: =AVERAGE(BW23:BW31) -> #DIV/0! | BX36: =AVERAGE(BX23:BX31) -> #DIV/0! | BY36: =BY37/'INDICADORES GERAL'!$D$22 -> 0
G37: =SUM(G23:G31) -> 1 | N37: =SUM(N23:N31) -> 5 | U37: =SUM(U23:U31) -> 1 | AB37: =SUM(AB23:AB31) -> 3 | AI37: =SUM(AI23:AI31) -> 2 | AP37: =SUM(AP23:AP31) -> 0 | AW37: =SUM(AW23:AW31) -> 1 | BD37: =SUM(BD23:BD31) -> 0 | BK37: =SUM(BK23:BK31) -> 1 | BR37: =SUM(BR23:BR31) -> 2 | BY37: =SUM(BY23:BY31) -> 0
A38: OFICCINA/CURSO | B38: QUANTIDADE DE ALUNOS | H38: OFICCINA/CURSO | I38: QUANTIDADE DE ALUNOS | P38: QUANTIDADE DE ALUNOS | W38: QUANTIDADE DE ALUNOS | AD38: QUANTIDADE DE ALUNOS | AK38: QUANTIDADE DE ALUNOS | AR38: QUANTIDADE DE ALUNOS | AY38: QUANTIDADE DE ALUNOS | BF38: QUANTIDADE DE ALUNOS | BM38: QUANTIDADE DE ALUNOS | BT38: QUANTIDADE DE ALUNOS
A39: Empreendedorismo EAD | B39: 32 | F39: 29 | G39: 32 | H39: Marketing Digital | I39: 45 | N39: =SUM(I39:M39) -> 45 | O39: 1- Manicure e Pedicure | P39: 16 | U39: =SUM(P39:T39) -> 16 | V39: Assistente Jurirido | W39: 40 | AB39: =SUM(W39:AA39) -> 40 | AC39: Canva | AD39: 40 | AI39: =SUM(AD39:AH39) -> 40 | AJ39: 1- Departamento Pessoal EAD | AK39: 49 | AP39: =SUM(AK39:AO39) -> 49 | AQ39: 1- Preparo de Massas Senac | AR39: 16 | AW39: =SUM(AR39:AV39) -> 16 | AX39: 1- Fashion Marketing Digital | AY39: 11 | BD39: =SUM(AY39:BC39) -> 11 | BE39: 1- Farmacia e Drogaria | BF39: 16 | BK39: =SUM(BF39:BJ39) -> 16 | BL39: 1 - Formação Jovem | BM39: 17 | BR39: =SUM(BM39:BQ39) -> 17 | BS39: Artesanato Natalino 01 - Programa 40+ | BT39: 25 | BY39: =SUM(BT39:BX39) -> 25
A40: Logistica EAD | B40: 21 | F40: 19 | G40: =B40-G24 -> 21 | H40: Decoração de festa com Balões | I40: 9 | N40: =SUM(I40:M40) -> 9 | O40: 2 - Excel | P40: 18 | U40: =SUM(P40:T40) -> 18 | V40: Atendente de Farmacia | W40: 40 | AB40: =SUM(W40:AA40) -> 40 | AC40: Gestão de Projetos | AD40: 20 | AI40: =SUM(AD40:AH40) -> 20 | AJ40: 2- Edição de Video | AK40: 13 | AP40: =SUM(AK40:AO40) -> 13 | AQ40: 2- Contabilidade EAD | AR40: 42 | AW40: =SUM(AR40:AV40) -> 42 | AX40: 2- Formação Jovem | BD40: =SUM(AY40:BC40) -> 0 | BE40: 2- Preparo de Pães, Roscas e Biscoitos Tradicionais | BF40: 17 | BK40: =SUM(BF40:BJ40) -> 17 | BL40: 2 - Atendente de Telemarketing | BM40: 19 | BR40: =SUM(BM40:BQ40) -> 19 | BS40: Atividade Física e Nutricional - Programa 40+ | BT40: 53 | BY40: =SUM(BT40:BX40) -> 53
A41: Recursos Humanos | B41: 63 | F41: 62 | G41: 62 | H41: Trancista Profissional | I41: 23 | N41: =SUM(I41:M41) -> 23 | O41: 3- Administração EAD | P41: 63 | U41: =SUM(P41:T41) -> 63 | V41: Design de Sobrancelha | W41: 25 | AB41: =SUM(W41:AA41) -> 25 | AC41: Formação Jovem | AD41: 24 | AI41: =SUM(AD41:AH41) -> 24 | AJ41: 3-Auto maquiagem | AK41: 12 | AP41: =SUM(AK41:AO41) -> 12 | AQ41: 3- Capacitação e Assistência Basica ao Idoso EAD | AR41: 14 | AW41: =SUM(AR41:AV41) -> 14 | AX41: 3- Design de Sobrancelha Epilação Egipicia | AY41: 42 | BD41: =SUM(AY41:BC41) -> 42 | BE41: 3- Tecnicas de Depilação | BF41: 20 | BK41: =SUM(BF41:BJ41) -> 20 | BL41: 3 - Design de Sobranacelhas | BM41: 31 | BR41: =SUM(BM41:BQ41) -> 31 | BS41: Artesanato Natalino 02 - Programa 40+ | BT41: 23 | BY41: =SUM(BT41:BX41) -> 23
G42: 6 | H42: Informatica | I42: 19 | N42: =SUM(I42:M42) -> 19 | U42: =SUM(P42:T42) -> 0 | AB42: =SUM(W42:AA42) -> 0 | AC42: Design De Sobrancelha A Ponte | AD42: 10 | AI42: =SUM(AD42:AH42) -> 10 | AJ42: 4- Informatica | AK42: 38 | AP42: =SUM(AK42:AO42) -> 38 | AQ42: 4- Preparo de Pães,Roscas e Biscoitos Tradicionais Senac | AR42: 14 | AW42: =SUM(AR42:AV42) -> 14 | AX42: 4- Preparo de Bolos e Tortas | AY42: 23 | BD42: =SUM(AY42:BC42) -> 23 | BE42: 4- Preparo de Salgado | BF42: 19 | BK42: =SUM(BF42:BJ42) -> 19 | BL42: 4 - Quitandas Mineiras | BM42: 23 | BR42: =SUM(BM42:BQ42) -> 23 | BY42: =SUM(BT42:BX42) -> 0
...

Sheet Polo BH - A Ponte
B2: FEVEREIRO | H2: MARÇO | N2: ABRIL | T2: MAIO | Z2: JUNHO | AF2: JULHO | AL2: AGOSTO | AR2: SETEMBRO | AX2: OUTUBRO | BD2: NOVEMBRO | BJ2: DEZEMBRO
A3: INDICADOR | B3: SEMANA 1 | C3: SEMANA 2 | D3: SEMANA 3 | E3: SEMANA 4 | F3: SEMANA 5 | G3: TOTAL | H3: SEMANA 1 | I3: SEMANA 2 | J3: SEMANA 3 | K3: SEMANA 4 | L3: SEMANA 5 | M3: TOTAL | N3: SEMANA 1 | O3: SEMANA 2 | P3: SEMANA 3 | Q3: SEMANA 4 | R3: SEMANA 5 | S3: TOTAL | T3: SEMANA 1 | U3: SEMANA 2 | V3: SEMANA 3 | W3: SEMANA 4 | X3: SEMANA 5 | Y3: TOTAL | Z3: SEMANA 1 | AA3: SEMANA 2 | AB3: SEMANA 3 | AC3: SEMANA 4 | AD3: SEMANA 5 | AE3: TOTAL | AF3: SEMANA 1 | AG3: SEMANA 2 | AH3: SEMANA 3 | AI3: SEMANA 4 | AJ3: SEMANA 5 | AK3: TOTAL | AL3: SEMANA 1 | AM3: SEMANA 2 | AN3: SEMANA 3 | AO3: SEMANA 4 | AP3: SEMANA 5 | AQ3: TOTAL | AR3: SEMANA 1 | AS3: SEMANA 2 | AT3: SEMANA 3 | AU3: SEMANA 4 | AV3: SEMANA 5 | AW3: TOTAL | AX3: SEMANA 1 | AY3: SEMANA 2 | AZ3: SEMANA 3 | BA3: SEMANA 4 | BB3: SEMANA 5 | BC3: TOTAL | BD3: SEMANA 1 | BE3: SEMANA 2 | BF3: SEMANA 3 | BG3: SEMANA 4 | BH3: SEMANA 5 | BI3: TOTAL | BJ3: SEMANA 1 | BK3: SEMANA 2 | BL3: SEMANA 3 | BM3: SEMANA 4 | BN3: SEMANA 5 | BO3: TOTAL
B4: PREENCHER | H4: PREENCHER | N4: PREENCHER | T4: PREENCHER | Z4: PREENCHER | AF4: PREENCHER | AL4: PREENCHER | AR4: PREENCHER | AX4: PREENCHER | BD4: PREENCHER | BJ4: PREENCHER
A5: Polo BH - A Ponte | B5: FREQUENCIA | H5: FREQUENCIA | N5: FREQUENCIA | T5: FREQUENCIA | Z5: FREQUENCIA | AF5: FREQUENCIA | AL5: FREQUENCIA | AR5: FREQUENCIA | AX5: FREQUENCIA | BD5: FREQUENCIA | BJ5: FREQUENCIA
A6: Oficina xxxx | G6: =AVERAGE(B6:F6) -> #DIV/0! | M6: =AVERAGE(H6:I6) -> #DIV/0! | S6: =AVERAGE(N6:R6) -> #DIV/0! | Y6: =AVERAGE(T6:X6) -> #DIV/0! | AE6: =AVERAGE(Z6:AD6) -> #DIV/0! | AH6: 87.7 | AK6: 88 | AQ6: =AVERAGE(AL6:AP6) -> #DIV/0! | AW6: =AVERAGE(AR6:AS6) -> #DIV/0! | BC6: =AVERAGE(AX6:BB6) -> #DIV/0! | BI6: =AVERAGE(BD6:BH6) -> #DIV/0! | BO6: =AVERAGE(BJ6:BN6) -> #DIV/0!
A7: Oficina xxxx | G7: =AVERAGE(B7:F7) -> #DIV/0! | M7: =AVERAGE(H7:I7) -> #DIV/0! | S7: =AVERAGE(N7:R7) -> #DIV/0! | Y7: =AVERAGE(T7:X7) -> #DIV/0! | AE7: =AVERAGE(Z7:AD7) -> #DIV/0! | AF7: 88.9 | AK7: =AVERAGE(AF7:AJ7) -> 88.9 | AQ7: =AVERAGE(AL7:AP7) -> #DIV/0! | AW7: =AVERAGE(AR7:AS7) -> #DIV/0! | BC7: =AVERAGE(AX7:BB7) -> #DIV/0! | BI7: =AVERAGE(BD7:BH7) -> #DIV/0! | BO7: =AVERAGE(BJ7:BN7) -> #DIV/0!
A8: Oficina xxxx | G8: =AVERAGE(B8:F8) -> #DIV/0! | M8: =AVERAGE(H8:I8) -> #DIV/0! | S8: =AVERAGE(N8:R8) -> #DIV/0! | Y8: =AVERAGE(T8:X8) -> #DIV/0! | AE8: =AVERAGE(Z8:AD8) -> #DIV/0! | AH8: 80 | AK8: 80 | AQ8: =AVERAGE(AL8:AP8) -> #DIV/0! | AW8: =AVERAGE(AR8:AS8) -> #DIV/0! | BC8: =AVERAGE(AX8:BB8) -> #DIV/0! | BI8: =AVERAGE(BD8:BH8) -> #DIV/0! | BO8: =AVERAGE(BJ8:BN8) -> #DIV/0!
A9: Oficina xxxx
A10: Oficina xxxx | G10: =AVERAGE(B10:F10) -> #DIV/0! | M10: =AVERAGE(H10:I10) -> #DIV/0! | S10: =AVERAGE(N10:R10) -> #DIV/0! | Y10: =AVERAGE(T10:X10) -> #DIV/0! | AE10: =AVERAGE(Z10:AD10) -> #DIV/0! | AF10: 90 | AK10: =AVERAGE(AF10:AJ10) -> 90 | AQ10: =AVERAGE(AL10:AP10) -> #DIV/0! | AW10: =AVERAGE(AR10:AS10) -> #DIV/0! | BC10: =AVERAGE(AX10:BB10) -> #DIV/0! | BI10: =AVERAGE(BD10:BH10) -> #DIV/0! | BO10: =AVERAGE(BJ10:BN10) -> #DIV/0!
A11: Oficina xxxx | G11: =AVERAGE(B11:F11) -> #DIV/0! | M11: =AVERAGE(H11:I11) -> #DIV/0! | S11: =AVERAGE(N11:R11) -> #DIV/0! | Y11: =AVERAGE(T11:X11) -> #DIV/0! | AE11: =AVERAGE(Z11:AD11) -> #DIV/0! | AH11: 85.2 | AK11: 85 | AQ11: =AVERAGE(AL11:AP11) -> #DIV/0! | AW11: =AVERAGE(AR11:AS11) -> #DIV/0! | BC11: =AVERAGE(AX11:BB11) -> #DIV/0! | BI11: =AVERAGE(BD11:BH11) -> #DIV/0! | BO11: =AVERAGE(BJ11:BN11) -> #DIV/0!
A12: Oficina xxxx | G12: =AVERAGE(B12:F12) -> #DIV/0! | M12: =AVERAGE(H12:I12) -> #DIV/0! | S12: =AVERAGE(N12:R12) -> #DIV/0! | Y12: =AVERAGE(T12:X12) -> #DIV/0! | AE12: =AVERAGE(Z12:AD12) -> #DIV/0! | AF12: 87.5 | AK12: =AVERAGE(AF12:AJ12) -> 87.5 | AQ12: =AVERAGE(AL12:AP12) -> #DIV/0! | AW12: =AVERAGE(AR12:AS12) -> #DIV/0! | BC12: =AVERAGE(AX12:BB12) -> #DIV/0! | BI12: =AVERAGE(BD12:BH12) -> #DIV/0! | BO12: =AVERAGE(BJ12:BN12) -> #DIV/0!
A13: Oficina xxxx
A14: Oficina xxxx | G14: =AVERAGE(B14:F14) -> #DIV/0! | M14: =AVERAGE(H14:I14) -> #DIV/0! | S14: =AVERAGE(N14:R14) -> #DIV/0! | Y14: =AVERAGE(T14:X14) -> #DIV/0! | AE14: =AVERAGE(Z14:AD14) -> #DIV/0! | AG14: 100 | AH14: 90 | AK14: =AVERAGE(AF14:AJ14) -> 95 | AQ14: =AVERAGE(AL14:AP14) -> #DIV/0! | AW14: =AVERAGE(AR14:AS14) -> #DIV/0! | BC14: =AVERAGE(AX14:BB14) -> #DIV/0! | BI14: =AVERAGE(BD14:BH14) -> #DIV/0! | BO14: =AVERAGE(BJ14:BN14) -> #DIV/0!
A15: TOTAL | B15: =AVERAGE(B6:B14) -> #DIV/0! | C15: =AVERAGE(C6:C14) -> #DIV/0! | D15: =AVERAGE(D6:D14) -> #DIV/0! | E15: =AVERAGE(E6:E14) -> #DIV/0! | F15: =AVERAGE(F6:F14) -> #DIV/0! | G15: =AVERAGE(G6:G14) -> #DIV/0! | H15: =AVERAGE(H6:H14) -> #DIV/0! | I15: =AVERAGE(I6:I14) -> #DIV/0! | ... BO15: =AVERAGE(BO6:BO14) -> #DIV/0!
A16: OFICCINA/CURSO | B16: EVASÃO | H16: EVASÃO | N16: EVASÃO | T16: EVASÃO | Z16: EVASÃO | AF16: EVASÃO | AL16: EVASÃO | AR16: EVASÃO | AX16: EVASÃO | BD16: EVASÃO | BJ16: EVASÃO
A17: FUTEBOL | G17: =SUM(B17:F17) -> 0 | M17: =SUM(H17:L17) -> 0 | S17: =SUM(N17:R17) -> 0 | Y17: =SUM(T17:X17) -> 0 | AE17: =SUM(Z17:AD17) -> 0 | AK17: =SUM(AF17:AJ17) -> 0 | AQ17: =SUM(AL17:AP17) -> 0 | AW17: =SUM(AR17:AV17) -> 0 | BC17: =SUM(AX17:BB17) -> 0 | BI17: =SUM(BD17:BH17) -> 0 | BO17: =SUM(BJ17:BN17) -> 0
A18: JIU-JITSU | G18: =SUM(B18:F18) -> 0 | M18: =SUM(H18:L18) -> 0 | S18: =SUM(N18:R18) -> 0 | Y18: =SUM(T18:X18) -> 0 | AE18: =SUM(Z18:AD18) -> 0 | AK18: =SUM(AF18:AJ18) -> 0 | AQ18: =SUM(AL18:AP18) -> 0 | AW18: =SUM(AR18:AV18) -> 0 | BC18: =SUM(AX18:BB18) -> 0 | BI18: =SUM(BD18:BH18) -> 0 | BO18: =SUM(BJ18:BN18) -> 0
A19: SKATE | G19: =SUM(B19:F19) -> 0 | M19: =SUM(H19:L19) -> 0 | S19: =SUM(N19:R19) -> 0 | Y19: =SUM(T19:X19) -> 0 | AE19: =SUM(Z19:AD19) -> 0 | AK19: =SUM(AF19:AJ19) -> 0 | AQ19: =SUM(AL19:AP19) -> 0 | AW19: =SUM(AR19:AV19) -> 0 | BC19: =SUM(AX19:BB19) -> 0 | BI19: =SUM(BD19:BH19) -> 0 | BO19: =SUM(BJ19:BN19) -> 0
A20: BALLET | G20: =SUM(B20:F20) -> 0 | M20: =SUM(H20:L20) -> 0 | S20: =SUM(N20:R20) -> 0 | Y20: =SUM(T20:X20) -> 0 | AE20: =SUM(Z20:AD20) -> 0 | AK20: =SUM(AF20:AJ20) -> 0 | AQ20: =SUM(AL20:AP20) -> 0 | AW20: =SUM(AR20:AV20) -> 0 | BC20: =SUM(AX20:BB20) -> 0 | BI20: =SUM(BD20:BH20) -> 0 | BO20: =SUM(BJ20:BN20) -> 0
A21: PERCUSSÃO | G21: =SUM(B21:F21) -> 0 | M21: =SUM(H21:L21) -> 0 | S21: =SUM(N21:R21) -> 0 | Y21: =SUM(T21:X21) -> 0 | AE21: =SUM(Z21:AD21) -> 0 | AK21: =SUM(AF21:AJ21) -> 0 | AQ21: =SUM(AL21:AP21) -> 0 | AW21: =SUM(AR21:AV21) -> 0 | BC21: =SUM(AX21:BB21) -> 0 | BI21: =SUM(BD21:BH21) -> 0 | BO21: =SUM(BJ21:BN21) -> 0
