Workbook

Sheet RESUMO
B2: PEC | G2: Q. PROFISSIONAL | L2: OUTLET
B3: DESCRIÇÃO | C3: VALOR | D3: TOTAL | E3: MESES | G3: DESCRIÇÃO | H3: VALOR | I3: TOTAL | J3: MESES | L3: DESCRIÇÃO | M3: VALOR | N3: TOTAL | O3: MESES
B4: =PEC!B50 -> Marketing | C4: =SUM(D4/E4) -> 0 | D4: =PEC!O50 -> 0 | E4: 11 | G4: ='Q. PROF.'!B50 -> Marketing | H4: =SUM(I4/J4) -> 0 | I4: ='Q. PROF.'!O50 -> 0 | J4: 11 | L4: =OUTLET!B50 -> Marketing | M4: =SUM(N4/O4) -> 46.363636 | N4: =OUTLET!O50 -> 510 | O4: 11
B5: =PEC!B53 -> Despesas com Pessoal | C5: =SUM(D5/E5) -> 12000 | D5: =PEC!O53 -> 144000 | E5: 12 | G5: ='Q. PROF.'!B53 -> Despesas com Pessoal | H5: =SUM(I5/J5) -> 7300 | I5: ='Q. PROF.'!O53 -> 87600 | J5: 12 | L5: =OUTLET!B53 -> Despesas com Pessoal | M5: =SUM(N5/O5) -> 6650 | N5: =OUTLET!O53 -> 79800 | O5: 12
B6: =PEC!B75 -> Despesas Administrativas | C6: =SUM(D6/E6) -> 6720.8333 | D6: =PEC!O75 -> 80650 | E6: 12 | G6: ='Q. PROF.'!B75 -> Despesas Administrativas | H6: =SUM(I6/J6) -> 812.5 | I6: ='Q. PROF.'!O75 -> 9750 | J6: 12 | L6: =OUTLET!B75 -> Despesas Administrativas | M6: =SUM(N6/O6) -> 3537.5 | N6: =OUTLET!O75 -> 42450 | O6: 12
B7: =PEC!B99 -> Despesas Financeiras / Bancos | C7: =SUM(D7/E7) -> 0 | D7: =PEC!O99 -> 0 | E7: 12 | G7: ='Q. PROF.'!B99 -> Despesas Financeiras / Bancos | H7: =SUM(I7/J7) -> 0 | I7: ='Q. PROF.'!O99 -> 0 | J7: 12 | L7: =OUTLET!B99 -> Despesas Financeiras / Bancos | M7: =SUM(N7/O7) -> 50 | N7: =OUTLET!O99 -> 600 | O7: 12
B8: =PEC!B105 -> Impostos e Taxas | C8: =SUM(D8/E8) -> 0 | D8: =PEC!O105 -> 0 | E8: 12 | G8: ='Q. PROF.'!B105 -> Impostos e Taxas | H8: =SUM(I8/J8) -> 0 | I8: ='Q. PROF.'!O105 -> 0 | J8: 12 | L8: =OUTLET!B105 -> Impostos e Taxas | M8: =SUM(N8/O8) -> 0 | N8: =OUTLET!O105 -> 0 | O8: 12
B9: =PEC!B116 -> Investimento | C9: =SUM(D9/E9) -> 1550 | D9: =PEC!O116 -> 18600 | E9: 12 | G9: ='Q. PROF.'!B116 -> Investimento | H9: =SUM(I9/J9) -> 0 | I9: ='Q. PROF.'!O116 -> 0 | J9: 12 | L9: =OUTLET!B116 -> Investimento | M9: =SUM(N9/O9) -> 0 | N9: =OUTLET!O116 -> 0 | O9: 12
B10: =PEC!B126 -> Despesas Com Veículos | C10: =SUM(D10/E10) -> 0 | D10: =PEC!O126 -> 0 | E10: 11 | G10: ='Q. PROF.'!B126 -> Despesas Com Veículos | H10: =SUM(I10/J10) -> 0 | I10: ='Q. PROF.'!O126 -> 0 | J10: 11 | L10: =OUTLET!B126 -> Despesas Com Veículos | M10: =SUM(N10/O10) -> 0 | N10: =OUTLET!O126 -> 0 | O10: 11
B11: =PEC!B130 -> Despesas Com Eventos | C11: =SUM(D11/E11) -> 4163.6364 | D11: =PEC!O130 -> 45800 | E11: 11 | G11: ='Q. PROF.'!B130 -> Despesas Com Eventos | H11: =SUM(I11/J11) -> 0 | I11: ='Q. PROF.'!O130 -> 0 | J11: 11 | L11: =OUTLET!B130 -> Despesas Com Eventos | M11: =SUM(N11/O11) -> 0 | N11: =OUTLET!O130 -> 0 | O11: 11
B12: =PEC!B133 -> Despesas Matérias-Primas | C12: =SUM(D12/E12) -> 0 | D12: =PEC!O133 -> 0 | E12: 12 | G12: ='Q. PROF.'!B133 -> Despesas Matérias-Primas | H12: =SUM(I12/J12) -> 0 | I12: ='Q. PROF.'!O133 -> 0 | J12: 12 | L12: =OUTLET!B133 -> Despesas Matérias-Primas | M12: =SUM(N12/O12) -> 0 | N12: =OUTLET!O133 -> 0 | O12: 12
L13: =OUTLET!B49 -> Compras Mercadorias Revenda | M13: =SUM(N13/O13) -> 800 | N13: =OUTLET!O49 -> 9600 | O13: 12
D15: =SUM(D4:D13) -> 289050 | I15: =SUM(I4:I13) -> 97350 | N15: =SUM(N4:N13) -> 132960
B17: PSICOSSOCIAL | G17: CASA SONHAR | L17: GRIFFTE
B18: DESCRIÇÃO | C18: VALOR | D18: TOTAL | E18: MESES | G18: DESCRIÇÃO | H18: VALOR | I18: TOTAL | J18: MESES | L18: DESCRIÇÃO | M18: VALOR | N18: TOTAL | O18: MESES
B19: =PSICOSSOCIAL!B50 -> Marketing | C19: =SUM(D19/E19) -> 0 | D19: =PSICOSSOCIAL!O50 -> 0 | E19: 11 | G19: ='CASA SONHAR'!B50 -> Marketing | H19: =SUM(I19/J19) -> 72.727273 | I19: ='CASA SONHAR'!O50 -> 800 | J19: 11 | L19: =GRIFFTE!B50 -> Marketing | M19: =SUM(N19/O19) -> 0 | N19: =GRIFFTE!O50 -> 0 | O19: 11
B20: =PSICOSSOCIAL!B53 -> Despesas com Pessoal | C20: =SUM(D20/E20) -> 7291.6667 | D20: =PSICOSSOCIAL!O53 -> 87500 | E20: 12 | G20: ='CASA SONHAR'!B53 -> Despesas com Pessoal | H20: =SUM(I20/J20) -> 19414.667 | I20: ='CASA SONHAR'!O53 -> 232976 | J20: 12 | L20: =GRIFFTE!B53 -> Despesas com Pessoal | M20: =SUM(N20/O20) -> 7800 | N20: =GRIFFTE!O53 -> 93600 | O20: 12
B21: =PSICOSSOCIAL!B75 -> Despesas Administrativas | C21: =SUM(D21/E21) -> 200 | D21: =PSICOSSOCIAL!O75 -> 2400 | E21: 12 | G21: ='CASA SONHAR'!B75 -> Despesas Administrativas | H21: =SUM(I21/J21) -> 7910 | I21: ='CASA SONHAR'!O75 -> 94920 | J21: 12 | L21: =GRIFFTE!B75 -> Despesas Administrativas | M21: =SUM(N21/O21) -> 2525 | N21: =GRIFFTE!O75 -> 30300 | O21: 12
B22: =PSICOSSOCIAL!B99 -> Despesas Financeiras / Bancos | C22: =SUM(D22/E22) -> 0 | D22: =PSICOSSOCIAL!O99 -> 0 | E22: 12 | G22: ='CASA SONHAR'!B99 -> Despesas Financeiras / Bancos | H22: =SUM(I22/J22) -> 0 | I22: ='CASA SONHAR'!O99 -> 0 | J22: 12 | L22: =GRIFFTE!B99 -> Despesas Financeiras / Bancos | M22: =SUM(N22/O22) -> 50 | N22: =GRIFFTE!O99 -> 600 | O22: 12
B23: =PSICOSSOCIAL!B105 -> Impostos e Taxas | C23: =SUM(D23/E23) -> 0 | D23: =PSICOSSOCIAL!O105 -> 0 | E23: 12 | G23: ='CASA SONHAR'!B105 -> Impostos e Taxas | H23: =SUM(I23/J23) -> 0 | I23: ='CASA SONHAR'!O105 -> 0 | J23: 12 | L23: =GRIFFTE!B105 -> Impostos e Taxas | M23: =SUM(N23/O23) -> 0 | N23: =GRIFFTE!O105 -> 0 | O23: 12
B24: =PSICOSSOCIAL!B116 -> Investimento | C24: =SUM(D24/E24) -> 0 | D24: =PSICOSSOCIAL!O116 -> 0 | E24: 12 | G24: ='CASA SONHAR'!B116 -> Investimento | H24: =SUM(I24/J24) -> 1116.6667 | I24: ='CASA SONHAR'!O116 -> 13400 | J24: 12 | L24: =GRIFFTE!B116 -> Investimento | M24: =SUM(N24/O24) -> 0 | N24: =GRIFFTE!O116 -> 0 | O24: 12
B25: =PSICOSSOCIAL!B126 -> Despesas Com Veículos | C25: =SUM(D25/E25) -> 163.63636 | D25: =PSICOSSOCIAL!O126 -> 1800 | E25: 11 | G25: ='CASA SONHAR'!B126 -> Despesas Com Veículos | H25: =SUM(I25/J25) -> 0 | I25: ='CASA SONHAR'!O126 -> 0 | J25: 11 | L25: =GRIFFTE!B126 -> Despesas Com Veículos | M25: =SUM(N25/O25) -> 0 | N25: =GRIFFTE!O126 -> 0 | O25: 11
B26: =PSICOSSOCIAL!B130 -> Despesas Com Eventos | C26: =SUM(D26/E26) -> 109.09091 | D26: =PSICOSSOCIAL!O130 -> 1200 | E26: 11 | G26: ='CASA SONHAR'!B130 -> Despesas Com Eventos | H26: =SUM(I26/J26) -> 1863.6364 | I26: ='CASA SONHAR'!O130 -> 20500 | J26: 11 | L26: =GRIFFTE!B130 -> Despesas Com Eventos | M26: =SUM(N26/O26) -> 0 | N26: =GRIFFTE!O130 -> 0 | O26: 11
B27: =PSICOSSOCIAL!B133 -> Despesas Matérias-Primas | C27: =SUM(D27/E27) -> 0 | D27: =PSICOSSOCIAL!O133 -> 0 | E27: 12 | G27: ='CASA SONHAR'!B133 -> Despesas Matérias-Primas | H27: =SUM(I27/J27) -> 0 | I27: ='CASA SONHAR'!O133 -> 0 | J27: 12 | L27: =GRIFFTE!B133 -> Despesas Matérias-Primas | M27: =SUM(N27/O27) -> 0 | N27: =GRIFFTE!O133 -> 0 | O27: 12
D30: =SUM(D19:D28) -> 92900 | I30: =SUM(I19:I27) -> 362596 | N30: =SUM(N19:N28) -> 124500
B32: MARKETING | G32: ADMINISTRATIVO
B33: DESCRIÇÃO | C33: VALOR | D33: TOTAL | E33: MESES | G33: DESCRIÇÃO | H33: VALOR | I33: TOTAL | J33: MESES
B34: =MARKETING!B50 -> Marketing | C34: =SUM(D34/E34) -> 13000 | D34: =MARKETING!O50 -> 143000 | E34: 11 | G34: =ADM!B50 -> Marketing | H34: =SUM(I34/J34) -> 0 | I34: =ADM!O50 -> 0 | J34: 11
B35: =MARKETING!B53 -> Despesas com Pessoal | C35: =SUM(D35/E35) -> 8808.3333 | D35: =MARKETING!O53 -> 105700 | E35: 12 | G35: =ADM!B53 -> Despesas com Pessoal | H35: =SUM(I35/J35) -> 33050 | I35: =ADM!O53 -> 396600 | J35: 12
B36: =MARKETING!B75 -> Despesas Administrativas | C36: =SUM(D36/E36) -> 3807.1333 | D36: =MARKETING!O75 -> 45685.6 | E36: 12 | G36: =ADM!B75 -> Despesas Administrativas | H36: =SUM(I36/J36) -> 12562.5 | I36: =ADM!O75 -> 150750 | J36: 12
B37: =MARKETING!B99 -> Despesas Financeiras / Bancos | C37: =SUM(D37/E37) -> 0 | D37: =MARKETING!O99 -> 0 | E37: 12 | G37: =ADM!B99 -> Despesas Financeiras / Bancos | H37: =SUM(I37/J37) -> 150 | I37: =ADM!O99 -> 1800 | J37: 12
B38: =MARKETING!B105 -> Impostos e Taxas | C38: =SUM(D38/E38) -> 0 | D38: =MARKETING!O105 -> 0 | E38: 12 | G38: =ADM!B105 -> Impostos e Taxas | H38: =SUM(I38/J38) -> 275 | I38: =ADM!O105 -> 3300 | J38: 12
B39: =MARKETING!B116 -> Investimento | C39: =SUM(D39/E39) -> 1458.3333 | D39: =MARKETING!O116 -> 17500 | E39: 12 | G39: =ADM!B116 -> Investimento | H39: =SUM(I39/J39) -> 750 | I39: =ADM!O116 -> 9000 | J39: 12
B40: =MARKETING!B126 -> Despesas Com Veículos | C40: =SUM(D40/E40) -> 0 | D40: =MARKETING!O126 -> 0 | E40: 11 | G40: =ADM!B125 -> Devolução Entradas | H40: =SUM(I40/J40) -> 1463.6364 | I40: =ADM!O126 -> 16100 | J40: 11
B41: =MARKETING!B130 -> Despesas Com Eventos | C41: =SUM(D41/E41) -> 10063.636 | D41: =MARKETING!O130 -> 110700 | E41: 11 | G41: =ADM!B129 -> Manutenções Veículos | H41: =SUM(I41/J41) -> 0 | I41: =ADM!O130 -> 0 | J41: 11
B42: =MARKETING!B133 -> Despesas Matérias-Primas | C42: =SUM(D42/E42) -> 0 | D42: =MARKETING!O133 -> 0 | E42: 12 | G42: =ADM!B132 -> Crowdfunding/Excurções/eventos | H42: =SUM(I42/J42) -> 0 | I42: =ADM!O133 -> 0 | J42: 12
B43: =MARKETING!B49 -> Compras Mercadorias Revenda | C43: =SUM(D43/E43) -> 2387.5 | D43: =MARKETING!O48 -> 28650 | E43: 12
D45: =SUM(D34:D43) -> 451235.6 | I45: =SUM(I34:I43) -> 577550
B47: RECEITA | G47: CUSTO
B48: =GERAL!B22 -> Doações | C48: =GERAL!O22 -> 76500 | G48: PEC | H48: =D15 -> 289050
...

Sheet GERAL
C1: INSTITUTO DE CAPACITACAO E ACAO SOCIAL O GRITO - PLANEJAMENTO 2025 - GERAL
A2: Emitido por RICARDO em 07/03/2024 | C2: =C47/O$47 -> 0.069748292 | D2: =D47/$O$47 -> 0.10924297 | E2: =E47/$O$47 -> 0.077005152 | F2: =F47/$O$47 -> 0.078055797 | G2: =G47/$O$47 -> 0.072448887 | H2: =H47/$O$47 -> 0.089515807 | I2: =I47/$O$47 -> 0.091464529 | J2: =J47/$O$47 -> 0.078489232 | K2: =K47/$O$47 -> 0.071367035 | ... N2: =N47/$O$47 -> 0.10139456
B3: CATEGORIA | C3: JANEIRO | D3: FEVEREIRO | E3: MARÇO | F3: ABRIL | G3: MAIO | H3: JUNHO | I3: JULHO | J3: AGOSTO | K3: SETEMBRO | L3: OUTUBRO | M3: NOVEMBRO | N3: DEZEMBRO | O3: TOTAL
B5: SALDO ACUMULADO | C5: =C6 -> 63350 | D5: =C5+D6 -> -56700.36 | E5: =D5+E6 -> -172478.72 | F5: =E5+F6 -> -293187.08 | G5: =F5+G6 -> -397825.44 | H5: =G5+H6 -> -394378.8 | I5: =H5+I6 -> -559617.16 | J5: =I5+J6 -> -687435.52 | K5: =J5+K6 -> -893253.88 | ... N5: =M5+N6 -> -1650756.6
B6: SALDO MÊS | C6: =SUM(C8-C47) -> 63350 | D6: =SUM(D8-D47) -> -120050.36 | E6: =SUM(E8-E47) -> -115778.36 | F6: =SUM(F8-F47) -> -120708.36 | G6: =SUM(G8-G47) -> -104638.36 | H6: =SUM(H8-H47) -> 3446.64 | I6: =SUM(I8-I47) -> -165238.36 | J6: =SUM(J8-J47) -> -127818.36 | ... N6: =SUM(N8-N47) -> -292416 | O6: =SUM(C6:N6) -> -1650756.6
B8: RECEITAS | C8: =SUM(C9,C16,C22,C28,C33,C37,C40,C43) -> 264500 | D8: =SUM(D9,D16,D22,D28,D33,D37,D40,D43) -> 195000 | E8: =SUM(E9,E16,E22,E28,E33,E37,E40,E43) -> 106300 | F8: =SUM(F9,F16,F22,F28,F33,F37,F40,F43) -> 104400 | G8: =SUM(G9,G16,G22,G28,G33,G37,G40,G43) -> 104300 | H8: =SUM(H9,H16,H22,H28,H33,H37,H40,H43) -> 261605 | I8: =SUM(I9,I16,I22,I28,I33,I37,I40,I43) -> 98540 | J8: =SUM(J9,J16,J22,J28,J33,J37,J40,J43) -> 98540 | ... N8: =SUM(N9,N16,N22,N28,N33,N37,N40,N43) -> 98540 | O8: =SUM(C8:N8) -> 1233185
B9: Devoluções | C9: =SUM(C10:C15) -> 0 | D9: =SUM(D10:D15) -> 0 | E9: =SUM(E10:E15) -> 0 | F9: =SUM(F10:F15) -> 0 | G9: =SUM(G10:G15) -> 0 | H9: =SUM(H10:H15) -> 0 | I9: =SUM(I10:I15) -> 0 | J9: =SUM(J10:J15) -> 0 | ... N9: =SUM(N10:N15) -> 0 | O9: =SUM(C9:N9) -> 0
B10: Devoluções Compra Mercadoria Revenda | C10: 0 | D10: 0 | E10: 0 | F10: 0 | G10: 0 | H10: 0 | I10: 0 | J10: 0 | K10: 0 | L10: 0 | M10: 0 | N10: 0 | O10: =SUM(C10:N10) -> 0
B11: Devoluções de Compra Material Consumo | C11: 0 | D11: 0 | E11: 0 | F11: 0 | G11: 0 | H11: 0 | I11: 0 | J11: 0 | K11: 0 | L11: 0 | M11: 0 | N11: 0 | O11: =SUM(C11:N11) -> 0
B12: Devoluções de Compra de Matéria Prima | C12: 0 | D12: 0 | E12: 0 | F12: 0 | G12: 0 | H12: 0 | I12: 0 | J12: 0 | K12: 0 | L12: 0 | M12: 0 | N12: 0 | O12: =SUM(C12:N12) -> 0
B13: Devoluções de Compra de Ativo | C13: 0 | D13: 0 | E13: 0 | F13: 0 | G13: 0 | H13: 0 | I13: 0 | J13: 0 | K13: 0 | L13: 0 | M13: 0 | N13: 0 | O13: =SUM(C13:N13) -> 0
B14: Devoluções de Compra de Serviços | C14: 0 | D14: 0 | E14: 0 | F14: 0 | G14: 0 | H14: 0 | I14: 0 | J14: 0 | K14: 0 | L14: 0 | M14: 0 | N14: 0 | O14: =SUM(C14:N14) -> 0
B15: Devolução de Doações | C15: 0 | D15: 0 | E15: 0 | F15: 0 | G15: 0 | H15: 0 | I15: 0 | J15: 0 | K15: 0 | L15: 0 | M15: 0 | N15: 0 | O15: =SUM(C15:N15) -> 0
B16: Outras Entradas | C16: =SUM(C17:C21) -> 0 | D16: =SUM(D17:D21) -> 0 | E16: =SUM(E17:E21) -> 0 | F16: =SUM(F17:F21) -> 0 | G16: =SUM(G17:G21) -> 0 | H16: =SUM(H17:H21) -> 0 | I16: =SUM(I17:I21) -> 0 | J16: =SUM(J17:J21) -> 0 | ... N16: =SUM(N17:N21) -> 0 | O16: =SUM(C16:N16) -> 0
B17: Empréstimos Bancários | C17: 0 | D17: 0 | E17: 0 | F17: 0 | G17: 0 | H17: 0 | I17: 0 | J17: 0 | K17: 0 | L17: 0 | M17: 0 | N17: 0 | O17: =SUM(C17:N17) -> 0
B18: Aumento de Capital | C18: 0 | D18: 0 | E18: 0 | F18: 0 | G18: 0 | H18: 0 | I18: 0 | J18: 0 | K18: 0 | L18: 0 | M18: 0 | N18: 0 | O18: =SUM(C18:N18) -> 0
B19: Venda de Ativos | C19: 0 | D19: 0 | E19: 0 | F19: 0 | G19: 0 | H19: 0 | I19: 0 | J19: 0 | K19: 0 | L19: 0 | M19: 0 | N19: 0 | O19: =SUM(C19:N19) -> 0
B20: AJUSTE DE CAIXA | C20: 0 | D20: 0 | E20: 0 | F20: 0 | G20: 0 | H20: 0 | I20: 0 | J20: 0 | K20: 0 | L20: 0 | M20: 0 | N20: 0 | O20: =SUM(C20:N20) -> 0
B21: Prêmios de Seguros / Sinistros | C21: 0 | D21: 0 | E21: 0 | F21: 0 | G21: 0 | H21: 0 | I21: 0 | J21: 0 | K21: 0 | L21: 0 | M21: 0 | N21: 0 | O21: =SUM(C21:N21) -> 0
B22: Doações | C22: =SUM(C23:C27) -> 5500 | D22: =SUM(D23:D27) -> 7000 | E22: =SUM(E23:E27) -> 5500 | F22: =SUM(F23:F27) -> 5500 | G22: =SUM(G23:G27) -> 5500 | H22: =SUM(H23:H27) -> 14500 | I22: =SUM(I23:I27) -> 5500 | J22: =SUM(J23:J27) -> 5500 | ... N22: =SUM(N23:N27) -> 5500 | O22: =SUM(C22:N22) -> 76500
B23: Doações Recorrentes | C23: =SUM(ADM!C23,MARKETING!C23,COMERCIAL!C23,OPERAÇÕES!C23,'FAVELA 3D'!C23) -> 2500 | D23: =SUM(ADM!D23,MARKETING!D23,COMERCIAL!D23,OPERAÇÕES!D23,'FAVELA 3D'!D23) -> 2500 | E23: =SUM(ADM!E23,MARKETING!E23,COMERCIAL!E23,OPERAÇÕES!E23,'FAVELA 3D'!E23) -> 2500 | F23: =SUM(ADM!F23,MARKETING!F23,COMERCIAL!F23,OPERAÇÕES!F23,'FAVELA 3D'!F23) -> 2500 | G23: =SUM(ADM!G23,MARKETING!G23,COMERCIAL!G23,OPERAÇÕES!G23,'FAVELA 3D'!G23) -> 2500 | H23: =SUM(ADM!H23,MARKETING!H23,COMERCIAL!H23,OPERAÇÕES!H23,'FAVELA 3D'!H23) -> 2500 | I23: =SUM(ADM!I23,MARKETING!I23,COMERCIAL!I23,OPERAÇÕES!I23,'FAVELA 3D'!I23) -> 2500 | J23: =SUM(ADM!J23,MARKETING!J23,COMERCIAL!J23,OPERAÇÕES!J23,'FAVELA 3D'!J23) -> 2500 | ... N23: =SUM(ADM!N23,MARKETING!N23,COMERCIAL!N23,OPERAÇÕES!N23,'FAVELA 3D'!N23) -> 2500 | O23: =SUM(C23:N23) -> 30000
B24: Doações Pontuais PF | C24: =SUM(ADM!C24,MARKETING!C24,COMERCIAL!C24,OPERAÇÕES!C24,'FAVELA 3D'!C24) -> 0 | D24: =SUM(ADM!D24,MARKETING!D24,COMERCIAL!D24,OPERAÇÕES!D24,'FAVELA 3D'!D24) -> 1500 | E24: =SUM(ADM!E24,MARKETING!E24,COMERCIAL!E24,OPERAÇÕES!E24,'FAVELA 3D'!E24) -> 0 | F24: =SUM(ADM!F24,MARKETING!F24,COMERCIAL!F24,OPERAÇÕES!F24,'FAVELA 3D'!F24) -> 0 | G24: =SUM(ADM!G24,MARKETING!G24,COMERCIAL!G24,OPERAÇÕES!G24,'FAVELA 3D'!G24) -> 0 | H24: =SUM(ADM!H24,MARKETING!H24,COMERCIAL!H24,OPERAÇÕES!H24,'FAVELA 3D'!H24) -> 9000 | I24: =SUM(ADM!I24,MARKETING!I24,COMERCIAL!I24,OPERAÇÕES!I24,'FAVELA 3D'!I24) -> 0 | J24: =SUM(ADM!J24,MARKETING!J24,COMERCIAL!J24,OPERAÇÕES!J24,'FAVELA 3D'!J24) -> 0 | ... N24: =SUM(ADM!N24,MARKETING!N24,COMERCIAL!N24,OPERAÇÕES!N24,'FAVELA 3D'!N24) -> 0 | O24: =SUM(C24:N24) -> 10500
B25: Doações Pontuais PJ | C25: =SUM(ADM!C25,MARKETING!C25,COMERCIAL!C25,OPERAÇÕES!C25,'FAVELA 3D'!C25) -> 0 | D25: =SUM(ADM!D25,MARKETING!D25,COMERCIAL!D25,OPERAÇÕES!D25,'FAVELA 3D'!D25) -> 0 | E25: =SUM(ADM!E25,MARKETING!E25,COMERCIAL!E25,OPERAÇÕES!E25,'FAVELA 3D'!E25) -> 0 | F25: =SUM(ADM!F25,MARKETING!F25,COMERCIAL!F25,OPERAÇÕES!F25,'FAVELA 3D'!F25) -> 0 | G25: =SUM(ADM!G25,MARKETING!G25,COMERCIAL!G25,OPERAÇÕES!G25,'FAVELA 3D'!G25) -> 0 | H25: =SUM(ADM!H25,MARKETING!H25,COMERCIAL!H25,OPERAÇÕES!H25,'FAVELA 3D'!H25) -> 0 | I25: =SUM(ADM!I25,MARKETING!I25,COMERCIAL!I25,OPERAÇÕES!I25,'FAVELA 3D'!I25) -> 0 | J25: =SUM(ADM!J25,MARKETING!J25,COMERCIAL!J25,OPERAÇÕES!J25,'FAVELA 3D'!J25) -> 0 | ... N25: =SUM(ADM!N25,MARKETING!N25,COMERCIAL!N25,OPERAÇÕES!N25,'FAVELA 3D'!N25) -> 0 | O25: =SUM(C25:N25) -> 0
B26: Sócio Doador | C26: =SUM(ADM!C26,MARKETING!C26,COMERCIAL!C26,OPERAÇÕES!C26,'FAVELA 3D'!C26) -> 3000 | D26: =SUM(ADM!D26,MARKETING!D26,COMERCIAL!D26,OPERAÇÕES!D26,'FAVELA 3D'!D26) -> 3000 | E26: =SUM(ADM!E26,MARKETING!E26,COMERCIAL!E26,OPERAÇÕES!E26,'FAVELA 3D'!E26) -> 3000 | F26: =SUM(ADM!F26,MARKETING!F26,COMERCIAL!F26,OPERAÇÕES!F26,'FAVELA 3D'!F26) -> 3000 | G26: =SUM(ADM!G26,MARKETING!G26,COMERCIAL!G26,OPERAÇÕES!G26,'FAVELA 3D'!G26) -> 3000 | H26: =SUM(ADM!H26,MARKETING!H26,COMERCIAL!H26,OPERAÇÕES!H26,'FAVELA 3D'!H26) -> 3000 | I26: =SUM(ADM!I26,MARKETING!I26,COMERCIAL!I26,OPERAÇÕES!I26,'FAVELA 3D'!I26) -> 3000 | J26: =SUM(ADM!J26,MARKETING!J26,COMERCIAL!J26,OPERAÇÕES!J26,'FAVELA 3D'!J26) -> 3000 | ... N26: =SUM(ADM!N26,MARKETING!N26,COMERCIAL!N26,OPERAÇÕES!N26,'FAVELA 3D'!N26) -> 3000 | O26: =SUM(C26:N26) -> 36000
B27: Patrocínios | C27: =SUM(ADM!C27,MARKETING!C27,COMERCIAL!C27,OPERAÇÕES!C27,'FAVELA 3D'!C27) -> 0 | D27: =SUM(ADM!D27,MARKETING!D27,COMERCIAL!D27,OPERAÇÕES!D27,'FAVELA 3D'!D27) -> 0 | E27: =SUM(ADM!E27,MARKETING!E27,COMERCIAL!E27,OPERAÇÕES!E27,'FAVELA 3D'!E27) -> 0 | F27: =SUM(ADM!F27,MARKETING!F27,COMERCIAL!F27,OPERAÇÕES!F27,'FAVELA 3D'!F27) -> 0 | G27: =SUM(ADM!G27,MARKETING!G27,COMERCIAL!G27,OPERAÇÕES!G27,'FAVELA 3D'!G27) -> 0 | H27: =SUM(ADM!H27,MARKETING!H27,COMERCIAL!H27,OPERAÇÕES!H27,'FAVELA 3D'!H27) -> 0 | I27: =SUM(ADM!I27,MARKETING!I27,COMERCIAL!I27,OPERAÇÕES!I27,'FAVELA 3D'!I27) -> 0 | J27: =SUM(ADM!J27,MARKETING!J27,COMERCIAL!J27,OPERAÇÕES!J27,'FAVELA 3D'!J27) -> 0 | ... N27: =SUM(ADM!N27,MARKETING!N27,COMERCIAL!N27,OPERAÇÕES!N27,'FAVELA 3D'!N27) -> 0 | O27: =SUM(C27:N27) -> 0
B28: Gerando Falcões | C28: =SUM(C29:C32) -> 53500 | D28: =SUM(D29:D32) -> 53500 | E28: =SUM(E29:E32) -> 53500 | F28: =SUM(F29:F32) -> 53500 | G28: =SUM(G29:G32) -> 53500 | H28: =SUM(H29:H32) -> 53500 | I28: =SUM(I29:I32) -> 53500 | J28: =SUM(J29:J32) -> 53500 | ... N28: =SUM(N29:N32) -> 53500 | O28: =SUM(C28:N28) -> 642000
B29: Aporte | C29: =SUM(ADM!C29,MARKETING!C29,COMERCIAL!C29,OPERAÇÕES!C29,'FAVELA 3D'!C29) -> 53500 | D29: =SUM(ADM!D29,MARKETING!D29,COMERCIAL!D29,OPERAÇÕES!D29,'FAVELA 3D'!D29) -> 53500 | E29: =SUM(ADM!E29,MARKETING!E29,COMERCIAL!E29,OPERAÇÕES!E29,'FAVELA 3D'!E29) -> 53500 | F29: =SUM(ADM!F29,MARKETING!F29,COMERCIAL!F29,OPERAÇÕES!F29,'FAVELA 3D'!F29) -> 53500 | G29: =SUM(ADM!G29,MARKETING!G29,COMERCIAL!G29,OPERAÇÕES!G29,'FAVELA 3D'!G29) -> 53500 | H29: =SUM(ADM!H29,MARKETING!H29,COMERCIAL!H29,OPERAÇÕES!H29,'FAVELA 3D'!H29) -> 53500 | I29: =SUM(ADM!I29,MARKETING!I29,COMERCIAL!I29,OPERAÇÕES!I29,'FAVELA 3D'!I29) -> 53500 | J29: =SUM(ADM!J29,MARKETING!J29,COMERCIAL!J29,OPERAÇÕES!J29,'FAVELA 3D'!J29) -> 53500 | ... N29: =SUM(ADM!N29,MARKETING!N29,COMERCIAL!N29,OPERAÇÕES!N29,'FAVELA 3D'!N29) -> 53500 | O29: =SUM(C29:N29) -> 642000
B30: Falcons Univercity | C30: =SUM(ADM!C30,MARKETING!C30,COMERCIAL!C30,OPERAÇÕES!C30,'FAVELA 3D'!C30) -> 0 | D30: =SUM(ADM!D30,MARKETING!D30,COMERCIAL!D30,OPERAÇÕES!D30,'FAVELA 3D'!D30) -> 0 | E30: =SUM(ADM!E30,MARKETING!E30,COMERCIAL!E30,OPERAÇÕES!E30,'FAVELA 3D'!E30) -> 0 | F30: =SUM(ADM!F30,MARKETING!F30,COMERCIAL!F30,OPERAÇÕES!F30,'FAVELA 3D'!F30) -> 0 | G30: =SUM(ADM!G30,MARKETING!G30,COMERCIAL!G30,OPERAÇÕES!G30,'FAVELA 3D'!G30) -> 0 | H30: =SUM(ADM!H30,MARKETING!H30,COMERCIAL!H30,OPERAÇÕES!H30,'FAVELA 3D'!H30) -> 0 | I30: =SUM(ADM!I30,MARKETING!I30,COMERCIAL!I30,OPERAÇÕES!I30,'FAVELA 3D'!I30) -> 0 | J30: =SUM(ADM!J30,MARKETING!J30,COMERCIAL!J30,OPERAÇÕES!J30,'FAVELA 3D'!J30) -> 0 | ... N30: =SUM(ADM!N30,MARKETING!N30,COMERCIAL!N30,OPERAÇÕES!N30,'FAVELA 3D'!N30) -> 0 | O30: =SUM(C30:N30) -> 0
B31: Regional GF | C31: =SUM(ADM!C31,MARKETING!C31,COMERCIAL!C31,OPERAÇÕES!C31,'FAVELA 3D'!C31) -> 0 | D31: =SUM(ADM!D31,MARKETING!D31,COMERCIAL!D31,OPERAÇÕES!D31,'FAVELA 3D'!D31) -> 0 | E31: =SUM(ADM!E31,MARKETING!E31,COMERCIAL!E31,OPERAÇÕES!E31,'FAVELA 3D'!E31) -> 0 | F31: =SUM(ADM!F31,MARKETING!F31,COMERCIAL!F31,OPERAÇÕES!F31,'FAVELA 3D'!F31) -> 0 | G31: =SUM(ADM!G31,MARKETING!G31,COMERCIAL!G31,OPERAÇÕES!G31,'FAVELA 3D'!G31) -> 0 | H31: =SUM(ADM!H31,MARKETING!H31,COMERCIAL!H31,OPERAÇÕES!H31,'FAVELA 3D'!H31) -> 0 | I31: =SUM(ADM!I31,MARKETING!I31,COMERCIAL!I31,OPERAÇÕES!I31,'FAVELA 3D'!I31) -> 0 | J31: =SUM(ADM!J31,MARKETING!J31,COMERCIAL!J31,OPERAÇÕES!J31,'FAVELA 3D'!J31) -> 0 | ... N31: =SUM(ADM!N31,MARKETING!N31,COMERCIAL!N31,OPERAÇÕES!N31,'FAVELA 3D'!N31) -> 0 | O31: =SUM(C31:N31) -> 0
B32: Favela 3D | C32: =SUM(ADM!C32,MARKETING!C32,COMERCIAL!C32,OPERAÇÕES!C32,'FAVELA 3D'!C32) -> 0 | D32: =SUM(ADM!D32,MARKETING!D32,COMERCIAL!D32,OPERAÇÕES!D32,'FAVELA 3D'!D32) -> 0 | E32: =SUM(ADM!E32,MARKETING!E32,COMERCIAL!E32,OPERAÇÕES!E32,'FAVELA 3D'!E32) -> 0 | F32: =SUM(ADM!F32,MARKETING!F32,COMERCIAL!F32,OPERAÇÕES!F32,'FAVELA 3D'!F32) -> 0 | G32: =SUM(ADM!G32,MARKETING!G32,COMERCIAL!G32,OPERAÇÕES!G32,'FAVELA 3D'!G32) -> 0 | H32: =SUM(ADM!H32,MARKETING!H32,COMERCIAL!H32,OPERAÇÕES!H32,'FAVELA 3D'!H32) -> 0 | I32: =SUM(ADM!I32,MARKETING!I32,COMERCIAL!I32,OPERAÇÕES!I32,'FAVELA 3D'!I32) -> 0 | J32: =SUM(ADM!J32,MARKETING!J32,COMERCIAL!J32,OPERAÇÕES!J32,'FAVELA 3D'!J32) -> 0 | ... N32: =SUM(ADM!N32,MARKETING!N32,COMERCIAL!N32,OPERAÇÕES!N32,'FAVELA 3D'!N32) -> 0 | O32: =SUM(C32:N32) -> 0
B33: Editais/Projetos | C33: =SUM(C34:C36) -> 174000 | D33: =SUM(D34:D36) -> 90000 | E33: =SUM(E34:E36) -> 0 | F33: =SUM(F34:F36) -> 0 | G33: =SUM(G34:G36) -> 0 | H33: =SUM(H34:H36) -> 149000 | I33: =SUM(I34:I36) -> 0 | J33: =SUM(J34:J36) -> 0 | ... N33: =SUM(N34:N36) -> 0 | O33: =SUM(C33:N33) -> 413000
B34: Ecogaiola | C34: =SUM(ADM!C34,MARKETING!C34,COMERCIAL!C34,OPERAÇÕES!C34,'FAVELA 3D'!C34) -> 0 | D34: =SUM(ADM!D34,MARKETING!D34,COMERCIAL!D34,OPERAÇÕES!D34,'FAVELA 3D'!D34) -> 0 | E34: =SUM(ADM!E34,MARKETING!E34,COMERCIAL!E34,OPERAÇÕES!E34,'FAVELA 3D'!E34) -> 0 | F34: =SUM(ADM!F34,MARKETING!F34,COMERCIAL!F34,OPERAÇÕES!F34,'FAVELA 3D'!F34) -> 0 | G34: =SUM(ADM!G34,MARKETING!G34,COMERCIAL!G34,OPERAÇÕES!G34,'FAVELA 3D'!G34) -> 0 | H34: =SUM(ADM!H34,MARKETING!H34,COMERCIAL!H34,OPERAÇÕES!H34,'FAVELA 3D'!H34) -> 0 | I34: =SUM(ADM!I34,MARKETING!I34,COMERCIAL!I34,OPERAÇÕES!I34,'FAVELA 3D'!I34) -> 0 | J34: =SUM(ADM!J34,MARKETING!J34,COMERCIAL!J34,OPERAÇÕES!J34,'FAVELA 3D'!J34) -> 0 | ... N34: =SUM(ADM!N34,MARKETING!N34,COMERCIAL!N34,OPERAÇÕES!N34,'FAVELA 3D'!N34) -> 0 | O34: =SUM(C34:N34) -> 0
B35: Prog. Hab. Polaris | C35: =SUM(ADM!C35,MARKETING!C35,COMERCIAL!C35,OPERAÇÕES!C35,'FAVELA 3D'!C35) -> 0 | D35: =SUM(ADM!D35,MARKETING!D35,COMERCIAL!D35,OPERAÇÕES!D35,'FAVELA 3D'!D35) -> 0 | E35: =SUM(ADM!E35,MARKETING!E35,COMERCIAL!E35,OPERAÇÕES!E35,'FAVELA 3D'!E35) -> 0 | F35: =SUM(ADM!F35,MARKETING!F35,COMERCIAL!F35,OPERAÇÕES!F35,'FAVELA 3D'!F35) -> 0 | G35: =SUM(ADM!G35,MARKETING!G35,COMERCIAL!G35,OPERAÇÕES!G35,'FAVELA 3D'!G35) -> 0 | H35: =SUM(ADM!H35,MARKETING!H35,COMERCIAL!H35,OPERAÇÕES!H35,'FAVELA 3D'!H35) -> 0 | I35: =SUM(ADM!I35,MARKETING!I35,COMERCIAL!I35,OPERAÇÕES!I35,'FAVELA 3D'!I35) -> 0 | J35: =SUM(ADM!J35,MARKETING!J35,COMERCIAL!J35,OPERAÇÕES!J35,'FAVELA 3D'!J35) -> 0 | ... N35: =SUM(ADM!N35,MARKETING!N35,COMERCIAL!N35,OPERAÇÕES!N35,'FAVELA 3D'!N35) -> 0 | O35: =SUM(C35:N35) -> 0
B36: Lei De Incentivo | C36: =SUM(ADM!C36,MARKETING!C36,COMERCIAL!C36,OPERAÇÕES!C36,'FAVELA 3D'!C36) -> 174000 | D36: =SUM(ADM!D36,MARKETING!D36,COMERCIAL!D36,OPERAÇÕES!D36,'FAVELA 3D'!D36) -> 90000 | E36: =SUM(ADM!E36,MARKETING!E36,COMERCIAL!E36,OPERAÇÕES!E36,'FAVELA 3D'!E36) -> 0 | F36: =SUM(ADM!F36,MARKETING!F36,COMERCIAL!F36,OPERAÇÕES!F36,'FAVELA 3D'!F36) -> 0 | G36: =SUM(ADM!G36,MARKETING!G36,COMERCIAL!G36,OPERAÇÕES!G36,'FAVELA 3D'!G36) -> 0 | H36: =SUM(ADM!H36,MARKETING!H36,COMERCIAL!H36,OPERAÇÕES!H36,'FAVELA 3D'!H36) -> 149000 | I36: =SUM(ADM!I36,MARKETING!I36,COMERCIAL!I36,OPERAÇÕES!I36,'FAVELA 3D'!I36) -> 0 | J36: =SUM(ADM!J36,MARKETING!J36,COMERCIAL!J36,OPERAÇÕES!J36,'FAVELA 3D'!J36) -> 0 | ... N36: =SUM(ADM!N36,MARKETING!N36,COMERCIAL!N36,OPERAÇÕES!N36,'FAVELA 3D'!N36) -> 0 | O36: =SUM(C36:N36) -> 413000
B37: Negócios Sociais | C37: =SUM(C38:C39) -> 16500 | D37: =SUM(D38:D39) -> 29500 | E37: =SUM(E38:E39) -> 34400 | F37: =SUM(F38:F39) -> 34400 | G37: =SUM(G38:G39) -> 34400 | H37: =SUM(H38:H39) -> 34400 | I37: =SUM(I38:I39) -> 29500 | J37: =SUM(J38:J39) -> 29500 | ... N37: =SUM(N38:N39) -> 16500 | O37: =SUM(C37:N37) -> 347600
B38: Vendas Outlet | C38: =SUM(ADM!C38,MARKETING!C38,COMERCIAL!C38,OPERAÇÕES!C38,'FAVELA 3D'!C38) -> 16500 | D38: =SUM(ADM!D38,MARKETING!D38,COMERCIAL!D38,OPERAÇÕES!D38,'FAVELA 3D'!D38) -> 16500 | E38: =SUM(ADM!E38,MARKETING!E38,COMERCIAL!E38,OPERAÇÕES!E38,'FAVELA 3D'!E38) -> 21400 | F38: =SUM(ADM!F38,MARKETING!F38,COMERCIAL!F38,OPERAÇÕES!F38,'FAVELA 3D'!F38) -> 21400 | G38: =SUM(ADM!G38,MARKETING!G38,COMERCIAL!G38,OPERAÇÕES!G38,'FAVELA 3D'!G38) -> 21400 | H38: =SUM(ADM!H38,MARKETING!H38,COMERCIAL!H38,OPERAÇÕES!H38,'FAVELA 3D'!H38) -> 21400 | I38: =SUM(ADM!I38,MARKETING!I38,COMERCIAL!I38,OPERAÇÕES!I38,'FAVELA 3D'!I38) -> 16500 | J38: =SUM(ADM!J38,MARKETING!J38,COMERCIAL!J38,OPERAÇÕES!J38,'FAVELA 3D'!J38) -> 16500 | ... N38: =SUM(ADM!N38,MARKETING!N38,COMERCIAL!N38,OPERAÇÕES!N38,'FAVELA 3D'!N38) -> 16500 | O38: =SUM(C38:N38) -> 217600
B39: Vendas Griffte | C39: =SUM(ADM!C39,MARKETING!C39,COMERCIAL!C39,OPERAÇÕES!C39,'FAVELA 3D'!C39) -> 0 | D39: =SUM(ADM!D39,MARKETING!D39,COMERCIAL!D39,OPERAÇÕES!D39,'FAVELA 3D'!D39) -> 13000 | E39: =SUM(ADM!E39,MARKETING!E39,COMERCIAL!E39,OPERAÇÕES!E39,'FAVELA 3D'!E39) -> 13000 | F39: =SUM(ADM!F39,MARKETING!F39,COMERCIAL!F39,OPERAÇÕES!F39,'FAVELA 3D'!F39) -> 13000 | G39: =SUM(ADM!G39,MARKETING!G39,COMERCIAL!G39,OPERAÇÕES!G39,'FAVELA 3D'!G39) -> 13000 | H39: =SUM(ADM!H39,MARKETING!H39,COMERCIAL!H39,OPERAÇÕES!H39,'FAVELA 3D'!H39) -> 13000 | I39: =SUM(ADM!I39,MARKETING!I39,COMERCIAL!I39,OPERAÇÕES!I39,'FAVELA 3D'!I39) -> 13000 | J39: =SUM(ADM!J39,MARKETING!J39,COMERCIAL!J39,OPERAÇÕES!J39,'FAVELA 3D'!J39) -> 13000 | ... N39: =SUM(ADM!N39,MARKETING!N39,COMERCIAL!N39,OPERAÇÕES!N39,'FAVELA 3D'!N39) -> 0 | O39: =SUM(C39:N39) -> 130000
B40: Eventos | C40: =SUM(C41:C42) -> 10000 | D40: =SUM(D41:D42) -> 10000 | E40: =SUM(E41:E42) -> 7900 | F40: =SUM(F41:F42) -> 6000 | G40: =SUM(G41:G42) -> 5900 | H40: =SUM(H41:H42) -> 5205 | I40: =SUM(I41:I42) -> 5040 | J40: =SUM(J41:J42) -> 5040 | ... N40: =SUM(N41:N42) -> 0 | O40: =SUM(C40:N40) -> 55085
B41: Clube Do Grito | C41: =SUM(ADM!C41,MARKETING!C41,COMERCIAL!C41,OPERAÇÕES!C41,'FAVELA 3D'!C41) -> 10000 | D41: =SUM(ADM!D41,MARKETING!D41,COMERCIAL!D41,OPERAÇÕES!D41,'FAVELA 3D'!D41) -> 10000 | E41: =SUM(ADM!E41,MARKETING!E41,COMERCIAL!E41,OPERAÇÕES!E41,'FAVELA 3D'!E41) -> 7900 | F41: =SUM(ADM!F41,MARKETING!F41,COMERCIAL!F41,OPERAÇÕES!F41,'FAVELA 3D'!F41) -> 6000 | G41: =SUM(ADM!G41,MARKETING!G41,COMERCIAL!G41,OPERAÇÕES!G41,'FAVELA 3D'!G41) -> 5900 | H41: =SUM(ADM!H41,MARKETING!H41,COMERCIAL!H41,OPERAÇÕES!H41,'FAVELA 3D'!H41) -> 5205 | I41: =SUM(ADM!I41,MARKETING!I41,COMERCIAL!I41,OPERAÇÕES!I41,'FAVELA 3D'!I41) -> 5040 | J41: =SUM(ADM!J41,MARKETING!J41,COMERCIAL!J41,OPERAÇÕES!J41,'FAVELA 3D'!J41) -> 5040 | ... N41: =SUM(ADM!N41,MARKETING!N41,COMERCIAL!N41,OPERAÇÕES!N41,'FAVELA 3D'!N41) -> 10000 | O41: =SUM(C41:N41) -> 55085
B42: Crowdfunding | C42: =SUM(ADM!C42,MARKETING!C42,COMERCIAL!C42,OPERAÇÕES!C42,'FAVELA 3D'!C42) -> 0 | D42: =SUM(ADM!D42,MARKETING!D42,COMERCIAL!D42,OPERAÇÕES!D42,'FAVELA 3D'!D42) -> 0 | E42: =SUM(ADM!E42,MARKETING!E42,COMERCIAL!E42,OPERAÇÕES!E42,'FAVELA 3D'!E42) -> 0 | F42: =SUM(ADM!F42,MARKETING!F42,COMERCIAL!F42,OPERAÇÕES!F42,'FAVELA 3D'!F42) -> 0 | G42: =SUM(ADM!G42,MARKETING!G42,COMERCIAL!G42,OPERAÇÕES!G42,'FAVELA 3D'!G42) -> 0 | H42: =SUM(ADM!H42,MARKETING!H42,COMERCIAL!H42,OPERAÇÕES!H42,'FAVELA 3D'!H42) -> 0 | I42: =SUM(ADM!I42,MARKETING!I42,COMERCIAL!I42,OPERAÇÕES!I42,'FAVELA 3D'!I42) -> 0 | J42: =SUM(ADM!J42,MARKETING!J42,COMERCIAL!J42,OPERAÇÕES!J42,'FAVELA 3D'!J42) -> 0 | ... N42: =SUM(ADM!N42,MARKETING!N42,COMERCIAL!N42,OPERAÇÕES!N42,'FAVELA 3D'!N42) -> 0 | O42: =SUM(C42:N42) -> 0
...

Sheet ADM
C1: INSTITUTO DE CAPACITACAO E ACAO SOCIAL O GRITO - PLANEJAMENTO 2025 - ADM
C2: =C47/O$47 -> 0.085499091 | D2: =D47/$O$47 -> 0.078884945 | E2: =E47/$O$47 -> 0.082382478 | F2: =F47/$O$47 -> 0.08338672 | G2: =G47/$O$47 -> 0.079092719 | H2: =H47/$O$47 -> 0.078884945 | I2: =I47/$O$47 -> 0.081516752 | J2: =J47/$O$47 -> 0.10719418 | K2: =K47/$O$47 -> 0.079767985 | ... N2: =N47/$O$47 -> 0.080425937
B3: CATEGORIA | C3: JANEIRO | D3: FEVEREIRO | E3: MARÇO | F3: ABRIL | G3: MAIO | H3: JUNHO | I3: JULHO | J3: AGOSTO | K3: SETEMBRO | L3: OUTUBRO | M3: NOVEMBRO | N3: DEZEMBRO | O3: TOTAL
B5: SALDO ACUMULADO | C5: =C6 -> -28880 | D5: =C5+D6 -> -53940 | E5: =D5+E6 -> -83120 | F5: =E5+F6 -> -114780 | G5: =F5+G6 -> -144060 | H5: =G5+H6 -> -173915 | I5: =H5+I6 -> -205455 | J5: =I5+J6 -> -251825 | K5: =J5+K6 -> -279395 | ... N5: =M5+N6 -> -388465
B6: SALDO MÊS | C6: =SUM(C8-C47) -> -28880 | D6: =SUM(D8-D47) -> -25060 | E6: =SUM(E8-E47) -> -29180 | F6: =SUM(F8-F47) -> -31660 | G6: =SUM(G8-G47) -> -29280 | H6: =SUM(H8-H47) -> -29855 | I6: =SUM(I8-I47) -> -31540 | J6: =SUM(J8-J47) -> -46370 | ... N6: =SUM(N8-N47) -> -35950 | O6: =SUM(C6:N6) -> -388465
B8: RECEITAS | C8: =SUM(C9,C16,C22,C28,C33,C37,C40,C43) -> 20500 | D8: =SUM(D9,D16,D22,D28,D33,D37,D40,D43) -> 20500 | E8: =SUM(E9,E16,E22,E28,E33,E37,E40,E43) -> 18400 | F8: =SUM(F9,F16,F22,F28,F33,F37,F40,F43) -> 16500 | G8: =SUM(G9,G16,G22,G28,G33,G37,G40,G43) -> 16400 | H8: =SUM(H9,H16,H22,H28,H33,H37,H40,H43) -> 15705 | I8: =SUM(I9,I16,I22,I28,I33,I37,I40,I43) -> 15540 | J8: =SUM(J9,J16,J22,J28,J33,J37,J40,J43) -> 15540 | ... N8: =SUM(N9,N16,N22,N28,N33,N37,N40,N43) -> 10500 | O8: =SUM(C8:N8) -> 181085
B9: Devoluções | C9: =SUM(C10:C15) -> 0 | D9: =SUM(D10:D15) -> 0 | E9: =SUM(E10:E15) -> 0 | F9: =SUM(F10:F15) -> 0 | G9: =SUM(G10:G15) -> 0 | H9: =SUM(H10:H15) -> 0 | I9: =SUM(I10:I15) -> 0 | J9: =SUM(J10:J15) -> 0 | ... N9: =SUM(N10:N15) -> 0 | O9: =SUM(C9:N9) -> 0
B10: Devoluções Compra Mercadoria Revenda | C10: 0 | D10: 0 | E10: 0 | F10: 0 | G10: 0 | H10: 0 | I10: 0 | J10: 0 | K10: 0 | L10: 0 | M10: 0 | N10: 0 | O10: =SUM(C10:N10) -> 0
B11: Devoluções de Compra Material Consumo | C11: 0 | D11: 0 | E11: 0 | F11: 0 | G11: 0 | H11: 0 | I11: 0 | J11: 0 | K11: 0 | L11: 0 | M11: 0 | N11: 0 | O11: =SUM(C11:N11) -> 0
B12: Devoluções de Compra de Matéria Prima | C12: 0 | D12: 0 | E12: 0 | F12: 0 | G12: 0 | H12: 0 | I12: 0 | J12: 0 | K12: 0 | L12: 0 | M12: 0 | N12: 0 | O12: =SUM(C12:N12) -> 0
B13: Devoluções de Compra de Ativo | C13: 0 | D13: 0 | E13: 0 | F13: 0 | G13: 0 | H13: 0 | I13: 0 | J13: 0 | K13: 0 | L13: 0 | M13: 0 | N13: 0 | O13: =SUM(C13:N13) -> 0
B14: Devoluções de Compra de Serviços | C14: 0 | D14: 0 | E14: 0 | F14: 0 | G14: 0 | H14: 0 | I14: 0 | J14: 0 | K14: 0 | L14: 0 | M14: 0 | N14: 0 | O14: =SUM(C14:N14) -> 0
B15: Devolução de Doações | C15: 0 | D15: 0 | E15: 0 | F15: 0 | G15: 0 | H15: 0 | I15: 0 | J15: 0 | K15: 0 | L15: 0 | M15: 0 | N15: 0 | O15: =SUM(C15:N15) -> 0
B16: Outras Entradas | C16: =SUM(C17:C21) -> 0 | D16: =SUM(D17:D21) -> 0 | E16: =SUM(E17:E21) -> 0 | F16: =SUM(F17:F21) -> 0 | G16: =SUM(G17:G21) -> 0 | H16: =SUM(H17:H21) -> 0 | I16: =SUM(I17:I21) -> 0 | J16: =SUM(J17:J21) -> 0 | ... N16: =SUM(N17:N21) -> 0 | O16: =SUM(C16:N16) -> 0
B17: Empréstimos Bancários | C17: 0 | D17: 0 | E17: 0 | F17: 0 | G17: 0 | H17: 0 | I17: 0 | J17: 0 | K17: 0 | L17: 0 | M17: 0 | N17: 0 | O17: =SUM(C17:N17) -> 0
B18: Aumento de Capital | C18: 0 | D18: 0 | E18: 0 | F18: 0 | G18: 0 | H18: 0 | I18: 0 | J18: 0 | K18: 0 | L18: 0 | M18: 0 | N18: 0 | O18: =SUM(C18:N18) -> 0
B19: Venda de Ativos | C19: 0 | D19: 0 | E19: 0 | F19: 0 | G19: 0 | H19: 0 | I19: 0 | J19: 0 | K19: 0 | L19: 0 | M19: 0 | N19: 0 | O19: =SUM(C19:N19) -> 0
B20: AJUSTE DE CAIXA | C20: 0 | D20: 0 | E20: 0 | F20: 0 | G20: 0 | H20: 0 | I20: 0 | J20: 0 | K20: 0 | L20: 0 | M20: 0 | N20: 0 | O20: =SUM(C20:N20) -> 0
B21: Prêmios de Seguros / Sinistros | C21: 0 | D21: 0 | E21: 0 | F21: 0 | G21: 0 | H21: 0 | I21: 0 | J21: 0 | K21: 0 | L21: 0 | M21: 0 | N21: 0 | O21: =SUM(C21:N21) -> 0
B22: Doações | C22: =SUM(C23:C27) -> 5500 | D22: =SUM(D23:D27) -> 5500 | E22: =SUM(E23:E27) -> 5500 | F22: =SUM(F23:F27) -> 5500 | G22: =SUM(G23:G27) -> 5500 | H22: =SUM(H23:H27) -> 5500 | I22: =SUM(I23:I27) -> 5500 | J22: =SUM(J23:J27) -> 5500 | ... N22: =SUM(N23:N27) -> 5500 | O22: =SUM(C22:N22) -> 66000
B23: Doações Recorrentes | C23: 2500 | D23: 2500 | E23: 2500 | F23: 2500 | G23: 2500 | H23: 2500 | I23: 2500 | J23: 2500 | K23: 2500 | L23: 2500 | M23: 2500 | N23: 2500 | O23: =SUM(C23:N23) -> 30000
B24: Doações Pontuais PF | C24: 0 | D24: 0 | E24: 0 | F24: 0 | G24: 0 | H24: 0 | I24: 0 | J24: 0 | K24: 0 | L24: 0 | M24: 0 | N24: 0 | O24: =SUM(C24:N24) -> 0
B25: Doações Pontuais PJ | C25: 0 | D25: 0 | E25: 0 | F25: 0 | G25: 0 | H25: 0 | I25: 0 | J25: 0 | K25: 0 | L25: 0 | M25: 0 | N25: 0 | O25: =SUM(C25:N25) -> 0
B26: Doador Anjo | C26: 3000 | D26: 3000 | E26: 3000 | F26: 3000 | G26: 3000 | H26: 3000 | I26: 3000 | J26: 3000 | K26: 3000 | L26: 3000 | M26: 3000 | N26: 3000 | O26: =SUM(C26:N26) -> 36000
B27: Patrocínios | C27: 0 | D27: 0 | E27: 0 | F27: 0 | G27: 0 | H27: 0 | I27: 0 | J27: 0 | K27: 0 | L27: 0 | M27: 0 | N27: 0 | O27: =SUM(C27:N27) -> 0
B28: Gerando Falcões | C28: =SUM(C29:C32) -> 0 | D28: =SUM(D29:D32) -> 0 | E28: =SUM(E29:E32) -> 0 | F28: =SUM(F29:F32) -> 0 | G28: =SUM(G29:G32) -> 0 | H28: =SUM(H29:H32) -> 0 | I28: =SUM(I29:I32) -> 0 | J28: =SUM(J29:J32) -> 0 | ... N28: =SUM(N29:N32) -> 0 | O28: =SUM(C28:N28) -> 0
B29: Aporte | C29: 0 | D29: 0 | E29: 0 | F29: 0 | G29: 0 | H29: 0 | I29: 0 | J29: 0 | K29: 0 | L29: 0 | M29: 0 | N29: 0 | O29: =SUM(C29:N29) -> 0
B30: Falcons Univercity | C30: 0 | D30: 0 | E30: 0 | F30: 0 | G30: 0 | H30: 0 | I30: 0 | J30: 0 | K30: 0 | L30: 0 | M30: 0 | N30: 0 | O30: =SUM(C30:N30) -> 0
B31: Regional GF | C31: 0 | D31: 0 | E31: 0 | F31: 0 | G31: 0 | H31: 0 | I31: 0 | J31: 0 | K31: 0 | L31: 0 | M31: 0 | N31: 0 | O31: =SUM(C31:N31) -> 0
B32: Favela 3D | C32: 0 | D32: 0 | E32: 0 | F32: 0 | G32: 0 | H32: 0 | I32: 0 | J32: 0 | K32: 0 | L32: 0 | M32: 0 | N32: 0 | O32: =SUM(C32:N32) -> 0
B33: Editais/Projetos | C33: =SUM(C34:C36) -> 0 | D33: =SUM(D34:D36) -> 0 | E33: =SUM(E34:E36) -> 0 | F33: =SUM(F34:F36) -> 0 | G33: =SUM(G34:G36) -> 0 | H33: =SUM(H34:H36) -> 0 | I33: =SUM(I34:I36) -> 0 | J33: =SUM(J34:J36) -> 0 | ... N33: =SUM(N34:N36) -> 0 | O33: =SUM(C33:N33) -> 0
B34: Ecogaiola | C34: 0 | D34: 0 | E34: 0 | F34: 0 | G34: 0 | H34: 0 | I34: 0 | J34: 0 | K34: 0 | L34: 0 | M34: 0 | N34: 0 | O34: =SUM(C34:N34) -> 0
B35: Prog. Hab. Polaris | C35: 0 | D35: 0 | E35: 0 | F35: 0 | G35: 0 | H35: 0 | I35: 0 | J35: 0 | K35: 0 | L35: 0 | M35: 0 | N35: 0 | O35: =SUM(C35:N35) -> 0
B36: Lei De Incentivo | C36: 0 | D36: 0 | E36: 0 | F36: 0 | G36: 0 | H36: 0 | I36: 0 | J36: 0 | K36: 0 | L36: 0 | M36: 0 | N36: 0 | O36: =SUM(C36:N36) -> 0
B37: Negócios Sociais | C37: =SUM(C38:C39) -> 0 | D37: =SUM(D38:D39) -> 0 | E37: =SUM(E38:E39) -> 0 | F37: =SUM(F38:F39) -> 0 | G37: =SUM(G38:G39) -> 0 | H37: =SUM(H38:H39) -> 0 | I37: =SUM(I38:I39) -> 0 | J37: =SUM(J38:J39) -> 0 | ... N37: =SUM(N38:N39) -> 0 | O37: =SUM(C37:N37) -> 0
B38: Vendas Outlet | C38: 0 | D38: 0 | E38: 0 | F38: 0 | G38: 0 | H38: 0 | I38: 0 | J38: 0 | K38: 0 | L38: 0 | M38: 0 | N38: 0 | O38: =SUM(C38:N38) -> 0
B39: Vendas Griffte | C39: 0 | D39: 0 | E39: 0 | F39: 0 | G39: 0 | H39: 0 | I39: 0 | J39: 0 | K39: 0 | L39: 0 | M39: 0 | N39: 0 | O39: =SUM(C39:N39) -> 0
B40: Eventos | C40: =SUM(C41:C42) -> 10000 | D40: =SUM(D41:D42) -> 10000 | E40: =SUM(E41:E42) -> 7900 | F40: =SUM(F41:F42) -> 6000 | G40: =SUM(G41:G42) -> 5900 | H40: =SUM(H41:H42) -> 5205 | I40: =SUM(I41:I42) -> 5040 | J40: =SUM(J41:J42) -> 5040 | ... N40: =SUM(N41:N42) -> 0 | O40: =SUM(C40:N40) -> 63085
B41: Clube do Grito 2024 (Cartões) | C41: 10000 | D41: 10000 | E41: 7900 | F41: 6000 | G41: 5900 | H41: 5205 | I41: 5040 | J41: 5040 | K41: =SUM(ADM!K41,MARKETING!K41,COMERCIAL!K41,OPERAÇÕES!K41) -> 0 | L41: =SUM(ADM!L41,MARKETING!L41,COMERCIAL!L41,OPERAÇÕES!L41) -> 0 | M41: =SUM(ADM!M41,MARKETING!M41,COMERCIAL!M41,OPERAÇÕES!M41) -> 0 | N41: =SUM(ADM!N41,MARKETING!N41,COMERCIAL!N41,OPERAÇÕES!N41) -> 0 | O41: =SUM(C41:N41) -> 63085
B42: Crowdfunding | C42: 0 | D42: 0 | E42: 0 | F42: 0 | G42: 0 | H42: 0 | I42: 0 | J42: 0 | K42: 0 | L42: 0 | M42: 0 | N42: 0 | O42: =SUM(C42:N42) -> 0
...

Sheet VALOR SETORIZADO
B2: PEC | G2: Q. PROFISSIONAL | L2: OUTLET
B3: TIME | C3: 6450 | D3: . | E3: 12 | G3: SUPERVISOR | H3: 2500 | I3: =SUM(H3*J3) -> 30000 | J3: 12 | L3: ATENDENTE | M3: 1320 | N3: =SUM(M3*O3) -> 15840 | O3: 12
B4: LOGISTICA/TRANSP. | C4: 600 | D4: =SUM(C4*E4) -> 31200 | E4: 52 | G4: ASSIST. Q.P. | H4: 1420 | I4: =SUM(H4*J4) -> 17040 | J4: 12 | L4: GERENTE NEGOCIOS SOCIAIS | M4: 1500 | N4: =SUM(M4*O4) -> 18000 | O4: 12
B5: ALIMENTAÇÃO | C5: 680 | D5: =SUM(C5*E5) -> 35360 | E5: 52 | G5: PROFESSORES | H5: 1000 | I5: =SUM(H5*J5) -> 10000 | J5: 10 | L5: LOGISTICA | M5: 1420 | N5: =SUM(M5*O5) -> 17040 | O5: 12
B6: MANUTENÇÃO | C6: 200 | D6: =SUM(C6*E6) -> 2000 | E6: 10 | G6: MOTORISTA | H6: 1420 | I6: =SUM(H6*J6) -> 17040 | J6: 12 | L6: MANUTENÇÃO | M6: 300 | N6: =SUM(M6*O6) -> 3600 | O6: 12
B7: EVENTOS | C7: 3000 | D7: =SUM(C7*E7) -> 6000 | E7: 2 | G7: MANUTENÇÃO | H7: 200 | I7: =SUM(H7*J7) -> 2000 | J7: 10 | L7: INSUMOS | M7: 300 | N7: =SUM(M7*O7) -> 3600 | O7: 12
B8: INSUMOS | C8: 250 | D8: =SUM(C8*E8) -> 2500 | E8: 10 | G8: TRANSPORTE | H8: 1000 | I8: =SUM(H8*J8) -> 10000 | J8: 10 | L8: FRETES | M8: 500 | N8: =SUM(M8*O8) -> 6000 | O8: 12
B9: MAT. OFIC. AQUIS. | C9: 20000 | D9: =SUM(C9*E9) -> 20000 | E9: 1 | G9: MATERIAL AULA | H9: 300 | I9: =SUM(H9*J9) -> 3000 | J9: 10
B10: TREINAMENTOS | C10: 1000 | D10: =SUM(C10*E10) -> 1000 | E10: 1 | G10: MATERIAL GRÁFICOS | H10: 50 | I10: =SUM(H10*J10) -> 500 | J10: 10
D13: =SUM(D3:D12) -> 98060 | I13: =SUM(I3:I11) -> 89580 | N13: =SUM(N3:N10) -> 64080
B15: PSICOSSOCIAL | G15: MARKETING | L15: GRIFFTE
B16: PSICÓLOGO | C16: 2000 | D16: =C16*E16 -> 24000 | E16: 12 | G16: SUPERVISOR | H16: 3000 | I16: =SUM(H16*J16) -> 36000 | J16: 12 | L16: COORDENADOR | M16: 2000 | N16: =SUM(M16*O16) -> 24000 | O16: 12
B17: INSUMOS | C17: 250 | D17: =C17*E17 -> 2500 | E17: 10 | G17: ASSIST. MTK | H17: 2000 | I17: =SUM(H17*J17) -> 24000 | J17: 12 | L17: GERENTE NEGOCIOS SOCIAIS | M17: 1500 | N17: =SUM(M17*O17) -> 18000 | O17: 12
G18: ASSIST. VIDEO | H18: 1000 | I18: =SUM(H18*J18) -> 12000 | J18: 12 | L18: MANUTENÇÃO | M18: 300 | N18: =SUM(M18*O18) -> 3600 | O18: 12
G19: Eventos | H19: 5000 | I19: =SUM(H19*J19) -> 5000 | J19: 1 | L19: LOGISTICA | M19: 1420 | N19: =SUM(M19*O19) -> 17040 | O19: 12
D20: =SUM(D16:D19) -> 26500 | G20: Material Divulgação | H20: 10000 | I20: =SUM(H20*J20) -> 10000 | J20: 1 | L20: INSUMOS | M20: 300 | N20: =SUM(M20*O20) -> 300 | O20: 1
B21: OPERAÇÕES | G21: Parceiros e Visitas | H21: 1500 | I21: =SUM(H21*J21) -> 1500 | J21: 1 | L21: COSTUREIRAS | M21: 3960 | N21: =SUM(M21*O21) -> 47520 | O21: 12
B22: COORDENADOR | C22: 3500 | D22: =C22*E22 -> 42000 | E22: 12 | G22: Ferramentas Trabalho | H22: 15000 | I22: =SUM(H22*J22) -> 15000 | J22: 1
G23: CAMISAS /UNIFORMES | H23: 3000 | I23: =SUM(H23*J23) -> 3000 | J23: 1
D25: =SUM(D22:D24) -> 42000 | I25: =SUM(I16:I24) -> 106500 | N25: =SUM(N16:N24) -> 110460
L27: CASA SONHAR
B28: RECEITA | D28: % | G28: CUSTO | I28: % | L28: Assistente pedagógico | M28: 1500 | N28: =SUM(M28*O28) -> 18000 | O28: 12
B29: JANTAR | C29: - | G29: QP | H29: =I13 -> 89580 | I29: =H29/H$39 -> 0.070390219 | L29: Monitor pedagógico | M29: 1400 | N29: =SUM(M29*O29) -> 16800 | O29: 12
B30: DOAÇÕES | C30: =ADM!O22 -> 66000 | D30: =C30/C$39 -> 0.34904937 | G30: PEC | H30: =D13 -> 98060 | I30: =H30/H$39 -> 0.077053637 | L30: Profissional de apoio e limpeza | M30: 1400 | N30: =SUM(M30*O30) -> 16800 | O30: 12
B31: APORTE | C31: =ADM!O28 -> 0 | D31: =C31/C$39 -> 0 | G31: CASA SONHAR | H31: =N48 -> 250440 | I31: =H31/H$39 -> 0.19679087 | L31: Educadores Sociais - (2) | M31: 3600 | N31: =SUM(M31*O31) -> 43200 | O31: 12
B32: NEGOCIOS SOCIAIS | C32: =ADM!O37 -> 0 | D32: =C32/C$39 -> 0 | G32: PSICOSSOCIAL | H32: =D20 -> 26500 | I32: =H32/H$39 -> 0.020823184 | L32: Educador de Ballet | M32: 900 | N32: =SUM(M32*O32) -> 10800 | O32: 12
B33: EVENTOS | C33: =ADM!O40 -> 63085 | D33: =C33/C$39 -> 0.33363302 | G33: MARKETING | H33: =I25 -> 106500 | I33: =H33/H$39 -> 0.083685625 | L33: Educador de Dança Contemporânea | M33: 600 | N33: =SUM(M33*O33) -> 7200 | O33: 12
B34: APLICAÇÕES | C34: =ADM!O43 -> 60000 | D34: =C34/C$39 -> 0.31731761 | G34: ADM | H34: 485000 | I34: =H34/H$39 -> 0.38110355 | L34: Educador de Artes | M34: 960 | N34: =SUM(M34*O34) -> 11520 | O34: 12
B35: EDITAIS | C35: =ADM!O33 -> 0 | G35: OUTLET | H35: =N13 -> 64080 | I35: =H35/H$39 -> 0.050352815 | L35: Educador de Musica | M35: 960 | N35: =SUM(M35*O35) -> 11520 | O35: 12
G36: GRIFFTE | H36: =N25 -> 110460 | I36: =H36/H$39 -> 0.086797316 | L36: Educador de Capoeira | M36: 180 | N36: =SUM(M36*O36) -> 2160 | O36: 12
G37: OPERAÇÕES | H37: =D25 -> 42000 | I37: =H37/H$39 -> 0.033002782 | L37: Alimentação | M37: 3500 | N37: =SUM(M37*O37) -> 38500 | O37: 11
L38: Material pedagógico | M38: 200 | N38: =SUM(M38*O38) -> 2200 | O38: 11
C39: =SUM(C29:C38) -> 189085 | D39: =C39/C$39 -> 1 | H39: =SUM(H29:H37) -> 1272620 | I39: =H39/H$39 -> 1 | L39: Eventos | M39: 3000 | N39: =SUM(M39*O39) -> 12000 | O39: 4
L40: Excursões qtdade a definir | N40: 5000
L41: Manutenção/Reforma | N41: 25000
L42: Manutenção Equipamento | M42: 200 | N42: =SUM(M42*O42) -> 2200 | O42: 11
L43: Aluguel | M43: 1500 | N43: =SUM(M43*O43) -> 18000 | O43: 12
L44: Agua | M44: 250 | N44: =SUM(M44*O44) -> 3000 | O44: 12
L45: Luz | M45: 350 | N45: =SUM(M45*O45) -> 4200 | O45: 12
L46: Telefonia/Internet | M46: 195 | N46: =SUM(M46*O46) -> 2340 | O46: 12
...

Sheet PREVISTO X REALIZADO
C1: INSTITUTO DE CAPACITACAO E ACAO SOCIAL O GRITO - PLANEJAMENTO 2024
D2: Emitido por RICARDO em 17/11/2023 10:58
B3: CATEGORIA | C3: PREVISTO | D3: REALIZADO/ REALIZAR | E3: DIFERENÇA | F3: JUSTIFICATIVA
B4: RECEITAS | C4: 0 | D4: 0 | E4: 0
B5: Devoluções | C5: 0 | D5: 0 | E5: 0
B6: Devoluções Compra Mercadoria Revenda | C6: 0 | D6: 0 | E6: 0
B7: Devoluções de Compra Material Consumo | C7: 0 | D7: 0 | E7: 0
B8: Devoluções de Compra de Matéria Prima | C8: 0 | D8: 0 | E8: 0
B9: Devoluções de Compra de Ativo | C9: 0 | D9: 0 | E9: 0
B10: Devoluções de Compra de Serviços | C10: 0 | D10: 0 | E10: 0
B11: Devolução de Doações | C11: 0 | D11: 0 | E11: 0
B12: Outras Entradas | C12: 0 | D12: 0 | E12: 0
B13: Empréstimos Bancários | C13: 0 | D13: 0 | E13: 0
B14: Aumento de Capital | C14: 0 | D14: 0 | E14: 0
B15: Venda de Ativos | C15: 0 | D15: 0 | E15: 0
... B136: Silker | C136: 0 | D136: 0 | E136: 0

Sheet MARKETING
C1: INSTITUTO DE CAPACITACAO E ACAO SOCIAL O GRITO - PLANEJAMENTO 2025 - MARKETING
A2: Emitido por RICARDO em 17/11/2023 10:58 | C2: =C47/O$47 -> 0.023491054 | D2: =D47/$O$47 -> 0.13583671 | E2: =E47/$O$47 -> 0.062611106 | F2: =F47/$O$47 -> 0.061835458 | G2: =G47/$O$47 -> 0.032360833 | H2: =H47/$O$47 -> 0.14316769 | I2: =I47/$O$47 -> 0.14870804 | J2: =J47/$O$47 -> 0.033025674 | K2: =K47/$O$47 -> 0.032360833 | ... N2: =N47/$O$47 -> 0.18781763
B3: CATEGORIA | C3: JANEIRO | D3: FEVEREIRO | E3: MARÇO | F3: ABRIL | G3: MAIO | H3: JUNHO | I3: JULHO | J3: AGOSTO | K3: SETEMBRO | L3: OUTUBRO | M3: NOVEMBRO | N3: DEZEMBRO | O3: TOTAL
B5: SALDO ACUMULADO | C5: =C6 -> -10600 | D5: =C5+D6 -> -70394.36 | E5: =D5+E6 -> -93746.72 | F5: =E5+F6 -> -116749.08 | G5: =F5+G6 -> -126451.44 | H5: =G5+H6 -> -177153.8 | I5: =H5+I6 -> -244256.16 | J5: =I5+J6 -> -259158.52 | K5: =J5+K6 -> -273760.88 | ... N5: =M5+N6 -> -421135.6
B6: SALDO MÊS | C6: =SUM(C8-C47) -> -10600 | D6: =SUM(D8-D47) -> -59794.36 | E6: =SUM(E8-E47) -> -23352.36 | F6: =SUM(F8-F47) -> -23002.36 | G6: =SUM(G8-G47) -> -9702.36 | H6: =SUM(H8-H47) -> -50702.36 | I6: =SUM(I8-I47) -> -67102.36 | J6: =SUM(J8-J47) -> -14902.36 | ... N6: =SUM(N8-N47) -> -84750 | O6: =SUM(C6:N6) -> -421135.6
B8: RECEITAS | C8: =SUM(C9,C16,C22,C28,C33,C37,C40,C43) -> 0 | D8: =SUM(D9,D16,D22,D28,D33,D37,D40,D43) -> 1500 | E8: =SUM(E9,E16,E22,E28,E33,E37,E40,E43) -> 4900 | F8: =SUM(F9,F16,F22,F28,F33,F37,F40,F43) -> 4900 | G8: =SUM(G9,G16,G22,G28,G33,G37,G40,G43) -> 4900 | H8: =SUM(H9,H16,H22,H28,H33,H37,H40,H43) -> 13900 | I8: =SUM(I9,I16,I22,I28,I33,I37,I40,I43) -> 0 | J8: =SUM(J9,J16,J22,J28,J33,J37,J40,J43) -> 0 | ... N8: =SUM(N9,N16,N22,N28,N33,N37,N40,N43) -> 0 | O8: =SUM(C8:N8) -> 30100
B9: Devoluções | C9: =SUM(C10:C15) -> 0 | D9: =SUM(D10:D15) -> 0 | E9: =SUM(E10:E15) -> 0 | F9: =SUM(F10:F15) -> 0 | G9: =SUM(G10:G15) -> 0 | H9: =SUM(H10:H15) -> 0 | I9: =SUM(I10:I15) -> 0 | J9: =SUM(J10:J15) -> 0 | ... N9: =SUM(N10:N15) -> 0 | O9: =SUM(C9:N9) -> 0
B10: Devoluções Compra Mercadoria Revenda | C10: 0 | D10: 0 | E10: 0 | F10: 0 | G10: 0 | H10: 0 | I10: 0 | J10: 0 | K10: 0 | L10: 0 | M10: 0 | N10: 0 | O10: =SUM(C10:N10) -> 0
B11: Devoluções de Compra Material Consumo | C11: 0 | D11: 0 | E11: 0 | F11: 0 | G11: 0 | H11: 0 | I11: 0 | J11: 0 | K11: 0 | L11: 0 | M11: 0 | N11: 0 | O11: =SUM(C11:N11) -> 0
B12: Devoluções de Compra de Matéria Prima | C12: 0 | D12: 0 | E12: 0 | F12: 0 | G12: 0 | H12: 0 | I12: 0 | J12: 0 | K12: 0 | L12: 0 | M12: 0 | N12: 0 | O12: =SUM(C12:N12) -> 0
B13: Devoluções de Compra de Ativo | C13: 0 | D13: 0 | E13: 0 | F13: 0 | G13: 0 | H13: 0 | I13: 0 | J13: 0 | K13: 0 | L13: 0 | M13: 0 | N13: 0 | O13: =SUM(C13:N13) -> 0
B14: Devoluções de Compra de Serviços | C14: 0 | D14: 0 | E14: 0 | F14: 0 | G14: 0 | H14: 0 | I14: 0 | J14: 0 | K14: 0 | L14: 0 | M14: 0 | N14: 0 | O14: =SUM(C14:N14) -> 0
B15: Devolução de Doações | C15: 0 | D15: 0 | E15: 0 | F15: 0 | G15: 0 | H15: 0 | I15: 0 | J15: 0 | K15: 0 | L15: 0 | M15: 0 | N15: 0 | O15: =SUM(C15:N15) -> 0
B16: Outras Entradas | C16: =SUM(C17:C21) -> 0 | D16: =SUM(D17:D21) -> 0 | E16: =SUM(E17:E21) -> 0 | F16: =SUM(F17:F21) -> 0 | G16: =SUM(G17:G21) -> 0 | H16: =SUM(H17:H21) -> 0 | I16: =SUM(I17:I21) -> 0 | J16: =SUM(J17:J21) -> 0 | ... N16: =SUM(N17:N21) -> 0 | O16: =SUM(C16:N16) -> 0
B17: Empréstimos Bancários | C17: 0 | D17: 0 | E17: 0 | F17: 0 | G17: 0 | H17: 0 | I17: 0 | J17: 0 | K17: 0 | L17: 0 | M17: 0 | N17: 0 | O17: =SUM(C17:N17) -> 0
B18: Aumento de Capital | C18: 0 | D18: 0 | E18: 0 | F18: 0 | G18: 0 | H18: 0 | I18: 0 | J18: 0 | K18: 0 | L18: 0 | M18: 0 | N18: 0 | O18: =SUM(C18:N18) -> 0
B19: Venda de Ativos | C19: 0 | D19: 0 | E19: 0 | F19: 0 | G19: 0 | H19: 0 | I19: 0 | J19: 0 | K19: 0 | L19: 0 | M19: 0 | N19: 0 | O19: =SUM(C19:N19) -> 0
B20: AJUSTE DE CAIXA | C20: 0 | D20: 0 | E20: 0 | F20: 0 | G20: 0 | H20: 0 | I20: 0 | J20: 0 | K20: 0 | L20: 0 | M20: 0 | N20: 0 | O20: =SUM(C20:N20) -> 0
B21: Prêmios de Seguros / Sinistros | C21: 0 | D21: 0 | E21: 0 | F21: 0 | G21: 0 | H21: 0 | I21: 0 | J21: 0 | K21: 0 | L21: 0 | M21: 0 | N21: 0 | O21: =SUM(C21:N21) -> 0
B22: Doações | C22: =SUM(C23:C27) -> 0 | D22: =SUM(D23:D27) -> 1500 | E22: =SUM(E23:E27) -> 0 | F22: =SUM(F23:F27) -> 0 | G22: =SUM(G23:G27) -> 0 | H22: =SUM(H23:H27) -> 9000 | I22: =SUM(I23:I27) -> 0 | J22: =SUM(J23:J27) -> 0 | ... N22: =SUM(N23:N27) -> 0 | O22: =SUM(C22:N22) -> 10500
B23: Doações Recorrentes | C23: 0 | D23: 0 | E23: 0 | F23: 0 | G23: 0 | H23: 0 | I23: 0 | J23: 0 | K23: 0 | L23: 0 | M23: 0 | N23: 0 | O23: =SUM(C23:N23) -> 0
B24: Doações Pontuais PF | C24: 0 | D24: 1500 | E24: 0 | F24: 0 | G24: 0 | H24: 9000 | I24: 0 | J24: 0 | K24: 0 | L24: 0 | M24: 0 | N24: 0 | O24: =SUM(C24:N24) -> 10500
B25: Doações Pontuais PJ | C25: 0 | D25: 0 | E25: 0 | F25: 0 | G25: 0 | H25: 0 | I25: 0 | J25: 0 | K25: 0 | L25: 0 | M25: 0 | N25: 0 | O25: =SUM(C25:N25) -> 0
B26: Sócio Doador | C26: 0 | D26: 0 | E26: 0 | F26: 0 | G26: 0 | H26: 0 | I26: 0 | J26: 0 | K26: 0 | L26: 0 | M26: 0 | N26: 0 | O26: =SUM(C26:N26) -> 0
B27: Patrocínios | C27: 0 | D27: 0 | E27: 0 | F27: 0 | G27: 0 | H27: 0 | I27: 0 | J27: 0 | K27: 0 | L27: 0 | M27: 0 | N27: 0 | O27: =SUM(C27:N27) -> 0
B28: Gerando Falcões | C28: =SUM(C29:C32) -> 0 | D28: =SUM(D29:D32) -> 0 | E28: =SUM(E29:E32) -> 0 | F28: =SUM(F29:F32) -> 0 | G28: =SUM(G29:G32) -> 0 | H28: =SUM(H29:H32) -> 0 | I28: =SUM(I29:I32) -> 0 | J28: =SUM(J29:J32) -> 0 | ... N28: =SUM(N29:N32) -> 0 | O28: =SUM(C28:N28) -> 0
B29: Aporte | C29: 0 | D29: 0 | E29: 0 | F29: 0 | G29: 0 | H29: 0 | I29: 0 | J29: 0 | K29: 0 | L29: 0 | M29: 0 | N29: 0 | O29: =SUM(C29:N29) -> 0
B30: Falcons Univercity | C30: 0 | D30: 0 | E30: 0 | F30: 0 | G30: 0 | H30: 0 | I30: 0 | J30: 0 | K30: 0 | L30: 0 | M30: 0 | N30: 0 | O30: =SUM(C30:N30) -> 0
B31: Regional GF | C31: 0 | D31: 0 | E31: 0 | F31: 0 | G31: 0 | H31: 0 | I31: 0 | J31: 0 | K31: 0 | L31: 0 | M31: 0 | N31: 0 | O31: =SUM(C31:N31) -> 0
B32: Favela 3D | C32: 0 | D32: 0 | E32: 0 | F32: 0 | G32: 0 | H32: 0 | I32: 0 | J32: 0 | K32: 0 | L32: 0 | M32: 0 | N32: 0 | O32: =SUM(C32:N32) -> 0
B33: Editais/Projetos | C33: =SUM(C34:C36) -> 0 | D33: =SUM(D34:D36) -> 0 | E33: =SUM(E34:E36) -> 0 | F33: =SUM(F34:F36) -> 0 | G33: =SUM(G34:G36) -> 0 | H33: =SUM(H34:H36) -> 0 | I33: =SUM(I34:I36) -> 0 | J33: =SUM(J34:J36) -> 0 | ... N33: =SUM(N34:N36) -> 0 | O33: =SUM(C33:N33) -> 0
B34: Ecogaiola | C34: 0 | D34: 0 | E34: 0 | F34: 0 | G34: 0 | H34: 0 | I34: 0 | J34: 0 | K34: 0 | L34: 0 | M34: 0 | N34: 0 | O34: =SUM(C34:N34) -> 0
B35: Prog. Hab. Polaris | C35: 0 | D35: 0 | E35: 0 | F35: 0 | G35: 0 | H35: 0 | I35: 0 | J35: 0 | K35: 0 | L35: 0 | M35: 0 | N35: 0 | O35: =SUM(C35:N35) -> 0
B36: Lei De Incentivo | C36: 0 | D36: 0 | E36: 0 | F36: 0 | G36: 0 | H36: 0 | I36: 0 | J36: 0 | K36: 0 | L36: 0 | M36: 0 | N36: 0 | O36: =SUM(C36:N36) -> 0
B37: Negócios Sociais | C37: =SUM(C38:C39) -> 0 | D37: =SUM(D38:D39) -> 0 | E37: =SUM(E38:E39) -> 4900 | F37: =SUM(F38:F39) -> 4900 | G37: =SUM(G38:G39) -> 4900 | H37: =SUM(H38:H39) -> 4900 | I37: =SUM(I38:I39) -> 0 | J37: =SUM(J38:J39) -> 0 | ... N37: =SUM(N38:N39) -> 0 | O37: =SUM(C37:N37) -> 19600
B38: Vendas Outlet | C38: 0 | D38: 0 | E38: 4900 | F38: 4900 | G38: 4900 | H38: 4900 | O38: =SUM(C38:N38) -> 19600
B39: Vendas Griffte | C39: 0 | D39: 0 | E39: 0 | F39: 0 | G39: 0 | H39: 0 | O39: =SUM(C39:N39) -> 0
B40: Eventos | C40: =SUM(C41:C42) -> 0 | D40: =SUM(D41:D42) -> 0 | E40: =SUM(E41:E42) -> 0 | F40: =SUM(F41:F42) -> 0 | G40: =SUM(G41:G42) -> 0 | H40: =SUM(H41:H42) -> 0 | I40: =SUM(I41:I42) -> 0 | J40: =SUM(J41:J42) -> 0 | ... N40: =SUM(N41:N42) -> 0 | O40: =SUM(C40:N40) -> 0
B41: Clube Do Grito | C41: 0 | D41: 0 | E41: 0 | F41: 0 | G41: 0 | H41: 0 | I41: 0 | J41: 0 | K41: 0 | L41: 0 | M41: 0 | N41: 0 | O41: =SUM(C41:N41) -> 0
B42: Crowdfunding | C42: 0 | D42: 0 | E42: 0 | F42: 0 | G42: 0 | H42: 0 | I42: 0 | J42: 0 | K42: 0 | L42: 0 | M42: 0 | N42: 0 | O42: =SUM(C42:N42) -> 0
...

Sheet FAVELA 3D
C1: INSTITUTO DE CAPACITACAO E ACAO SOCIAL O GRITO - PLANEJAMENTO 2025 - FAVELA 3D
A2: Emitido por RICARDO em 17/11/2023 10:58 | C2: =C47/O$47 -> 0.081926121 | D2: =D47/$O$47 -> 0.0823219 | E2: =E47/$O$47 -> 0.083377309 | F2: =F47/$O$47 -> 0.084036939 | G2: =G47/$O$47 -> 0.083377309 | H2: =H47/$O$47 -> 0.083377309 | I2: =I47/$O$47 -> 0.084036939 | J2: =J47/$O$47 -> 0.083377309 | K2: =K47/$O$47 -> 0.083377309 | ... N2: =N47/$O$47 -> 0.083377309
B3: CATEGORIA | C3: JANEIRO | D3: FEVEREIRO | E3: MARÇO | F3: ABRIL | G3: MAIO | H3: JUNHO | I3: JULHO | J3: AGOSTO | K3: SETEMBRO | L3: OUTUBRO | M3: NOVEMBRO | N3: DEZEMBRO | O3: TOTAL
B5: SALDO ACUMULADO | C5: =C6 -> -8600 | D5: =C5+D6 -> -17500 | E5: =D5+E6 -> -27200 | F5: =E5+F6 -> -37400 | G5: =F5+G6 -> -47100 | H5: =G5+H6 -> -56800 | I5: =H5+I6 -> -67000 | J5: =I5+J6 -> -76700 | K5: =J5+K6 -> -86400 | ... N5: =M5+N6 -> -116000
B6: SALDO MÊS | C6: =SUM(C8-C47) -> -8600 | D6: =SUM(D8-D47) -> -8900 | E6: =SUM(E8-E47) -> -9700 | F6: =SUM(F8-F47) -> -10200 | G6: =SUM(G8-G47) -> -9700 | H6: =SUM(H8-H47) -> -9700 | I6: =SUM(I8-I47) -> -10200 | J6: =SUM(J8-J47) -> -9700 | ... N6: =SUM(N8-N47) -> -9700 | O6: =SUM(C6:N6) -> -116000
B8: RECEITAS | C8: =SUM(C9,C16,C22,C28,C33,C37,C40,C43) -> 53500 | D8: =SUM(D9,D16,D22,D28,D33,D37,D40,D43) -> 53500 | E8: =SUM(E9,E16,E22,E28,E33,E37,E40,E43) -> 53500 | F8: =SUM(F9,F16,F22,F28,F33,F37,F40,F43) -> 53500 | G8: =SUM(G9,G16,G22,G28,G33,G37,G40,G43) -> 53500 | H8: =SUM(H9,H16,H22,H28,H33,H37,H40,H43) -> 53500 | I8: =SUM(I9,I16,I22,I28,I33,I37,I40,I43) -> 53500 | J8: =SUM(J9,J16,J22,J28,J33,J37,J40,J43) -> 53500 | ... N8: =SUM(N9,N16,N22,N28,N33,N37,N40,N43) -> 53500 | O8: =SUM(C8:N8) -> 642000
B9: Devoluções | C9: =SUM(C10:C15) -> 0 | D9: =SUM(D10:D15) -> 0 | E9: =SUM(E10:E15) -> 0 | F9: =SUM(F10:F15) -> 0 | G9: =SUM(G10:G15) -> 0 | H9: =SUM(H10:H15) -> 0 | I9: =SUM(I10:I15) -> 0 | J9: =SUM(J10:J15) -> 0 | ... N9: =SUM(N10:N15) -> 0 | O9: =SUM(C9:N9) -> 0
B10: Devoluções Compra Mercadoria Revenda | C10: 0 | D10: 0 | E10: 0 | F10: 0 | G10: 0 | H10: 0 | I10: 0 | J10: 0 | K10: 0 | L10: 0 | M10: 0 | N10: 0 | O10: =SUM(C10:N10) -> 0
B11: Devoluções de Compra Material Consumo | C11: 0 | D11: 0 | E11: 0 | F11: 0 | G11: 0 | H11: 0 | I11: 0 | J11: 0 | K11: 0 | L11: 0 | M11: 0 | N11: 0 | O11: =SUM(C11:N11) -> 0
B12: Devoluções de Compra de Matéria Prima | C12: 0 | D12: 0 | E12: 0 | F12: 0 | G12: 0 | H12: 0 | I12: 0 | J12: 0 | K12: 0 | L12: 0 | M12: 0 | N12: 0 | O12: =SUM(C12:N12) -> 0
B13: Devoluções de Compra de Ativo | C13: 0 | D13: 0 | E13: 0 | F13: 0 | G13: 0 | H13: 0 | I13: 0 | J13: 0 | K13: 0 | L13: 0 | M13: 0 | N13: 0 | O13: =SUM(C13:N13) -> 0
B14: Devoluções de Compra de Serviços | C14: 0 | D14: 0 | E14: 0 | F14: 0 | G14: 0 | H14: 0 | I14: 0 | J14: 0 | K14: 0 | L14: 0 | M14: 0 | N14: 0 | O14: =SUM(C14:N14) -> 0
B15: Devolução de Doações | C15: 0 | D15: 0 | E15: 0 | F15: 0 | G15: 0 | H15: 0 | I15: 0 | J15: 0 | K15: 0 | L15: 0 | M15: 0 | N15: 0 | O15: =SUM(C15:N15) -> 0
B16: Outras Entradas | C16: =SUM(C17:C21) -> 0 | D16: =SUM(D17:D21) -> 0 | E16: =SUM(E17:E21) -> 0 | F16: =SUM(F17:F21) -> 0 | G16: =SUM(G17:G21) -> 0 | H16: =SUM(H17:H21) -> 0 | I16: =SUM(I17:I21) -> 0 | J16: =SUM(J17:J21) -> 0 | ... N16: =SUM(N17:N21) -> 0 | O16: =SUM(C16:N16) -> 0
B17: Empréstimos Bancários | C17: 0 | D17: 0 | E17: 0 | F17: 0 | G17: 0 | H17: 0 | I17: 0 | J17: 0 | K17: 0 | L17: 0 | M17: 0 | N17: 0 | O17: =SUM(C17:N17) -> 0
B18: Aumento de Capital | C18: 0 | D18: 0 | E18: 0 | F18: 0 | G18: 0 | H18: 0 | I18: 0 | J18: 0 | K18: 0 | L18: 0 | M18: 0 | N18: 0 | O18: =SUM(C18:N18) -> 0
B19: Venda de Ativos | C19: 0 | D19: 0 | E19: 0 | F19: 0 | G19: 0 | H19: 0 | I19: 0 | J19: 0 | K19: 0 | L19: 0 | M19: 0 | N19: 0 | O19: =SUM(C19:N19) -> 0
B20: AJUSTE DE CAIXA | C20: 0 | D20: 0 | E20: 0 | F20: 0 | G20: 0 | H20: 0 | I20: 0 | J20: 0 | K20: 0 | L20: 0 | M20: 0 | N20: 0 | O20: =SUM(C20:N20) -> 0
B21: Prêmios de Seguros / Sinistros | C21: 0 | D21: 0 | E21: 0 | F21: 0 | G21: 0 | H21: 0 | I21: 0 | J21: 0 | K21: 0 | L21: 0 | M21: 0 | N21: 0 | O21: =SUM(C21:N21) -> 0
B22: Doações | C22: =SUM(C23:C27) -> 0 | D22: =SUM(D23:D27) -> 0 | E22: =SUM(E23:E27) -> 0 | F22: =SUM(F23:F27) -> 0 | G22: =SUM(G23:G27) -> 0 | H22: =SUM(H23:H27) -> 0 | I22: =SUM(I23:I27) -> 0 | J22: =SUM(J23:J27) -> 0 | ... N22: =SUM(N23:N27) -> 0 | O22: =SUM(C22:N22) -> 0
B23: Doações Recorrentes | C23: 0 | D23: 0 | E23: 0 | F23: 0 | G23: 0 | H23: 0 | I23: 0 | J23: 0 | K23: 0 | L23: 0 | M23: 0 | N23: 0 | O23: =SUM(C23:N23) -> 0
B24: Doações Pontuais PF | C24: 0 | D24: 0 | E24: 0 | F24: 0 | G24: 0 | H24: 0 | I24: 0 | J24: 0 | K24: 0 | L24: 0 | M24: 0 | N24: 0 | O24: =SUM(C24:N24) -> 0
B25: Doações Pontuais PJ | C25: 0 | D25: 0 | E25: 0 | F25: 0 | G25: 0 | H25: 0 | I25: 0 | J25: 0 | K25: 0 | L25: 0 | M25: 0 | N25: 0 | O25: =SUM(C25:N25) -> 0
B26: Sócio Doador | C26: 0 | D26: 0 | E26: 0 | F26: 0 | G26: 0 | H26: 0 | I26: 0 | J26: 0 | K26: 0 | L26: 0 | M26: 0 | N26: 0 | O26: =SUM(C26:N26) -> 0
B27: Patrocínios | C27: 0 | D27: 0 | E27: 0 | F27: 0 | G27: 0 | H27: 0 | I27: 0 | J27: 0 | K27: 0 | L27: 0 | M27: 0 | N27: 0 | O27: =SUM(C27:N27) -> 0
B28: Gerando Falcões | C28: =SUM(C29:C32) -> 53500 | D28: =SUM(D29:D32) -> 53500 | E28: =SUM(E29:E32) -> 53500 | F28: =SUM(F29:F32) -> 53500 | G28: =SUM(G29:G32) -> 53500 | H28: =SUM(H29:H32) -> 53500 | I28: =SUM(I29:I32) -> 53500 | J28: =SUM(J29:J32) -> 53500 | ... N28: =SUM(N29:N32) -> 53500 | O28: =SUM(C28:N28) -> 642000
B29: Aporte | C29: 53500 | D29: 53500 | E29: 53500 | F29: 53500 | G29: 53500 | H29: 53500 | I29: 53500 | J29: 53500 | K29: 53500 | L29: 53500 | M29: 53500 | N29: 53500 | O29: =SUM(C29:N29) -> 642000
B30: Falcons Univercity | C30: 0 | D30: 0 | E30: 0 | F30: 0 | G30: 0 | H30: 0 | I30: 0 | J30: 0 | K30: 0 | L30: 0 | M30: 0 | N30: 0 | O30: =SUM(C30:N30) -> 0
B31: Regional GF | C31: 0 | D31: 0 | E31: 0 | F31: 0 | G31: 0 | H31: 0 | I31: 0 | J31: 0 | K31: 0 | L31: 0 | M31: 0 | N31: 0 | O31: =SUM(C31:N31) -> 0
B32: Favela 3D | C32: 0 | D32: 0 | E32: 0 | F32: 0 | G32: 0 | H32: 0 | I32: 0 | J32: 0 | K32: 0 | L32: 0 | M32: 0 | N32: 0 | O32: =SUM(C32:N32) -> 0
B33: Editais/Projetos | C33: =SUM(C34:C36) -> 0 | D33: =SUM(D34:D36) -> 0 | E33: =SUM(E34:E36) -> 0 | F33: =SUM(F34:F36) -> 0 | G33: =SUM(G34:G36) -> 0 | H33: =SUM(H34:H36) -> 0 | I33: =SUM(I34:I36) -> 0 | J33: =SUM(J34:J36) -> 0 | ... N33: =SUM(N34:N36) -> 0 | O33: =SUM(C33:N33) -> 0
B34: Ecogaiola | C34: 0 | D34: 0 | E34: 0 | F34: 0 | G34: 0 | H34: 0 | I34: 0 | J34: 0 | K34: 0 | L34: 0 | M34: 0 | N34: 0 | O34: =SUM(C34:N34) -> 0
B35: Prog. Hab. Polaris | C35: 0 | D35: 0 | E35: 0 | F35: 0 | G35: 0 | H35: 0 | I35: 0 | J35: 0 | K35: 0 | L35: 0 | M35: 0 | N35: 0 | O35: =SUM(C35:N35) -> 0
B36: Lei De Incentivo | C36: 0 | D36: 0 | E36: 0 | F36: 0 | G36: 0 | H36: 0 | I36: 0 | J36: 0 | K36: 0 | L36: 0 | M36: 0 | N36: 0 | O36: =SUM(C36:N36) -> 0
B37: Negócios Sociais | C37: =SUM(C38:C39) -> 0 | D37: =SUM(D38:D39) -> 0 | E37: =SUM(E38:E39) -> 0 | F37: =SUM(F38:F39) -> 0 | G37: =SUM(G38:G39) -> 0 | H37: =SUM(H38:H39) -> 0 | I37: =SUM(I38:I39) -> 0 | J37: =SUM(J38:J39) -> 0 | ... N37: =SUM(N38:N39) -> 0 | O37: =SUM(C37:N37) -> 0
B38: Vendas Outlet | C38: 0 | D38: 0 | E38: 0 | F38: 0 | G38: 0 | H38: 0 | I38: 0 | J38: 0 | K38: 0 | L38: 0 | M38: 0 | N38: 0 | O38: =SUM(C38:N38) -> 0
B39: Vendas Griffte | C39: 0 | D39: 0 | E39: 0 | F39: 0 | G39: 0 | H39: 0 | I39: 0 | J39: 0 | K39: 0 | L39: 0 | M39: 0 | N39: 0 | O39: =SUM(C39:N39) -> 0
B40: Eventos | C40: =SUM(C41:C42) -> 0 | D40: =SUM(D41:D42) -> 0 | E40: =SUM(E41:E42) -> 0 | F40: =SUM(F41:F42) -> 0 | G40: =SUM(G41:G42) -> 0 | H40: =SUM(H41:H42) -> 0 | I40: =SUM(I41:I42) -> 0 | J40: =SUM(J41:J42) -> 0 | ... N40: =SUM(N41:N42) -> 0 | O40: =SUM(C40:N40) -> 0
B41: Clube Do Grito | C41: 0 | D41: 0 | E41: 0 | F41: 0 | G41: 0 | H41: 0 | I41: 0 | J41: 0 | K41: 0 | L41: 0 | M41: 0 | N41: 0 | O41: =SUM(C41:N41) -> 0
B42: Crowdfunding | C42: 0 | D42: 0 | E42: 0 | F42: 0 | G42: 0 | H42: 0 | I42: 0 | J42: 0 | K42: 0 | L42: 0 | M42: 0 | N42: 0 | O42: =SUM(C42:N42) -> 0
...

Sheet COMERCIAL
C1: INSTITUTO DE CAPACITACAO E ACAO SOCIAL O GRITO - PLANEJAMENTO 2025 - NEGOCIOS SOCIAIS
A2: Emitido por RICARDO em 17/11/2023 10:58 | C2: =C47/O$47 -> 0.096862023 | D2: =D47/$O$47 -> 0.081779362 | E2: =E47/$O$47 -> 0.08217112 | F2: =F47/$O$47 -> 0.083346392 | G2: =G47/$O$47 -> 0.082014417 | H2: =H47/$O$47 -> 0.081975241 | I2: =I47/$O$47 -> 0.081779362 | J2: =J47/$O$47 -> 0.081779362 | K2: =K47/$O$47 -> 0.081975241 | ... N2: =N47/$O$47 -> 0.082562877
B3: CATEGORIA | C3: JANEIRO | D3: FEVEREIRO | E3: MARÇO | F3: ABRIL | G3: MAIO | H3: JUNHO | I3: JULHO | J3: AGOSTO | K3: SETEMBRO | L3: OUTUBRO | M3: NOVEMBRO | N3: DEZEMBRO | O3: TOTAL
B5: SALDO ACUMULADO | C5: =C6 -> -8225 | D5: =C5+D6 -> 400 | E5: =D5+E6 -> 8925 | F5: =E5+F6 -> 17150 | G5: =F5+G6 -> 25715 | H5: =G5+H6 -> 34290 | I5: =H5+I6 -> 42915 | J5: =I5+J6 -> 51540 | K5: =J5+K6 -> 60115 | ... N5: =M5+N6 -> 72740
B6: SALDO MÊS | C6: =SUM(C8-C47) -> -8225 | D6: =SUM(D8-D47) -> 8625 | E6: =SUM(E8-E47) -> 8525 | F6: =SUM(F8-F47) -> 8225 | G6: =SUM(G8-G47) -> 8565 | H6: =SUM(H8-H47) -> 8575 | I6: =SUM(I8-I47) -> 8625 | J6: =SUM(J8-J47) -> 8625 | ... N6: =SUM(N8-N47) -> -4575 | O6: =SUM(C6:N6) -> 72740
